Workbook

Sheet Bảng tổng
A1: Công ty TNHH Giấy Đông Á
A2: Thôn Mộc Ty, xã Trưng Trắc, huyện Văn Lâm, tỉnh Hưng Yên
A3: XUẤT NHẬP TỒN NĂM 2025
A7: STT | B7: Tên nguyên vật liệu | C7: Đơn vị tính | D7: Tồn đầu kỳ | E7: Số lượng nhập | F7: Số lượng xuất | G7: Tồn cuối | H7: Ghi chú
A9: 1 | B9: Vỏ thùng otakami 320/80 | C9: Cái | D9: ='THÙNG OTAKMI320,80'!G8 -> 0 | E9: ='THÙNG OTAKMI320,80'!E150 -> 22776 | F9: ='THÙNG OTAKMI320,80'!F150 -> 22505 | G9: =D9+E9-F9 -> 271
A10: =+A9+1 -> 2 | B10: Vỏ thùng otakami 320/76 | C10: Cái | D10: ='THÙNG OTAKAMI320,76'!G8 -> 0 | E10: ='THÙNG OTAKAMI320,76'!E56 -> 3722 | F10: ='THÙNG OTAKAMI320,76'!F56 -> 3722 | G10: =D10+E10-F10 -> 0
A11: =+A10+1 -> 3 | B11: Vỏ thùng otakami 180/80 | C11: Cái | D11: ='THÙNG OTAKAMI180,80 '!G9 -> 0 | E11: ='THÙNG OTAKAMI180,80 '!E84 -> 857 | F11: ='THÙNG OTAKAMI180,80 '!F84 -> 560 | G11: =D11+E11-F11 -> 297
A12: =+A11+1 -> 4 | B12: Vỏ thùng otakami 700/80 | C12: Cái | D12: ='Thùng otakami 700,80'!G9 -> 0 | E12: ='Thùng otakami 700,80'!E42 -> 1300 | F12: ='Thùng otakami 700,80'!F42 -> 1318 | G12: =D12+E12-F12 -> -18
A13: =+A12+1 -> 5 | B13: Vỏ thùng otakami 700/76 | C13: Cái | D13: ='Thùng otakami 700,76 '!G8 -> 0 | E13: ='Thùng otakami 700,76 '!E61 -> 500 | F13: ='Thùng otakami 700,76 '!F61 -> 540 | G13: =D13+E13-F13 -> -40
A14: =+A13+1 -> 6 | B14: Vỏ thùng otakami 160/80 | C14: Cái | D14: ='Thùng otakami 160,80'!G8 -> 0 | E14: ='Thùng otakami 160,80'!E43 -> 400 | F14: ='Thùng otakami 160,80'!F43 -> 400 | G14: =D14+E14-F14 -> 0
A15: =+A14+1 -> 7 | B15: Phôi ĐL 15 - 2 Lớp | C15: Kg | D15: ='Phôi DL 15,2L'!G9 -> 0 | E15: ='Phôi DL 15,2L'!E47 -> 39004 | F15: ='Phôi DL 15,2L'!F47 -> 39004 | G15: =D15+E15-F15 -> 0 | I15: DL 15 và 15,5 : | K15: =SUM(E15:E16) -> 399683 | L15: =114000-K15 -> -285683
B16: Phôi ĐL 15,5 - 2 Lớp | C16: Kg | D16: ='Phôi DL 15,5. 2 L'!G9 -> 0 | E16: ='Phôi DL 15,5. 2 L'!E149 -> 360679 | F16: ='Phôi DL 15,5. 2 L'!F149 -> 358756.8 | G16: =D16+E16-F16 -> 1922.2
A17: =+A15+1 -> 8 | B17: Phôi ĐL 18 - 2 Lớp | C17: Kg | D17: ='Phôi DL 18,2L.700g'!G9 -> 0 | E17: ='Phôi DL 18,2L.700g'!E47 -> 9635.2 | F17: ='Phôi DL 18,2L.700g'!F47 -> 9658.2 | G17: =D17+E17-F17 -> -23 | I17: DL 18 : | K17: =+E17+E18+E20+E22+E23 -> 21348.2
A18: =+A17+1 -> 9 | B18: Phôi ĐL 18 - 1Lớp - 700g | C18: Kg | D18: ='Phôi DL 18,1L.700g ,2 L'!G9 -> 0 | E18: ='Phôi DL 18,1L.700g ,2 L'!E47 -> 2342 | F18: ='Phôi DL 18,1L.700g ,2 L'!F47 -> 2342 | G18: =D18+E18-F18 -> 0 | H18: =+SUM(E15:E23) -> 472912.7 | I18: DL 16 : | K18: =+E21 -> 39948.1
A19: =+A18+1 -> 10 | B19: Phôi ĐL 23 - 2Lớp - 700g - 160 M | C19: Kg | D19: ='Phôi DL 23,2L.160m'!G9 -> 0 | E19: ='Phôi DL 23,2L.160m'!E47 -> 11933.4 | F19: ='Phôi DL 23,2L.160m'!F47 -> 10099 | G19: =D19+E19-F19 -> 1834.4 | I19: DL 23 : | K19: =+E19 -> 11933.4
A20: =+A19+1 -> 11 | B20: Phôi ĐL 18 - 2Lớp - 600G | C20: Kg | D20: ='Phôi DL 18,2L.600g '!G9 -> 0 | E20: ='Phôi DL 18,2L.600g '!E47 -> 6063 | F20: ='Phôi DL 18,2L.600g '!F47 -> 6040 | G20: =D20+E20-F20 -> 23 | I20: =+SUM(F15:F22) -> 467616
A21: =+A20+1 -> 12 | B21: Phôi ĐL 16 - 2Lớp - 180 M | C21: Kg | D21: ='Phôi DL 16,2L.180m'!G9 -> 0 | E21: ='Phôi DL 16,2L.180m'!E48 -> 39948.1 | F21: ='Phôi DL 16,2L.180m'!F48 -> 39422 | G21: =D21+E21-F21 -> 526.1
A22: =+A21+1 -> 13 | B22: Phôi ĐL 18 - 1Lớp - 600 M | C22: Kg | D22: ='Phôi DL 18,1L,600'!G9 -> 0 | E22: ='Phôi DL 18,1L,600'!E47 -> 2294 | F22: ='Phôi DL 18,1L,600'!F47 -> 2294 | G22: =D22+E22-F22 -> 0
B23: Phôi ĐL 18,5 - 2Lớp | C23: Kg | D23: ='Phôi DL 18,5,2L'!G9 -> 0 | E23: ='Phôi DL 18,5,2L'!E47 -> 1014 | F23: ='Phôi DL 18,5,2L'!F47 -> 0 | G23: =D23+E23-F23 -> 1014 | I23: =+G18+G23 -> 1014
A24: =+A22+1 -> 14 | B24: Lõi 76 k 2850 | C24: ống | D24: ='Lõi 76'!G8 -> 0 | E24: ='Lõi 76'!E59 -> 2483 | F24: ='Lõi 76'!F59 -> 2483 | G24: =D24+E24-F24 -> 0
A25: =+A24+1 -> 15 | B25: Lõi 80 k2850 | C25: Kg | D25: ='Lõi 80'!G8 -> 0 | E25: ='Lõi 80'!E146 -> 13243 | F25: ='Lõi 80'!F146 -> 13264 | G25: =D25+E25-F25 -> -21
A26: =+A25+1 -> 16 | B26: Bao trắng 600 BB/80 | C26: Kg | D26: ='Bao trắng 600g,bb,80 '!G8 -> 0 | E26: ='Bao trắng 600g,bb,80 '!E158 -> 136.6 | F26: ='Bao trắng 600g,bb,80 '!F158 -> 72.7 | G26: =D26+E26-F26 -> 63.9
A27: =+A26+1 -> 17 | B27: Bao trắng 320 M - C | C27: Kg | D27: ='Bao trắng 320 M ,C '!G8 -> 0 | E27: ='Bao trắng 320 M ,C '!E153 -> 41.6 | F27: ='Bao trắng 320 M ,C '!F153 -> 42.5 | G27: =D27+E27-F27 -> -0.9
A28: =+A27+1 -> 18 | B28: Bao trắng 320M - 76 - MTL | C28: Kg | D28: ='Bao 320 M ,76 MTL'!G8 -> 0 | E28: ='Bao 320 M ,76 MTL'!E160 -> 297.6 | F28: ='Bao 320 M ,76 MTL'!F160 -> 298 | G28: =D28+E28-F28 -> -0.4 | K28: =+E17+E18+E20+E22 -> 20334.2
A29: =+A28+1 -> 19 | B29: Bao trắng otakami 320 M -76-MTL | C29: Kg | D29: ='Bao trắng 4, 320 M,76 MTL'!G8 -> 0 | E29: ='Bao trắng 4, 320 M,76 MTL'!E151 -> 93 | F29: ='Bao trắng 4, 320 M,76 MTL'!F151 -> 69.3 | G29: =D29+E29-F29 -> 23.7
B30: Tổng cộng | E30: =SUM(E9:E29) -> 518762.5 | F30: =SUM(F9:F29) -> 512890.5 | G30: =SUM(G9:G29) -> 5872

Sheet THÙNG OTAKMI320,80
A1: Công ty TNHH Giấy Đông Á
A2: Thôn Mộc Ty, xã Trưng Trắc, huyện Văn Lâm, tỉnh Hưng Yên
A3: THẺ KHO NGUYÊN VẬT LIỆU
A7: STT | B7: Ngày tháng | C7: Tên nguyên vật liệu | D7: ĐVT | E7: Số lượng nhập | F7: Số lượng xuất | G7: Tồn | H7: Người nhận | I7: Ghi chú
C8: Tồn đầu kỳ
A9: 1 | B9: 45703 | C9: Vỏ thùng otakami 320/80 | D9: cái | E9: 940 | G9: =+G8+E9-F9 -> 940 | H9: Nguyễn Thanh Tâm | I9: SX
A10: =+A9+1 -> 2 | B10: 45703 | C10: Vỏ thùng otakami 320/80 | D10: cái | E10: 920 | G10: =+G9+E10-F10 -> 1860 | H10: Nguyễn Thanh Tâm | I10: SX
A11: =+A10+1 -> 3 | B11: 45712 | D11: cái | E11: 1000 | F11: 48 | G11: =+G10+E11-F11 -> 2812 | H11: Nguyễn Thanh Tâm | I11: SX | J11: có 10 vỏ lỗi
A12: =+A11+1 -> 4 | B12: 45716 | D12: cái | F12: 53 | G12: =+G11+E12-F12 -> 2759 | H12: Nguyễn Thanh Tâm | I12: SX
A13: =+A12+1 -> 5 | B13: 45717 | D13: cái | F13: 166 | G13: =+G12+E13-F13 -> 2593 | H13: Nguyễn Thanh Tâm | I13: SX
A14: =+A13+1 -> 6 | B14: 45719 | D14: cái | F14: 242 | G14: =+G13+E14-F14 -> 2351 | H14: Nguyễn Thanh Tâm | I14: SX
A15: =+A14+1 -> 7 | B15: 45720 | D15: cái | F15: 185 | G15: =+G14+E15-F15 -> 2166 | H15: Nguyễn Thanh Tâm | I15: SX
A16: =+A15+1 -> 8 | B16: 45728 | D16: cái | E16: 109 | F16: =56 -> 56 | G16: =+G15+E16-F16 -> 2219 | H16: Nguyễn Thanh Tâm | I16: SX | J16: Cộng 109 vỏ thùng 320/76 do nhầm thùng
B17: 45733 | C17: Nhập 40 cái vỏ thùng 80 xếp lẫn trong thùng 76 | D17: cái | E17: 40 | F17: 109 | G17: =+G16+E17-F17 -> 2150 | J17: Xuất 109 vỏ thùng 320/80 sang 320/76
A18: =+A16+1 -> 9 | B18: 45737 | D18: cái | F18: 270 | G18: =+G17+E18-F18 -> 1880
A19: =+A18+1 -> 10 | B19: 45738 | D19: cái | F19: 140 | G19: =+G18+E19-F19 -> 1740 | H19: Nguyễn Thanh Tâm | I19: SX
A20: =+A19+1 -> 11 | B20: 45739 | D20: cái | F20: 73 | G20: =+G19+E20-F20 -> 1667 | H20: Nguyễn Thanh Tâm | I20: SX
A21: =+A20+1 -> 12 | B21: 45740 | D21: cái | F21: =164+92+9 -> 265 | G21: =+G20+E21-F21 -> 1402 | H21: Nguyễn Thanh Tâm | I21: SX
A22: =+A21+1 -> 13 | B22: 45743 | D22: cái | F22: 133 | G22: =+G21+E22-F22 -> 1269 | H22: Nguyễn Thanh Tâm | I22: SX
A23: =+A22+1 -> 14 | B23: 45744 | D23: cái | F23: 214 | G23: =+G22+E23-F23 -> 1055 | H23: Nguyễn Thanh Tâm | I23: SX
A24: =+A23+1 -> 15 | B24: 45746 | D24: cái | F24: 271 | G24: =+G23+E24-F24 -> 784 | H24: Nguyễn Thanh Tâm | I24: SX
A25: =+A24+1 -> 16 | B25: 45747 | D25: cái | F25: 326 | G25: =+G24+E25-F25 -> 458 | H25: Nguyễn Thanh Tâm | I25: SX
A26: =+A25+1 -> 17 | B26: 45748 | D26: cái | F26: 275 | G26: =+G25+E26-F26 -> 183 | H26: Nguyễn Thanh Tâm | I26: SX
A27: 0 | B27: 45761 | D27: cái | E27: 400 | G27: =+G26+E27-F27 -> 583 | H27: Nguyễn Thanh Tâm | I27: SX
A28: =+A27+1 -> 1 | B28: 45764 | D28: cái | F28: 265 | G28: =+G27+E28-F28 -> 318 | H28: Nguyễn Thanh Tâm | I28: SX | M28: =6703+109 -> 6812
A29: =+A28+1 -> 2 | B29: 45765 | D29: cái | F29: 266 | G29: =+G28+E29-F29 -> 52 | H29: Nguyễn Thanh Tâm | I29: SX
A30: =+A29+1 -> 3 | B30: 45766 | D30: cái | E30: 700 | F30: 256 | G30: =+G29+E30-F30 -> 496 | H30: Nguyễn Thanh Tâm | I30: SX
A31: =+A30+1 -> 4 | B31: 45768 | D31: cái | F31: 73 | G31: =+G30+E31-F31 -> 423 | H31: Nguyễn Thanh Tâm | I31: SX
A32: =+A31+1 -> 5 | B32: 45771 | D32: cái | E32: 200 | F32: 69 | G32: =+G31+E32-F32 -> 554 | H32: Nguyễn Thanh Tâm | I32: SX
A33: =+A32+1 -> 6 | B33: 45772 | D33: cái | F33: 182 | G33: =+G32+E33-F33 -> 372 | H33: Nguyễn Thanh Tâm | I33: SX
A34: =+A33+1 -> 7 | B34: 45785 | D34: cái | F34: 161 | G34: =+G33+E34-F34 -> 211
A35: =+A34+1 -> 8 | B35: 45786 | D35: cái | E35: 100 | G35: =+G34+E35-F35 -> 311
A36: =+A35+1 -> 9 | B36: 45787 | D36: cái | F36: 128 | G36: =+G35+E36-F36 -> 183
A37: =+A36+1 -> 10 | B37: 45789 | D37: cái | E37: 197 | G37: =+G36+E37-F37 -> 380
A38: =+A37+1 -> 11 | B38: 45791 | D38: cái | E38: 1560 | G38: =+G37+E38-F38 -> 1940 | H38: x
A39: =+A38+1 -> 12 | B39: 45792 | D39: cái | F39: =84+11 -> 95 | G39: =+G38+E39-F39 -> 1845
A40: =+A39+1 -> 13 | B40: 45793 | D40: cái | E40: 400 | F40: 167 | G40: =+G39+E40-F40 -> 2078 | H40: x
A41: =+A40+1 -> 14 | B41: 45794 | D41: cái | F41: 20 | G41: =+G40+E41-F41 -> 2058
A42: =+A41+1 -> 15 | B42: 45796 | D42: cái | F42: 126 | G42: =+G41+E42-F42 -> 1932 | H42: Chạy hàng 320/86
A43: =+A42+1 -> 16 | B43: 45797 | D43: cái | E43: 1630 | F43: 186 | G43: =+G42+E43-F43 -> 3376 | H43: x
...

Sheet THÙNG OTAKAMI320,76
A1: Công ty TNHH Giấy Đông Á
A2: Thôn Mộc Ty, xã Trưng Trắc, huyện Văn Lâm, tỉnh Hưng Yên
A3: THẺ KHO NGUYÊN VẬT LIỆU
A7: STT | B7: Ngày tháng | C7: Tên nguyên vật liệu | D7: ĐVT | E7: Số lượng nhập | F7: Số lượng xuất | G7: Tồn | H7: Người nhận | I7: Ghi chú
C8: Tồn đầu kỳ
A9: 1 | B9: 45703 | C9: Vỏ thùng otakami 320/76 | D9: cái | E9: 1590 | G9: =+G8+E9-F9 -> 1590 | H9: Nguyễn Thanh Tâm | I9: SX
A10: =+A9+1 -> 2 | B10: 45703 | C10: Vỏ thùng otakami 320/76 | D10: cái | E10: 920 | G10: =+G9+E10-F10 -> 2510 | H10: Nguyễn Thanh Tâm | I10: SX
A11: =+A10+1 -> 3 | B11: 45705 | C11: Vỏ thùng otakami 320/76 | D11: cái | E11: 390 | G11: =+G10+E11-F11 -> 2900 | H11: Nguyễn Thanh Tâm | I11: SX
A12: =+A11+1 -> 4 | B12: 45720 | C12: Vỏ thùng otakami 320/76 | D12: cái | F12: 45 | G12: =+G11+E12-F12 -> 2855 | H12: Nguyễn Thanh Tâm | I12: SX
A13: =+A12+1 -> 5 | B13: 45721 | C13: Vỏ thùng otakami 320/76 | D13: cái | F13: 228 | G13: =+G12+E13-F13 -> 2627 | H13: Nguyễn Thanh Tâm | I13: SX
A14: =+A13+1 -> 6 | B14: 45722 | C14: Vỏ thùng otakami 320/76 | D14: cái | F14: 219 | G14: =+G13+E14-F14 -> 2408 | H14: Nguyễn Thanh Tâm | I14: SX
A15: =+A14+1 -> 7 | B15: 45724 | C15: Vỏ thùng otakami 320/76 | D15: cái | F15: 109 | G15: =+G14+E15-F15 -> 2299 | H15: Nguyễn Thanh Tâm | I15: SX | J15: Xuất chạy 320M/80 - MC (điều chuyển thùng 76 thành thùng 80)
A16: =+A15+1 -> 8 | B16: 45727 | C16: Vỏ thùng otakami 320/76 | D16: cái | F16: =5*20+6 -> 106 | G16: =+G15+E16-F16 -> 2193 | H16: Nguyễn Thanh Tâm | I16: SX
A17: =+A16+1 -> 9 | B17: 45728 | D17: cái | F17: 77 | G17: =+G16+E17-F17 -> 2116
A18: =+A17+1 -> 10 | B18: 45729 | D18: cái | F18: 62 | G18: =+G17+E18-F18 -> 2054 | H18: Nguyễn Thanh Tâm | I18: SX
A19: =+A18+1 -> 11 | B19: 45731 | D19: cái | F19: =12*20+9+1 -> 250 | G19: =+G18+E19-F19 -> 1804 | H19: Nguyễn Thanh Tâm | I19: SX
A20: =+A19+1 -> 12 | B20: 45733 | C20: xuất thùng 76 sang 80 đặt lẫn vào nhau 40 cái | D20: cái | F20: =367+80 -> 447 | G20: =+G19+E20-F20 -> 1357 | H20: Nguyễn Thanh Tâm | I20: SX | J20: Trong 407 cái vỏ thùng có 40 cái lẫn thùng 80
A21: =+A20+1 -> 13 | B21: 45734 | D21: cái | F21: 343 | G21: =+G20+E21-F21 -> 1014 | H21: Nguyễn Thanh Tâm | I21: SX
A22: =+A21+1 -> 14 | B22: 45735 | D22: cái | F22: 167 | G22: =+G21+E22-F22 -> 847 | H22: Nguyễn Thanh Tâm | I22: SX
A23: =+A22+1 -> 15 | B23: 45749 | D23: cái | F23: 340 | G23: =+G22+E23-F23 -> 507
A24: =+A23+1 -> 16 | B24: 45761 | D24: cái | E24: 300 | G24: =+G23+E24-F24 -> 807
A25: =+A24+1 -> 17 | B25: 45762 | D25: cái | F25: 15 | G25: =+G24+E25-F25 -> 792
A26: =+A25+1 -> 18 | B26: 45763 | D26: cái | F26: 306 | G26: =+G25+E26-F26 -> 486
A27: =+A26+1 -> 19 | B27: 45766 | D27: cái | E27: 300 | G27: =+G26+E27-F27 -> 786
A28: =+A27+1 -> 20 | B28: 45768 | D28: cái | F28: 129 | G28: =+G27+E28-F28 -> 657
A29: =+A28+1 -> 21 | B29: 45769 | D29: cái | F29: 125 | G29: =+G28+E29-F29 -> 532
A30: =+A29+1 -> 22 | B30: 45771 | D30: cái | E30: 200 | G30: =+G29+E30-F30 -> 732
A31: =+A30+1 -> 23 | B31: 45774 | D31: cái | F31: 251 | G31: =+G30+E31-F31 -> 481
A32: =+A31+1 -> 24 | B32: 45776 | D32: cái | F32: 68 | G32: =+G31+E32-F32 -> 413 | K32: =259+176 -> 435
A33: =+A32+1 -> 25 | B33: 45782 | D33: cái | F33: 259 | G33: =+G32+E33-F33 -> 154 | K33: =+K32-183 -> 252
A34: =+A33+1 -> 26 | B34: 45786 | D34: cái | E34: 22 | G34: =+G33+E34-F34 -> 176
A35: =+A34+1 -> 27 | B35: 45796 | D35: cái | F35: 176 | G35: =+G34+E35-F35 -> 0 | H35: Chạy hàng 320/86
A36: =+A35+1 -> 28 | D36: cái | G36: =+G35+E36-F36 -> 0
A37: =+A36+1 -> 29 | D37: cái | G37: =+G36+E37-F37 -> 0
A38: =+A37+1 -> 30 | D38: cái | G38: =+G37+E38-F38 -> 0
A39: =+A38+1 -> 31 | D39: cái | G39: =+G38+E39-F39 -> 0
A40: =+A39+1 -> 32 | D40: cái | G40: =+G39+E40-F40 -> 0
A41: =+A40+1 -> 33 | D41: cái | G41: =+G40+E41-F41 -> 0
A42: =+A41+1 -> 34 | D42: cái | G42: =+G41+E42-F42 -> 0
A43: =+A42+1 -> 35 | D43: cái | G43: =+G42+E43-F43 -> 0
...

Sheet THÙNG OTAKAMI180,80  
A1: Công ty TNHH Giấy Đông Á
A2: Thôn Mộc Ty, xã Trưng Trắc, huyện Văn Lâm, tỉnh Hưng Yên
A4: THẺ KHO NGUYÊN VẬT LIỆU
A8: STT | B8: Ngày tháng | C8: Tên nguyên vật liệu | D8: ĐVT | E8: Số lượng nhập | F8: Số lượng xuất | G8: Tồn | H8: Người nhận | I8: Ghi chú
C9: Tồn đầu kỳ
A10: 1 | B10: 45703 | C10: Thùng otakami 180/80 | D10: Cái | E10: 450 | G10: =+G9+E10-F10 -> 450 | H10: Nguyễn Thanh Tâm | I10: SX
A11: 2 | B11: 45705 | C11: Thùng otakami 180/80 | D11: Cái | E11: 50 | G11: =+G10+E11-F11 -> 500 | H11: Nguyễn Thanh Tâm | I11: SX
A12: =+A11+1 -> 3 | B12: 45716 | D12: Cái | F12: 22 | G12: =+G11+E12-F12 -> 478 | H12: Nguyễn Thanh Tâm | I12: SX | K12: 22
A13: =+A12+1 -> 4 | B13: 45723 | D13: Cái | F13: 118 | G13: =+G12+E13-F13 -> 360 | H13: Nguyễn Thanh Tâm | I13: SX | K13: 118
A14: =+A13+1 -> 5 | B14: 45724 | D14: Cái | F14: 14 | G14: =+G13+E14-F14 -> 346 | H14: Nguyễn Thanh Tâm | I14: SX | K14: 14
A15: =+A14+1 -> 6 | B15: 45724 | C15: Nhập lại vỏ thùng hàng lỗi lọc ra | D15: Cái | E15: 57 | G15: =+G14+E15-F15 -> 403
A16: =+A15+1 -> 7 | B16: 45729 | D16: Cái | F16: 141 | G16: =+G15+E16-F16 -> 262 | H16: Nguyễn Thanh Tâm | I16: SX | K16: 141
A17: =+A16+1 -> 8 | B17: 45730 | D17: Cái | F17: 120 | G17: =+G16+E17-F17 -> 142 | K17: 120
A18: =+A17+1 -> 9 | B18: 45735 | D18: Cái | F18: 99 | G18: =+G17+E18-F18 -> 43 | H18: Nguyễn Thanh Tâm | I18: SX | K18: 99
A19: =+A18+1 -> 10 | B19: 45738 | D19: Cái | F19: 4 | G19: =+G18+E19-F19 -> 39 | H19: Nguyễn Thanh Tâm | I19: SX | K19: 4
A20: =+A19+1 -> 11 | B20: 45762 | D20: Cái | F20: 19 | G20: =+G19+E20-F20 -> 20 | H20: Nguyễn Thanh Tâm | I20: SX | K20: 19
A21: =+A20+1 -> 12 | B21: 45759 | D21: Cái | E21: 300 | F21: 23 | G21: =+G20+E21-F21 -> 297 | H21: Nguyễn Thanh Tâm | I21: SX | K21: =SUM(K12:K20) -> 537
A22: =+A21+1 -> 13 | D22: Cái | G22: =+G21+E22-F22 -> 297 | H22: Nguyễn Thanh Tâm | I22: SX | K22: =800-K21 -> 263 | N22: =3420-1143 -> 2277
A23: =+A22+1 -> 14 | D23: Cái | G23: =+G22+E23-F23 -> 297 | H23: Nguyễn Thanh Tâm | I23: SX
A24: =+A23+1 -> 15 | D24: Cái | G24: =+G23+E24-F24 -> 297 | H24: Nguyễn Thanh Tâm | I24: SX
A25: =+A24+1 -> 16 | D25: Cái | G25: =+G24+E25-F25 -> 297 | H25: Nguyễn Thanh Tâm | I25: SX
A26: =+A25+1 -> 17 | D26: Cái | G26: =+G25+E26-F26 -> 297 | H26: Nguyễn Thanh Tâm | I26: SX | Q26: =280+44 -> 324
A27: =+A26+1 -> 18 | D27: Cái | G27: =+G26+E27-F27 -> 297 | H27: Nguyễn Thanh Tâm | I27: SX
A28: =+A27+1 -> 19 | D28: Cái | G28: =+G27+E28-F28 -> 297 | H28: Nguyễn Thanh Tâm | I28: SX
A29: =+A28+1 -> 20 | D29: Cái | G29: =+G28+E29-F29 -> 297 | H29: Nguyễn Thanh Tâm | I29: SX
A30: =+A29+1 -> 21 | D30: Cái | G30: =+G29+E30-F30 -> 297 | H30: Nguyễn Thị Liên | I30: Thử máy
A31: =+A30+1 -> 22 | D31: Cái | G31: =+G30+E31-F31 -> 297 | H31: Nguyễn Thị Liên | I31: SX
A32: =+A31+1 -> 23 | D32: Cái | G32: =+G31+E32-F32 -> 297 | H32: Nguyễn Thị Liên | I32: SX
A33: =+A32+1 -> 24 | D33: cái | G33: =+G32+E33-F33 -> 297 | H33: Nguyễn thị Liên | I33: SX
A34: =+A33+1 -> 25 | D34: cái | G34: =+G33+E34-F34 -> 297
A35: =+A34+1 -> 26 | D35: cái | G35: =+G34+E35-F35 -> 297 | H35: Nguyễn Thanh Tâm | I35: SX
A36: =+A35+1 -> 27 | D36: cái | G36: =+G35+E36-F36 -> 297 | H36: Nguyễn Thanh Tâm | I36: SX
A37: =+A36+1 -> 28 | D37: cái | G37: =+G36+E37-F37 -> 297 | H37: Nguyễn Thanh Tâm | I37: SX
A38: =+A37+1 -> 29 | D38: cái | G38: =+G37+E38-F38 -> 297 | H38: Nguyễn Thanh Tâm | I38: SX
A39: =+A38+1 -> 30 | D39: cái | G39: =+G38+E39-F39 -> 297 | H39: Nguyễn Thanh Tâm | I39: SX
A40: =+A39+1 -> 31 | D40: cái | G40: =+G39+E40-F40 -> 297 | H40: Nguyễn Thanh Tâm | I40: SX
A41: =+A40+1 -> 32 | D41: cái | G41: =+G40+E41-F41 -> 297 | H41: Nguyễn Thanh Tâm | I41: SX
A42: =+A41+1 -> 33 | D42: cái | G42: =+G41+E42-F42 -> 297 | H42: Nguyễn Thanh Tâm | I42: SX
A43: =+A42+1 -> 34 | D43: cái | G43: =+G42+E43-F43 -> 297
A44: =+A43+1 -> 35 | D44: cái | G44: =+G43+E44-F44 -> 297
...

Sheet Thùng otakami 700,80
A1: Công ty TNHH Giấy Đông Á
A2: Thôn Mộc Ty, xã Trưng Trắc, huyện Văn Lâm, tỉnh Hưng Yên
A4: THẺ KHO NGUYÊN VẬT LIỆU
A8: STT | B8: Ngày tháng | C8: Tên nguyên vật liệu | D8: ĐVT | E8: Số lượng nhập | F8: Số lượng xuất | G8: Tồn | H8: Người nhận | I8: Ghi chú
C9: Tồn đầu kỳ
A10: 1 | B10: 45705 | C10: Thùng otakami 700g/80 | D10: cái | E10: 600 | G10: =+G9+E10-F10 -> 600
A11: =+A10+1 -> 2 | B11: 45710 | C11: Thùng otakami 700g/80 | D11: cái | F11: 311 | G11: =+G10+E11-F11 -> 289
A12: =+A11+1 -> 3 | B12: 45712 | D12: cái | F12: 63 | G12: =+G11+E12-F12 -> 226
A13: =+A12+1 -> 4 | B13: 45713 | D13: cái | F13: 226 | G13: =+G12+E13-F13 -> 0
A14: =+A13+1 -> 5 | B14: 45769 | D14: cái | E14: 300 | G14: =+G13+E14-F14 -> 300
A15: =+A14+1 -> 6 | B15: 45770 | D15: cái | F15: 55 | G15: =+G14+E15-F15 -> 245
A16: =+A15+1 -> 7 | B16: 45793 | D16: cái | E16: 400 | G16: =+G15+E16-F16 -> 645
A17: =+A16+1 -> 8 | B17: 45815 | D17: cái | F17: 197 | G17: =+G16+E17-F17 -> 448
A18: =+A17+1 -> 9 | B18: 45817 | D18: cái | F18: 39 | G18: =+G17+E18-F18 -> 409
A19: =+A18+1 -> 10 | B19: 45828 | D19: cái | F19: 17 | G19: =+G18+E19-F19 -> 392
A20: =+A19+1 -> 11 | B20: 45834 | C20: Xuất trả jp | D20: cái | F20: 410 | G20: =+G19+E20-F20 -> -18
A21: =+A20+1 -> 12 | D21: cái | G21: =+G20+E21-F21 -> -18
A22: =+A21+1 -> 13 | D22: cái | G22: =+G21+E22-F22 -> -18
A23: =+A22+1 -> 14 | D23: cái | G23: =+G22+E23-F23 -> -18
A24: =+A23+1 -> 15 | D24: cái | G24: =+G23+E24-F24 -> -18
A25: =+A24+1 -> 16 | D25: cái | G25: =+G24+E25-F25 -> -18
A26: =+A25+1 -> 17 | D26: cái | G26: =+G25+E26-F26 -> -18
A27: =+A26+1 -> 18 | D27: cái | G27: =+G26+E27-F27 -> -18
A28: =+A27+1 -> 19 | D28: cái | G28: =+G27+E28-F28 -> -18
A29: =+A28+1 -> 20 | D29: cái | G29: =+G28+E29-F29 -> -18
A30: =+A29+1 -> 21 | D30: cái | G30: =+G29+E30-F30 -> -18
A31: =+A30+1 -> 22 | D31: cái | G31: =+G30+E31-F31 -> -18
A32: =+A31+1 -> 23 | D32: cái | G32: =+G31+E32-F32 -> -18
... A41: =+A40+1 -> 32 | D41: cái | G41: =+G40+E41-F41 -> -18
C42: Tổng cộng | E42: =SUM(E10:E41) -> 1300 | F42: =SUM(F10:F41) -> 1318 | G42: =+E42-F42+G9 -> -18

Sheet Thùng otakami 700,76 
A1: Công ty TNHH Giấy Đông Á
A2: Thôn Mộc Ty, xã Trưng Trắc, huyện Văn Lâm, tỉnh Hưng Yên
A4: =+'[1]Hộp CB'!A4:I5 -> THẺ KHO NGUYÊN VẬT LIỆU
A7: STT | B7: Ngày tháng | C7: Tên nguyên vật liệu | D7: ĐVT | E7: Số lượng nhập | F7: Số lượng xuất | G7: Tồn | H7: Người nhận | I7: Ghi chú
C8: Tồn đầu kỳ
A9: 1 | B9: 45705 | C9: Thùng otakami700g/76 | D9: Cái | E9: 300 | G9: =+G8+E9-F9 -> 300 | H9: Nguyễn Thanh Tâm | I9: Sản xuất
A10: =+A9+1 -> 2 | B10: 45714 | D10: Cái | F10: 160 | G10: =+G9+E10-F10 -> 140 | H10: Nguyễn Thanh Tâm | I10: Sản xuất
A11: =+A10+1 -> 3 | B11: 45715 | D11: Cái | F11: 140 | G11: =+G10+E11-F11 -> 0 | H11: Nguyễn Thanh Tâm | I11: Sản xuất
A12: =+A11+1 -> 4 | B12: 45771 | D12: Cái | E12: 200 | G12: =+G11+E12-F12 -> 200 | H12: Nguyễn Thanh Tâm | I12: Sản xuất
A13: =+A12+1 -> 5 | B13: 45828 | D13: Cái | F13: 116 | G13: =+G12+E13-F13 -> 84
A14: =+A13+1 -> 6 | B14: 45835 | D14: Cái | F14: 124 | G14: =+G13+E14-F14 -> -40 | H14: Nguyễn Thanh Tâm | I14: Sản xuất
A15: =+A14+1 -> 7 | D15: Cái | G15: =+G14+E15-F15 -> -40 | H15: Nguyễn Thanh Tâm | I15: Sản xuất
A16: =+A15+1 -> 8 | D16: Cái | G16: =+G15+E16-F16 -> -40 | H16: Nguyễn Thanh Tâm | I16: Sản xuất
A17: =+A16+1 -> 9 | D17: Cái | G17: =+G16+E17-F17 -> -40 | H17: Nguyễn Thanh Tâm | I17: Sản xuất
A18: =+A17+1 -> 10 | D18: Cái | G18: =+G17+E18-F18 -> -40
A19: =+A18+1 -> 11 | D19: Cái | G19: =+G18+E19-F19 -> -40
A20: =+A19+1 -> 12 | D20: Cái | G20: =+G19+E20-F20 -> -40
A21: =+A20+1 -> 13 | D21: Cái | G21: =+G20+E21-F21 -> -40
A22: =+A21+1 -> 14 | D22: Cái | G22: =+G21+E22-F22 -> -40
A23: =+A22+1 -> 15 | D23: Cái | G23: =+G22+E23-F23 -> -40
A24: =+A23+1 -> 16 | D24: Cái | G24: =+G23+E24-F24 -> -40
A25: =+A24+1 -> 17 | D25: Cái | G25: =+G24+E25-F25 -> -40
A26: =+A25+1 -> 18 | D26: Cái | G26: =+G25+E26-F26 -> -40
A27: =+A26+1 -> 19 | D27: Cái | G27: =+G26+E27-F27 -> -40
A28: =+A27+1 -> 20 | D28: Cái | G28: =+G27+E28-F28 -> -40
A29: =+A28+1 -> 21 | D29: Cái | G29: =+G28+E29-F29 -> -40
... A51: =+A50+1 -> 43 | D51: Cái | G51: =+G50+E51-F51 -> -40
A52: =+A51+1 -> 44 | G52: =+G51+E52-F52 -> -40
A53: =+A52+1 -> 45 | G53: =+G52+E53-F53 -> -40
A54: =+A53+1 -> 46 | G54: =+G53+E54-F54 -> -40
A55: =+A54+1 -> 47 | G55: =+G54+E55-F55 -> -40
A56: =+A55+1 -> 48 | G56: =+G55+E56-F56 -> -40
A57: =+A56+1 -> 49 | G57: =+G56+E57-F57 -> -40
A58: =+A57+1 -> 50 | G58: =+G57+E58-F58 -> -40
A59: =+A58+1 -> 51 | G59: =+G58+E59-F59 -> -40
A60: =+A59+1 -> 52 | G60: =+G59+E60-F60 -> -40
C61: Tổng cộng | E61: =SUM(E9:E60) -> 500 | F61: =SUM(F9:F60) -> 540 | G61: =+G8+E61-F61 -> -40
F62: =18676-18566 -> 110
H66: =25*60+6+46 -> 1552
H67: =1545-1552 -> -7

Sheet Thùng otakami 160,80
A1: Công ty TNHH Giấy Đông Á
A2: Thôn Mộc Ty, xã Trưng Trắc, huyện Văn Lâm, tỉnh Hưng Yên
A4: =+'[1]Hộp CB'!A4:I5 -> THẺ KHO NGUYÊN VẬT LIỆU
J5: =5+10+5+2+10+10+3+7+8 -> 60
A7: STT | B7: Ngày tháng | C7: Tên nguyên vật liệu | D7: ĐVT | E7: Số lượng nhập | F7: Số lượng xuất | G7: Tồn | H7: Người nhận | I7: Ghi chú
C8: Tồn đầu kỳ
A9: 1 | B9: 45705 | C9: Thùng otakami 160/80 | D9: Cái | E9: 400 | G9: =+G8+E9-F9 -> 400 | H9: Nguyễn thanh Tâm | I9: SX
A10: =+A9+1 -> 2 | B10: 45736 | D10: Cái | F10: 183 | G10: =+G9+E10-F10 -> 217 | H10: Nguyễn Thị Liên | I10: SX
A11: =+A10+1 -> 3 | B11: 45750 | F11: 217 | G11: =+G10+E11-F11 -> 0 | H11: Nguyễn thanh Tâm | I11: SX
A12: =+A11+1 -> 4 | G12: =+G11+E12-F12 -> 0 | H12: Nguyễn thanh Tâm | I12: SX
A13: =+A12+1 -> 5 | G13: =+G12+E13-F13 -> 0 | H13: Nguyễn thanh Tâm | I13: SX
A14: =+A13+1 -> 6 | G14: =+G13+E14-F14 -> 0 | H14: Nguyễn thanh Tâm | I14: SX
A15: =+A14+1 -> 7 | G15: =+G14+E15-F15 -> 0
A16: =+A15+1 -> 8 | G16: =+G15+E16-F16 -> 0
A17: =+A16+1 -> 9 | G17: =+G16+E17-F17 -> 0
A18: =+A17+1 -> 10 | G18: =+G17+E18-F18 -> 0
A19: =+A18+1 -> 11 | G19: =+G18+E19-F19 -> 0
A20: =+A19+1 -> 12 | G20: =+G19+E20-F20 -> 0
A21: =+A20+1 -> 13 | G21: =+G20+E21-F21 -> 0
A22: =+A21+1 -> 14 | G22: =+G21+E22-F22 -> 0
A23: =+A22+1 -> 15 | G23: =+G22+E23-F23 -> 0
A24: =+A23+1 -> 16 | G24: =+G23+E24-F24 -> 0
A25: =+A24+1 -> 17 | G25: =+G24+E25-F25 -> 0
A26: =+A25+1 -> 18 | G26: =+G25+E26-F26 -> 0
... A41: =+A40+1 -> 33 | G41: =+G40+E41-F41 -> 0
G42: =+G41+E42-F42 -> 0
C43: Tổng cộng | E43: =SUM(E9:E42) -> 400 | F43: =SUM(F9:F42) -> 400 | G43: =+G8+E43-F43 -> 0
F44: =18676-18566 -> 110
F54: =481-442 -> 39
G60: =442-360 -> 82

Sheet Phôi DL 15,2L
A1: Công ty TNHH Giấy Đông Á
A2: Thôn Mộc Ty, xã Trưng Trắc, huyện Văn Lâm, tỉnh Hưng Yên
A4: THẺ KHO NGUYÊN VẬT LIỆU
A8: STT | B8: Ngày tháng | C8: Tên nguyên vật liệu | D8: ĐVT | E8: Số lượng nhập | F8: Số lượng xuất | G8: Tồn | H8: Người nhận | I8: Ghi chú
C9: Tồn đầu kỳ
A10: 1 | B10: 45708 | C10: Phôi Định Lượng 15. 2 Lớp (320 M) | D10: Kg | E10: 13458 | G10: =+G9+E10-F10 -> 13458 | H10: Nguyễn Thanh Tâm | I10: 17 cuộn
A11: =+A10+1 -> 2 | B11: 45709 | D11: Kg | E11: 19210 | G11: =+G10+E11-F11 -> 32668 | H11: Nguyễn Thanh Tâm | I11: 24 cuộn
A12: =+A11+1 -> 3 | B12: 45712 | D12: Kg | F12: 758 | G12: =+G11+E12-F12 -> 31910 | H12: Nguyễn Thanh Tâm | I12: SX
A13: =+A12+1 -> 4 | B13: 45716 | D13: Kg | F13: 794 | G13: =+G12+E13-F13 -> 31116 | H13: Nguyễn Thanh Tâm | I13: SX
A14: =+A13+1 -> 5 | B14: 45717 | D14: Kg | F14: 2318 | G14: =+G13+E14-F14 -> 28798 | H14: Nguyễn Thanh Tâm | I14: SX
A15: =+A14+1 -> 6 | B15: 45719 | D15: Kg | F15: 3194 | G15: =+G14+E15-F15 -> 25604 | H15: Nguyễn Thanh Tâm | I15: SX | J15: Hỏng 5 hộp
A16: =+A15+1 -> 7 | B16: 45720 | D16: Kg | F16: 3316 | G16: =+G15+E16-F16 -> 22288
A17: =+A16+1 -> 8 | B17: 45721 | D17: Kg | F17: 3276 | G17: =+G16+E17-F17 -> 19012
A18: =+A17+1 -> 9 | B18: 45694 | D18: Kg | F18: 3137 | G18: =+G17+E18-F18 -> 15875
A19: =+A18+1 -> 10 | B19: 45724 | D19: Kg | F19: 1594 | G19: =+G18+E19-F19 -> 14281
A20: =+A19+1 -> 11 | B20: 45726 | F20: 2457 | G20: =+G19+E20-F20 -> 11824
A21: =+A20+1 -> 12 | B21: 45727 | F21: 3803 | G21: =+G20+E21-F21 -> 8021
A22: =+A21+1 -> 13 | B22: 45728 | F22: 3955 | G22: =+G21+E22-F22 -> 4066
A23: =+A22+1 -> 14 | B23: 45729 | F23: 882 | G23: =+G22+E23-F23 -> 3184 | M23: =28798+6336 -> 35134
A24: =+A23+1 -> 15 | B24: 45730 | E24: 6336 | G24: =+G23+E24-F24 -> 9520 | O24: =7*20+17 -> 157
A25: =+A24+1 -> 16 | B25: 45731 | F25: =742+800+806 -> 2348 | G25: =+G24+E25-F25 -> 7172 | O25: =+O24*16 -> 2512
A26: =+A25+1 -> 17 | B26: 45734 | F26: 4730 | G26: =+G25+E26-F26 -> 2442 | O26: =+O25*91 -> 228592
A27: =+A26+1 -> 18 | B27: 45735 | F27: 1620 | G27: =+G26+E27-F27 -> 822 | J27: =+F27-1843 -> -223 | O27: =+O26/2810 -> 81.349466
A28: =+A27+1 -> 19 | B28: 45740 | F28: 822 | G28: =+G27+E28-F28 -> 0
A29: =+A28+1 -> 20 | G29: =+G28+E29-F29 -> 0
A30: =+A29+1 -> 21 | G30: =+G29+E30-F30 -> 0
A31: =+A30+1 -> 22 | G31: =+G30+E31-F31 -> 0
A32: =+A31+1 -> 23 | G32: =+G31+E32-F32 -> 0 | K32: =788+741+770+832+788+811 -> 4730
A33: =+A32+1 -> 24 | G33: =+G32+E33-F33 -> 0
A34: =+A33+1 -> 25 | G34: =+G33+E34-F34 -> 0
A35: =+A34+1 -> 26 | G35: =+G34+E35-F35 -> 0
A36: =+A35+1 -> 27 | G36: =+G35+E36-F36 -> 0
G37: =+G36+E37-F37 -> 0
G38: =+G37+E38-F38 -> 0
G39: =+G38+E39-F39 -> 0
G40: =+G39+E40-F40 -> 0
G41: =+G40+E41-F41 -> 0
A42: =+A36+1 -> 28 | G42: =+G41+E42-F42 -> 0
A43: =+A42+1 -> 29 | G43: =+G42+E43-F43 -> 0
A44: =+A43+1 -> 30 | G44: =+G43+E44-F44 -> 0
...

Sheet Phôi DL 15,5. 2 L
A1: Công ty TNHH Giấy Đông Á
A2: Thôn Mộc Ty, xã Trưng Trắc, huyện Văn Lâm, tỉnh Hưng Yên
A4: THẺ KHO NGUYÊN VẬT LIỆU
A8: STT | B8: Ngày tháng | C8: Tên nguyên vật liệu | D8: ĐVT | E8: Số lượng nhập | F8: Số lượng xuất | G8: Tồn | H8: Người nhận | I8: Ghi chú
C9: Tồn đầu kỳ
A10: 1 | B10: 45730 | C10: Phôi Định Lượng 15.5 2 lớp | D10: Kg | E10: 7112 | G10: =+G9+E10-F10 -> 7112 | H10: Nguyễn Thanh Tâm | I10: 17 cuộn
A11: =+A10+1 -> 2 | B11: 45731 | D11: Kg | F11: 787 | G11: =+G10+E11-F11 -> 6325 | H11: Nguyễn Thanh Tâm | I11: 24 cuộn
A12: =+A11+1 -> 3 | B12: 45733 | D12: Kg | F12: 5329 | G12: =+G11+E12-F12 -> 996 | H12: Nguyễn Thanh Tâm | I12: SX
A13: =+A12+1 -> 4 | B13: 45734 | D13: Kg | F13: 996 | G13: =+G12+E13-F13 -> 0 | H13: Nguyễn Thanh Tâm | I13: SX
A14: =+A13+1 -> 5 | B14: 45735 | D14: Kg | E14: 17954 | G14: =+G13+E14-F14 -> 17954 | H14: Nguyễn Thanh Tâm | I14: SX
A15: =+A14+1 -> 6 | B15: 45736 | D15: Kg | E15: 18346 | G15: =+G14+E15-F15 -> 36300 | H15: Nguyễn Thanh Tâm | I15: SX
A16: =+A15+1 -> 7 | B16: 45737 | D16: Kg | F16: 3954 | G16: =+G15+E16-F16 -> 32346
A17: =+A16+1 -> 8 | B17: 45738 | D17: Kg | F17: 2053 | G17: =+G16+E17-F17 -> 30293
A18: =+A17+1 -> 9 | B18: 45739 | D18: Kg | F18: 1082 | G18: =+G17+E18-F18 -> 29211
A19: =+A18+1 -> 10 | B19: 45740 | D19: Kg | F19: 2957 | G19: =+G18+E19-F19 -> 26254
A20: =+A19+1 -> 11 | B20: 45743 | F20: 1951 | G20: =+G19+E20-F20 -> 24303
A21: =+A20+1 -> 12 | B21: 45744 | F21: 3136 | G21: =+G20+E21-F21 -> 21167
A22: =+A21+1 -> 13 | B22: 45746 | F22: =4812-1039 -> 3773 | G22: =+G21+E22-F22 -> 17394
A23: =+A22+1 -> 14 | B23: 45747 | F23: 4877 | G23: =+G22+E23-F23 -> 12517
A24: =+A23+1 -> 15 | B24: 45748 | E24: =931+995+946 -> 2872 | F24: 3979 | G24: =+G23+E24-F24 -> 11410
A25: =+A24+1 -> 16 | B25: 45749 | F25: 4935 | G25: =+G24+E25-F25 -> 6475 | L25: =37452+30895 -> 68347
A26: =+A25+1 -> 17 | B26: 45750 | F26: 931 | G26: =+G25+E26-F26 -> 5544
A27: =+A26+1 -> 18 | B27: 45751 | F27: 4602 | G27: =+G26+E27-F27 -> 942 | M27: =38246+30895 -> 69141
A28: =+A27+1 -> 19 | B28: 45752 | F28: 942 | G28: =+G27+E28-F28 -> 0 | H28: Do cấn trừ phôi | I28: 995 | J28: =995-942 -> 53
A29: =+A28+1 -> 20 | B29: 45758 | E29: 8639 | G29: =+G28+E29-F29 -> 8639
A30: =+A29+1 -> 21 | B30: 45761 | E30: 13310 | G30: =+G29+E30-F30 -> 21949
A31: =+A30+1 -> 22 | B31: 45762 | F31: 931 | G31: =+G30+E31-F31 -> 21018
A32: =+A31+1 -> 23 | B32: 45763 | F32: 3781 | G32: =+G31+E32-F32 -> 17237
A33: =+A32+1 -> 24 | B33: 45764 | F33: 3863 | G33: =+G32+E33-F33 -> 13374
A34: =+A33+1 -> 25 | B34: 45765 | F34: 3790 | G34: =+G33+E34-F34 -> 9584
A35: =+A34+1 -> 26 | B35: 45766 | F35: 3705 | G35: =+G34+E35-F35 -> 5879
A36: =+A35+1 -> 27 | B36: 45768 | F36: 2952 | G36: =+G35+E36-F36 -> 2927
A37: =+A36+1 -> 28 | B37: 45769 | F37: 1894 | G37: =+G36+E37-F37 -> 1033
A38: =+A37+1 -> 29 | B38: 45787 | G38: =+G37+E38-F38 -> 1033
A39: =+A38+1 -> 30 | B39: 45786 | E39: 18512 | G39: =+G38+E39-F39 -> 19545
A40: =+A39+1 -> 31 | B40: 45787 | F40: 1945 | G40: =+G39+E40-F40 -> 17600
A41: =+A40+1 -> 32 | B41: 45789 | F41: 1007 | G41: =+G40+E41-F41 -> 16593
A42: =+A41+1 -> 33 | B42: 45792 | F42: 995 | G42: =+G41+E42-F42 -> 15598
A43: =+A42+1 -> 34 | B43: 45794 | F43: 981 | G43: =+G42+E43-F43 -> 14617
A44: =+A43+1 -> 35 | B44: 45796 | F44: 3913 | G44: =+G43+E44-F44 -> 10704
...

Sheet Phôi DL 18,2L.700g
A1: Công ty TNHH Giấy Đông Á
A2: Thôn Mộc Ty, xã Trưng Trắc, huyện Văn Lâm, tỉnh Hưng Yên
A4: THẺ KHO NGUYÊN VẬT LIỆU
A8: STT | B8: Ngày tháng | C8: Tên nguyên vật liệu | D8: ĐVT | E8: Số lượng nhập | F8: Số lượng xuất | G8: Tồn | H8: Người nhận | I8: Ghi chú
C9: Tồn đầu kỳ
A10: 1 | B10: 45708 | C10: Phôi Định Lượng 18. 2 Lớp (700g) | D10: Hộp | E10: 4095 | G10: =+G9+E10-F10 -> 4095 | H10: Nguyễn Thanh Tâm | I10: 6
A11: =+A10+1 -> 2 | B11: 45710 | D11: Hộp | F11: 3415 | G11: =+G10+E11-F11 -> 680 | H11: Nguyễn Thanh Tâm | I11: 5
A12: =+A11+1 -> 3 | B12: 45712 | D12: Hộp | F12: 680 | G12: =+G11+E12-F12 -> 0 | H12: Nguyễn Thanh Tâm | I12: 1
A13: =+A12+1 -> 4 | B13: 45712 | D13: Hộp | E13: 1588 | G13: =+G12+E13-F13 -> 1588 | H13: Nguyễn Thanh Tâm | I13: 2
A14: =+A13+1 -> 5 | B14: 45714 | D14: Hộp | E14: 293 | F14: 1588 | G14: =+G13+E14-F14 -> 293 | H14: Nguyễn Thanh Tâm | I14: phôi k đúng định lượng | L14: =+F11+F12+F14+F17+F19 -> 8132 | M14: =+L14-E18-E19 -> 6898.8
A15: =+A14+1 -> 6 | B15: 45719 | D15: Hộp | F15: 293 | G15: =+G14+E15-F15 -> 0 | H15: Nguyễn Thanh Tâm | I15: SX
A16: =+A15+1 -> 7 | B16: 45748 | E16: 2426 | G16: =+G15+E16-F16 -> 2426 | N16: =+F11+F12+F14+F17+F19-E18-E19 -> 6898.8
A17: =+A16+1 -> 8 | B17: 45770 | F17: 1592 | G17: =+G16+E17-F17 -> 834
A18: =+A17+1 -> 9 | B18: 23/04/2025 | C18: Nhập lại cuộn 608,4 còn tồn và 134,3 kg trả lại jp do nhăn | E18: =608.4 -> 608.4 | G18: =+G17+E18-F18 -> 1442.4
A19: =+A18+1 -> 10 | B19: 45792 | C19: Nhập lại phôi do chạy k đạt đường kính | E19: =624.8 -> 624.8 | F19: 857 | G19: =+G18+E19-F19 -> 1210.2 | L19: =3160+834 -> 3994
A20: =+A19+1 -> 11 | B20: 45815 | F20: =608.4+624.8 -> 1233.2 | G20: =+G19+E20-F20 -> -23 | I20: Do khi nhập lại tịnh cân sai | K20: =+F19-E19 -> 232.2 | N20: =1592-743 -> 849
A21: =+A20+1 -> 12 | G21: =+G20+E21-F21 -> -23 | K21: =+K20/12 -> 19.35 | L21: =557+625+608.4 -> 1790.4 | N21: =857-625 -> 232
A22: =+A21+1 -> 13 | G22: =+G21+E22-F22 -> -23 | K22: =+K21/31 -> 0.62419355 | L22: =2646-L21 -> 855.6
A23: =+A22+1 -> 14 | G23: =+G22+E23-F23 -> -23
A24: =+A23+1 -> 15 | G24: =+G23+E24-F24 -> -23
A25: =+A24+1 -> 16 | G25: =+G24+E25-F25 -> -23
A26: =+A25+1 -> 17 | G26: =+G25+E26-F26 -> -23
A27: =+A26+1 -> 18 | G27: =+G26+E27-F27 -> -23 | L27: =3160+1198 -> 4358
A28: =+A27+1 -> 19 | G28: =+G27+E28-F28 -> -23 | L28: =4370-L27 -> 12
A29: =+A28+1 -> 20 | G29: =+G28+E29-F29 -> -23 | K29: =857-E19 -> 232.2
A30: =+A29+1 -> 21 | G30: =+G29+E30-F30 -> -23
A31: =+A30+1 -> 22 | G31: =+G30+E31-F31 -> -23
A32: =+A31+1 -> 23 | G32: =+G31+E32-F32 -> -23
A33: =+A32+1 -> 24 | G33: =+G32+E33-F33 -> -23
A34: =+A33+1 -> 25 | G34: =+G33+E34-F34 -> -23
A35: =+A34+1 -> 26 | G35: =+G34+E35-F35 -> -23
A36: =+A35+1 -> 27 | G36: =+G35+E36-F36 -> -23
G37: =+G36+E37-F37 -> -23
G38: =+G37+E38-F38 -> -23
G39: =+G38+E39-F39 -> -23
G40: =+G39+E40-F40 -> -23
G41: =+G40+E41-F41 -> -23
A42: =+A36+1 -> 28 | G42: =+G41+E42-F42 -> -23
A43: =+A42+1 -> 29 | G43: =+G42+E43-F43 -> -23
A44: =+A43+1 -> 30 | G44: =+G43+E44-F44 -> -23
...

Sheet Phôi DL 18,1L.700g ,2 L
A1: Công ty TNHH Giấy Đông Á
A2: Thôn Mộc Ty, xã Trưng Trắc, huyện Văn Lâm, tỉnh Hưng Yên
A4: THẺ KHO NGUYÊN VẬT LIỆU
A8: STT | B8: Ngày tháng | C8: Tên nguyên vật liệu | D8: ĐVT | E8: Số lượng nhập | F8: Số lượng xuất | G8: Tồn | H8: Người nhận | I8: Ghi chú
C9: Tồn đầu kỳ
A10: 1 | B10: 45712 | C10: Phôi Định Lượng 18. 1 Lớp (700g) | D10: Hộp | E10: 2342 | G10: =+G9+E10-F10 -> 2342 | H10: Nguyễn Thanh Tâm | I10: 3
A11: =+A10+1 -> 2 | B11: 45713 | D11: Hộp | F11: 798 | G11: =+G10+E11-F11 -> 1544 | H11: Nguyễn Thanh Tâm | J11: Chạy 700g/80 Có 52 thùng chạy 700g/76
A12: =+A11+1 -> 3 | B12: 45730 | D12: Hộp | F12: 1544 | G12: =+G11+E12-F12 -> 0 | H12: Nguyễn Thanh Tâm
A13: =+A12+1 -> 4 | B13: 45748 | C13: Phôi Định Lượng 18. 2 Lớp (700g) | D13: Hộp | G13: =+G12+E13-F13 -> 0 | H13: Nguyễn Thanh Tâm
A14: =+A13+1 -> 5 | D14: Hộp | G14: =+G13+E14-F14 -> 0 | H14: Nguyễn Thanh Tâm
A15: =+A14+1 -> 6 | D15: Hộp | G15: =+G14+E15-F15 -> 0 | H15: Nguyễn Thanh Tâm | I15: SX | J15: Hỏng 5 hộp
A16: =+A15+1 -> 7 | G16: =+G15+E16-F16 -> 0
A17: =+A16+1 -> 8 | G17: =+G16+E17-F17 -> 0
A18: =+A17+1 -> 9 | G18: =+G17+E18-F18 -> 0
A19: =+A18+1 -> 10 | G19: =+G18+E19-F19 -> 0
A20: =+A19+1 -> 11 | G20: =+G19+E20-F20 -> 0
A21: =+A20+1 -> 12 | G21: =+G20+E21-F21 -> 0
A22: =+A21+1 -> 13 | G22: =+G21+E22-F22 -> 0
A23: =+A22+1 -> 14 | G23: =+G22+E23-F23 -> 0
A24: =+A23+1 -> 15 | G24: =+G23+E24-F24 -> 0
A25: =+A24+1 -> 16 | G25: =+G24+E25-F25 -> 0
A26: =+A25+1 -> 17 | G26: =+G25+E26-F26 -> 0
A27: =+A26+1 -> 18 | G27: =+G26+E27-F27 -> 0
... A36: =+A35+1 -> 27 | G36: =+G35+E36-F36 -> 0
G37: =+G36+E37-F37 -> 0
G38: =+G37+E38-F38 -> 0
G39: =+G38+E39-F39 -> 0
G40: =+G39+E40-F40 -> 0
G41: =+G40+E41-F41 -> 0
A42: =+A36+1 -> 28 | G42: =+G41+E42-F42 -> 0
A43: =+A42+1 -> 29 | G43: =+G42+E43-F43 -> 0
A44: =+A43+1 -> 30 | G44: =+G43+E44-F44 -> 0
A45: =+A44+1 -> 31 | G45: =+G44+E45-F45 -> 0
A46: =+A45+1 -> 32 | G46: =+G45+E46-F46 -> 0
C47: Tổng cộng | E47: =SUM(E10:E46) -> 2342 | F47: =SUM(F10:F46) -> 2342 | G47: =+E47-F47+G9 -> 0

Sheet Phôi DL 23,2L.160m
A1: Công ty TNHH Giấy Đông Á
A2: Thôn Mộc Ty, xã Trưng Trắc, huyện Văn Lâm, tỉnh Hưng Yên
A4: THẺ KHO NGUYÊN VẬT LIỆU
A8: STT | B8: Ngày tháng | C8: Tên nguyên vật liệu | D8: ĐVT | E8: Số lượng nhập | F8: Số lượng xuất | G8: Tồn | H8: Người nhận | I8: Ghi chú
C9: Tồn đầu kỳ | D9: Kg
A10: 1 | C10: Phôi Định Lượng 23. 2 Lớp (160m) | D10: Kg | E10: 3568 | G10: =+G9+E10-F10 -> 3568 | H10: Nguyễn Thanh Tâm | I10: 5
A11: =+A10+1 -> 2 | B11: 45730 | D11: Kg | E11: =788-9 -> 779 | G11: =+G10+E11-F11 -> 4347 | H11: Nguyễn Thanh Tâm
A12: =+A11+1 -> 3 | B12: 45736 | D12: Kg | F12: 2191 | G12: =+G11+E12-F12 -> 2156 | H12: Nguyễn Thanh Tâm | I12: 3
A13: =+A12+1 -> 4 | B13: 45748 | D13: Kg | E13: =972+948+1011+940+840+955.4+972+948 -> 7586.4 | G13: =+G12+E13-F13 -> 9742.4 | H13: Nguyễn Thanh Tâm | I13: SX
A14: =+A13+1 -> 5 | B14: 45750 | D14: Kg | F14: 3128 | G14: =+G13+E14-F14 -> 6614.4 | H14: Nguyễn Thanh Tâm | I14: SX
A15: =+A14+1 -> 6 | B15: 45843 | C15: Xuất phôi trả jp | D15: Kg | F15: 4780 | G15: =+G14+E15-F15 -> 1834.4 | H15: Nguyễn Thanh Tâm | I15: SX | J15: Hỏng 5 hộp
A16: =+A15+1 -> 7 | G16: =+G15+E16-F16 -> 1834.4
A17: =+A16+1 -> 8 | G17: =+G16+E17-F17 -> 1834.4
A18: =+A17+1 -> 9 | G18: =+G17+E18-F18 -> 1834.4
A19: =+A18+1 -> 10 | G19: =+G18+E19-F19 -> 1834.4
A20: =+A19+1 -> 11 | G20: =+G19+E20-F20 -> 1834.4
A21: =+A20+1 -> 12 | G21: =+G20+E21-F21 -> 1834.4
A22: =+A21+1 -> 13 | G22: =+G21+E22-F22 -> 1834.4
A23: =+A22+1 -> 14 | G23: =+G22+E23-F23 -> 1834.4 | L23: =1011+840 -> 1851
A24: =+A23+1 -> 15 | G24: =+G23+E24-F24 -> 1834.4
A25: =+A24+1 -> 16 | G25: =+G24+E25-F25 -> 1834.4
A26: =+A25+1 -> 17 | G26: =+G25+E26-F26 -> 1834.4
A27: =+A26+1 -> 18 | G27: =+G26+E27-F27 -> 1834.4
A28: =+A27+1 -> 19 | G28: =+G27+E28-F28 -> 1834.4
A29: =+A28+1 -> 20 | G29: =+G28+E29-F29 -> 1834.4
A30: =+A29+1 -> 21 | G30: =+G29+E30-F30 -> 1834.4
A31: =+A30+1 -> 22 | G31: =+G30+E31-F31 -> 1834.4
A32: =+A31+1 -> 23 | G32: =+G31+E32-F32 -> 1834.4
A33: =+A32+1 -> 24 | G33: =+G32+E33-F33 -> 1834.4
A34: =+A33+1 -> 25 | G34: =+G33+E34-F34 -> 1834.4
A35: =+A34+1 -> 26 | G35: =+G34+E35-F35 -> 1834.4
A36: =+A35+1 -> 27 | G36: =+G35+E36-F36 -> 1834.4
G37: =+G36+E37-F37 -> 1834.4
G38: =+G37+E38-F38 -> 1834.4
G39: =+G38+E39-F39 -> 1834.4
G40: =+G39+E40-F40 -> 1834.4
G41: =+G40+E41-F41 -> 1834.4
A42: =+A36+1 -> 28 | G42: =+G41+E42-F42 -> 1834.4
A43: =+A42+1 -> 29 | G43: =+G42+E43-F43 -> 1834.4
A44: =+A43+1 -> 30 | G44: =+G43+E44-F44 -> 1834.4
...

Sheet Phôi DL 18,2L.600g 
A1: Công ty TNHH Giấy Đông Á
A2: Thôn Mộc Ty, xã Trưng Trắc, huyện Văn Lâm, tỉnh Hưng Yên
A4: THẺ KHO NGUYÊN VẬT LIỆU
A8: STT | B8: Ngày tháng | C8: Tên nguyên vật liệu | D8: ĐVT | E8: Số lượng nhập | F8: Số lượng xuất | G8: Tồn | H8: Người nhận | I8: Ghi chú
C9: Tồn đầu kỳ
A10: 1 | B10: 45712 | C10: Phôi Định Lượng 18. 2 Lớp (600g) | D10: Hộp | E10: 2139 | G10: =+G9+E10-F10 -> 2139 | H10: Nguyễn Thanh Tâm | I10: 3
A11: =+A10+1 -> 2 | B11: 45715 | D11: Hộp | F11: 2139 | G11: =+G10+E11-F11 -> 0 | H11: Nguyễn Thanh Tâm
A12: =+A11+1 -> 3 | B12: 45748 | D12: Hộp | E12: 3924 | G12: =+G11+E12-F12 -> 3924 | H12: Nguyễn Thanh Tâm | I12: SX
A13: =+A12+1 -> 4 | B13: 45769 | D13: Hộp | F13: 764 | G13: =+G12+E13-F13 -> 3160 | H13: Nguyễn Thanh Tâm | I13: SX
A14: =+A13+1 -> 5 | B14: 45815 | D14: Hộp | F14: =781+766 -> 1547 | G14: =+G13+E14-F14 -> 1613 | H14: Nguyễn Thanh Tâm | I14: SX
A15: =+A14+1 -> 6 | B15: 45828 | D15: Hộp | F15: 1590 | G15: =+G14+E15-F15 -> 23 | H15: Nguyễn Thanh Tâm | I15: SX | J15: Hỏng 5 hộp
A16: =+A15+1 -> 7 | G16: =+G15+E16-F16 -> 23
A17: =+A16+1 -> 8 | G17: =+G16+E17-F17 -> 23
A18: =+A17+1 -> 9 | G18: =+G17+E18-F18 -> 23
A19: =+A18+1 -> 10 | G19: =+G18+E19-F19 -> 23
A20: =+A19+1 -> 11 | G20: =+G19+E20-F20 -> 23 | L20: =3924+'Phôi DL 18,2L.700g'!L26+3924+1315 -> 9163 | O20: =5976+798+2139 -> 8913
A21: =+A20+1 -> 12 | G21: =+G20+E21-F21 -> 23
A22: =+A21+1 -> 13 | G22: =+G21+E22-F22 -> 23
A23: =+A22+1 -> 14 | G23: =+G22+E23-F23 -> 23
A24: =+A23+1 -> 15 | G24: =+G23+E24-F24 -> 23
A25: =+A24+1 -> 16 | G25: =+G24+E25-F25 -> 23
A26: =+A25+1 -> 17 | G26: =+G25+E26-F26 -> 23
A27: =+A26+1 -> 18 | G27: =+G26+E27-F27 -> 23
A28: =+A27+1 -> 19 | G28: =+G27+E28-F28 -> 23
A29: =+A28+1 -> 20 | G29: =+G28+E29-F29 -> 23
A30: =+A29+1 -> 21 | G30: =+G29+E30-F30 -> 23
A31: =+A30+1 -> 22 | G31: =+G30+E31-F31 -> 23
A32: =+A31+1 -> 23 | G32: =+G31+E32-F32 -> 23
... A36: =+A35+1 -> 27 | G36: =+G35+E36-F36 -> 23
G37: =+G36+E37-F37 -> 23
G38: =+G37+E38-F38 -> 23
G39: =+G38+E39-F39 -> 23
G40: =+G39+E40-F40 -> 23
G41: =+G40+E41-F41 -> 23
A42: =+A36+1 -> 28 | G42: =+G41+E42-F42 -> 23
A43: =+A42+1 -> 29 | G43: =+G42+E43-F43 -> 23
A44: =+A43+1 -> 30 | G44: =+G43+E44-F44 -> 23
A45: =+A44+1 -> 31 | G45: =+G44+E45-F45 -> 23
A46: =+A45+1 -> 32 | G46: =+G45+E46-F46 -> 23
C47: Tổng cộng | E47: =SUM(E10:E46) -> 6063 | F47: =SUM(F10:F46) -> 6040 | G47: =+E47-F47+G9 -> 23

Sheet Phôi DL 16,2L.180m
A1: Công ty TNHH Giấy Đông Á
A2: Thôn Mộc Ty, xã Trưng Trắc, huyện Văn Lâm, tỉnh Hưng Yên
A4: THẺ KHO NGUYÊN VẬT LIỆU
A8: STT | B8: Ngày tháng | C8: Tên nguyên vật liệu | D8: ĐVT | E8: Số lượng nhập | F8: Số lượng xuất | G8: Tồn | H8: Người nhận | I8: Ghi chú
C9: Tồn đầu kỳ
A10: 1 | B10: 45712 | C10: Phôi Định Lượng 16. 2 Lớp (180m) | D10: Hộp | E10: 5993 | G10: =+G9+E10-F10 -> 5993 | H10: Nguyễn Thanh Tâm | I10: 8
A11: =+A10+1 -> 2 | B11: 45716 | D11: Hộp | F11: 744 | G11: =+G10+E11-F11 -> 5249 | H11: Nguyễn Thanh Tâm
A12: =+A11+1 -> 3 | B12: 45723 | D12: Hộp | F12: 1383 | G12: =+G11+E12-F12 -> 3866 | H12: Nguyễn Thanh Tâm | I12: SX
A13: =+A12+1 -> 4 | B13: 45724 | D13: Hộp | F13: 781 | G13: =+G12+E13-F13 -> 3085 | H13: Nguyễn Thanh Tâm | I13: SX
A14: =+A13+1 -> 5 | B14: 45729 | D14: Hộp | F14: 1582 | G14: =+G13+E14-F14 -> 1503 | H14: Nguyễn Thanh Tâm | I14: SX
A15: =+A14+1 -> 6 | B15: 45730 | D15: Hộp | F15: 1503 | G15: =+G14+E15-F15 -> 0 | H15: Nguyễn Thanh Tâm | I15: SX | J15: Hỏng 5 hộp
A16: =+A15+1 -> 7 | B16: 45758 | E16: 8235.1 | G16: =+G15+E16-F16 -> 8235.1
A17: =+A16+1 -> 8 | B17: 45761 | E17: 5666 | G17: =+G16+E17-F17 -> 13901.1 | I17: Chạy 320m
A18: =+A17+1 -> 9 | B18: 45762 | C18: Nhập lại 557kg hàng xuất ra chạy k đạt đường kính | E18: =557 -> 557 | F18: 820 | G18: =+G17+E18-F18 -> 13638.1
A19: =+A18+1 -> 10 | B19: 45771 | F19: 986 | G19: =+G18+E19-F19 -> 12652.1
A20: =+A19+1 -> 11 | B20: 45772 | F20: 2831 | G20: =+G19+E20-F20 -> 9821.1
A21: =+A20+1 -> 12 | B21: 45772 | E21: 19497 | G21: =+G20+E21-F21 -> 29318.1 | I21: Chạy 320m
A22: =+A21+1 -> 13 | B22: 45774 | F22: 3796 | G22: =+G21+E22-F22 -> 25522.1
A23: =+A22+1 -> 14 | B23: 45776 | F23: 921 | G23: =+G22+E23-F23 -> 24601.1
A24: =+A23+1 -> 15 | B24: 45782 | F24: 3866 | G24: =+G23+E24-F24 -> 20735.1
A25: =+A24+1 -> 16 | B25: 45785 | F25: 3832 | G25: =+G24+E25-F25 -> 16903.1
A26: =+A25+1 -> 17 | B26: 45789 | F26: 989 | G26: =+G25+E26-F26 -> 15914.1
A27: =+A26+1 -> 18 | B27: 45792 | F27: 1034 | G27: =+G26+E27-F27 -> 14880.1
A28: =+A27+1 -> 19 | B28: 45793 | F28: 2063 | G28: =+G27+E28-F28 -> 12817.1
A29: =+A28+1 -> 20 | B29: 45797 | F29: 1021 | G29: =+G28+E29-F29 -> 11796.1
A30: =+A29+1 -> 21 | B30: 45843 | C30: Xuât hàng trả jp | F30: 11270 | G30: =+G29+E30-F30 -> 526.1
A31: =+A30+1 -> 22 | G31: =+G30+E31-F31 -> 526.1
A32: =+A31+1 -> 23 | G32: =+G31+E32-F32 -> 526.1 | N32: =258*16 -> 4128
A33: =+A32+1 -> 24 | G33: =+G32+E33-F33 -> 526.1 | O33: =367985/0.894 -> 411616.33
A34: =+A33+1 -> 25 | G34: =+G33+E34-F34 -> 526.1 | N34: =4128-4116 -> 12
A35: =+A34+1 -> 26 | G35: =+G34+E35-F35 -> 526.1
A36: =+A35+1 -> 27 | G36: =+G35+E36-F36 -> 526.1
A37: =+A36+1 -> 28 | G37: =+G36+E37-F37 -> 526.1
A38: =+A37+1 -> 29 | G38: =+G37+E38-F38 -> 526.1
A39: =+A38+1 -> 30 | G39: =+G38+E39-F39 -> 526.1
A40: =+A39+1 -> 31 | G40: =+G39+E40-F40 -> 526.1
A41: =+A40+1 -> 32 | G41: =+G40+E41-F41 -> 526.1
A42: =+A41+1 -> 33 | G42: =+G41+E42-F42 -> 526.1
A43: =+A42+1 -> 34 | G43: =+G42+E43-F43 -> 526.1
A44: =+A43+1 -> 35 | G44: =+G43+E44-F44 -> 526.1
...

Sheet Phôi DL 18,1L,600
A1: Công ty TNHH Giấy Đông Á
A2: Thôn Mộc Ty, xã Trưng Trắc, huyện Văn Lâm, tỉnh Hưng Yên
A4: THẺ KHO NGUYÊN VẬT LIỆU
A8: STT | B8: Ngày tháng | C8: Tên nguyên vật liệu | D8: ĐVT | E8: Số lượng nhập | F8: Số lượng xuất | G8: Tồn | H8: Người nhận | I8: Ghi chú
C9: Tồn đầu kỳ
A10: 1 | B10: 45712 | C10: Phôi Định Lượng 18. 1 Lớp (600g) | D10: Hộp | E10: 2294 | G10: =+G9+E10-F10 -> 2294 | H10: Nguyễn Thanh Tâm | I10: 3
A11: =+A10+1 -> 2 | B11: 45713 | D11: Hộp | F11: =764+752+778 -> 2294 | G11: =+G10+E11-F11 -> 0 | H11: Nguyễn Thanh Tâm | J11: Chạy 700g/80
A12: =+A11+1 -> 3 | D12: Hộp | G12: =+G11+E12-F12 -> 0 | H12: Nguyễn Thanh Tâm | I12: SX
A13: =+A12+1 -> 4 | D13: Hộp | G13: =+G12+E13-F13 -> 0 | H13: Nguyễn Thanh Tâm | I13: SX
A14: =+A13+1 -> 5 | D14: Hộp | G14: =+G13+E14-F14 -> 0 | H14: Nguyễn Thanh Tâm | I14: SX
A15: =+A14+1 -> 6 | D15: Hộp | G15: =+G14+E15-F15 -> 0 | H15: Nguyễn Thanh Tâm | I15: SX | J15: Hỏng 5 hộp
A16: =+A15+1 -> 7 | G16: =+G15+E16-F16 -> 0
A17: =+A16+1 -> 8 | G17: =+G16+E17-F17 -> 0
A18: =+A17+1 -> 9 | G18: =+G17+E18-F18 -> 0
A19: =+A18+1 -> 10 | G19: =+G18+E19-F19 -> 0 | L19: =5976+798+2139+2294 -> 11207
A20: =+A19+1 -> 11 | G20: =+G19+E20-F20 -> 0
A21: =+A20+1 -> 12 | G21: =+G20+E21-F21 -> 0
A22: =+A21+1 -> 13 | G22: =+G21+E22-F22 -> 0
A23: =+A22+1 -> 14 | G23: =+G22+E23-F23 -> 0 | L23: =+E10+'Phôi DL 18,2L.600g '!E10+'Phôi DL 18,1L.700g ,2 L'!E10+'Phôi DL 18,2L.700g'!E47 -> 16410.2
A24: =+A23+1 -> 15 | G24: =+G23+E24-F24 -> 0
A25: =+A24+1 -> 16 | G25: =+G24+E25-F25 -> 0
A26: =+A25+1 -> 17 | G26: =+G25+E26-F26 -> 0
A27: =+A26+1 -> 18 | G27: =+G26+E27-F27 -> 0
A28: =+A27+1 -> 19 | G28: =+G27+E28-F28 -> 0
A29: =+A28+1 -> 20 | G29: =+G28+E29-F29 -> 0
A30: =+A29+1 -> 21 | G30: =+G29+E30-F30 -> 0
A31: =+A30+1 -> 22 | G31: =+G30+E31-F31 -> 0
A32: =+A31+1 -> 23 | G32: =+G31+E32-F32 -> 0
A33: =+A32+1 -> 24 | G33: =+G32+E33-F33 -> 0
A34: =+A33+1 -> 25 | G34: =+G33+E34-F34 -> 0
A35: =+A34+1 -> 26 | G35: =+G34+E35-F35 -> 0
A36: =+A35+1 -> 27 | G36: =+G35+E36-F36 -> 0
G37: =+G36+E37-F37 -> 0
G38: =+G37+E38-F38 -> 0
G39: =+G38+E39-F39 -> 0
G40: =+G39+E40-F40 -> 0
G41: =+G40+E41-F41 -> 0
A42: =+A36+1 -> 28 | G42: =+G41+E42-F42 -> 0
A43: =+A42+1 -> 29 | G43: =+G42+E43-F43 -> 0
A44: =+A43+1 -> 30 | G44: =+G43+E44-F44 -> 0
...

Sheet Phôi DL 18,5,2L
A1: Công ty TNHH Giấy Đông Á
A2: Thôn Mộc Ty, xã Trưng Trắc, huyện Văn Lâm, tỉnh Hưng Yên
A4: THẺ KHO NGUYÊN VẬT LIỆU
A8: STT | B8: Ngày tháng | C8: Tên nguyên vật liệu | D8: ĐVT | E8: Số lượng nhập | F8: Số lượng xuất | G8: Tồn | H8: Người nhận | I8: Ghi chú
C9: Tồn đầu kỳ
A10: 1 | B10: 45748 | C10: Phôi Định Lượng 18,5- 2 Lớp | D10: Hộp | E10: 1014 | G10: =+G9+E10-F10 -> 1014 | H10: Nguyễn Thanh Tâm
A11: =+A10+1 -> 2 | D11: Hộp | G11: =+G10+E11-F11 -> 1014 | H11: Nguyễn Thanh Tâm
A12: =+A11+1 -> 3 | D12: Hộp | G12: =+G11+E12-F12 -> 1014 | H12: Nguyễn Thanh Tâm
A13: =+A12+1 -> 4 | D13: Hộp | G13: =+G12+E13-F13 -> 1014 | H13: Nguyễn Thanh Tâm
A14: =+A13+1 -> 5 | D14: Hộp | G14: =+G13+E14-F14 -> 1014 | H14: Nguyễn Thanh Tâm
A15: =+A14+1 -> 6 | D15: Hộp | G15: =+G14+E15-F15 -> 1014 | H15: Nguyễn Thanh Tâm
A16: =+A15+1 -> 7 | G16: =+G15+E16-F16 -> 1014
A17: =+A16+1 -> 8 | G17: =+G16+E17-F17 -> 1014
A18: =+A17+1 -> 9 | G18: =+G17+E18-F18 -> 1014
A19: =+A18+1 -> 10 | G19: =+G18+E19-F19 -> 1014
A20: =+A19+1 -> 11 | G20: =+G19+E20-F20 -> 1014
A21: =+A20+1 -> 12 | G21: =+G20+E21-F21 -> 1014
A22: =+A21+1 -> 13 | G22: =+G21+E22-F22 -> 1014
A23: =+A22+1 -> 14 | G23: =+G22+E23-F23 -> 1014
A24: =+A23+1 -> 15 | G24: =+G23+E24-F24 -> 1014
A25: =+A24+1 -> 16 | G25: =+G24+E25-F25 -> 1014
A26: =+A25+1 -> 17 | G26: =+G25+E26-F26 -> 1014
A27: =+A26+1 -> 18 | G27: =+G26+E27-F27 -> 1014
... A36: =+A35+1 -> 27 | G36: =+G35+E36-F36 -> 1014
G37: =+G36+E37-F37 -> 1014
G38: =+G37+E38-F38 -> 1014
G39: =+G38+E39-F39 -> 1014
G40: =+G39+E40-F40 -> 1014
G41: =+G40+E41-F41 -> 1014
A42: =+A36+1 -> 28 | G42: =+G41+E42-F42 -> 1014
A43: =+A42+1 -> 29 | G43: =+G42+E43-F43 -> 1014
A44: =+A43+1 -> 30 | G44: =+G43+E44-F44 -> 1014
A45: =+A44+1 -> 31 | G45: =+G44+E45-F45 -> 1014
A46: =+A45+1 -> 32 | G46: =+G45+E46-F46 -> 1014
C47: Tổng cộng | E47: =SUM(E10:E46) -> 1014 | F47: =SUM(F10:F46) -> 0 | G47: =+E47-F47+G9 -> 1014

Sheet Lõi 76
A1: Công ty TNHH Giấy Đông Á
A2: Thôn Mộc Ty, xã Trưng Trắc, huyện Văn Lâm, tỉnh Hưng Yên
A4: =+'[1]Hộp HV'!A4:I5 -> THẺ KHO NGUYÊN VẬT LIỆU
A7: STT | B7: Ngày tháng | C7: Tên nguyên vật liệu | D7: ĐVT | E7: Số lượng nhập | F7: Số lượng xuất | G7: Tồn | H7: Người nhận | I7: Ghi chú
A9: 1 | B9: 45709 | C9: Lõi 76 k2850 | D9: ống | E9: 315 | G9: =+G8+E9-F9 -> 315
A10: =+A9+1 -> 2 | B10: 45712 | E10: 380 | G10: =+G9+E10-F10 -> 695
A11: =+A10+1 -> 3 | B11: 45714 | F11: 90 | G11: =+G10+E11-F11 -> 605
A12: =+A11+1 -> 4 | B12: 45715 | F12: 73 | G12: =+G11+E12-F12 -> 532
A13: =+A12+1 -> 5 | B13: 45716 | E13: 200 | G13: =+G12+E13-F13 -> 732
A14: =+A13+1 -> 6 | B14: 45720 | F14: 26 | G14: =+G13+E14-F14 -> 706
A15: =+A14+1 -> 7 | B15: 45721 | F15: 120 | G15: =+G14+E15-F15 -> 586
A16: =+A15+1 -> 8 | B16: 45722 | F16: 115 | G16: =+G15+E16-F16 -> 471
A17: =+A16+1 -> 9 | B17: 45724 | F17: 58 | G17: =+G16+E17-F17 -> 413
A18: =+A17+1 -> 10 | B18: 45726 | F18: 90 | G18: =+G17+E18-F18 -> 323
A19: =+A18+1 -> 11 | E19: 300 | F19: 135 | G19: =+G18+E19-F19 -> 488
A20: =+A19+1 -> 12 | B20: 45728 | F20: 41 | G20: =+G19+E20-F20 -> 447
B21: 45729 | F21: 41 | G21: =+G20+E21-F21 -> 406
A22: =+A20+1 -> 13 | B22: 45731 | F22: =129+3 -> 132 | G22: =+G21+E22-F22 -> 274
A23: =+A22+1 -> 14 | B23: 45733 | F23: 191 | G23: =+G22+E23-F23 -> 83
A24: =+A23+1 -> 15 | B24: 45706 | E24: 200 | F24: 184 | G24: =+G23+E24-F24 -> 99 | L24: =249*16 -> 3984
A25: =+A24+1 -> 16 | B25: 45735 | F25: 80 | G25: =+G24+E25-F25 -> 19 | J25: =274-82 -> 192
A26: =+A25+1 -> 17 | B26: 45737 | E26: 1088 | G26: =+G25+E26-F26 -> 1107
A27: =+A26+1 -> 18 | B27: 45749 | F27: 176 | G27: =+G26+E27-F27 -> 931
A28: =+A27+1 -> 19 | B28: 45750 | F28: 35 | G28: =+G27+E28-F28 -> 896
A29: =+A28+1 -> 20 | B29: 45751 | F29: 139 | G29: =+G28+E29-F29 -> 757
A30: =+A29+1 -> 21 | B30: 45752 | F30: 66 | G30: =+G29+E30-F30 -> 691
A31: =+A30+1 -> 22 | B31: 45763 | F31: 161 | G31: =+G30+E31-F31 -> 530
A32: =+A31+1 -> 23 | B32: 45768 | F32: 69 | G32: =+G31+E32-F32 -> 461
A33: =+A32+1 -> 24 | B33: 45769 | F33: 69 | G33: =+G32+E33-F33 -> 392
A34: =+A33+1 -> 25 | B34: 45774 | F34: 138 | G34: =+G33+E34-F34 -> 254 | O34: =6*20+8 -> 128
A35: =+A34+1 -> 26 | B35: 45776 | F35: 41 | G35: =+G34+E35-F35 -> 213 | O35: =+O34*16+5 -> 2053
A36: =+A35+1 -> 27 | B36: 45782 | F36: 143 | G36: =+G35+E36-F36 -> 70 | O36: =+O35*91 -> 186823
A37: =+A36+1 -> 28 | B37: 45785 | F37: 40 | G37: =+G36+E37-F37 -> 30
A38: =+A37+1 -> 29 | B38: 45799 | F38: 30 | G38: =+G37+E38-F38 -> 0 | L38: =4*20+8 -> 88
A39: =+A38+1 -> 30 | G39: =+G38+E39-F39 -> 0 | L39: =+L38*16 -> 1408
A40: =+A39+1 -> 31 | G40: =+G39+E40-F40 -> 0 | L40: =+L39*91 -> 128128
A41: =+A40+1 -> 32 | G41: =+G40+E41-F41 -> 0 | L41: =+L40/2810 -> 45.597153 | N41: =6*20+1 -> 121
A42: =+A41+1 -> 33 | G42: =+G41+E42-F42 -> 0 | N42: =2*20 -> 40
A43: =+A42+1 -> 34 | G43: =+G42+E43-F43 -> 0 | N43: =+N42+N41 -> 161
A44: =+A43+1 -> 35 | G44: =+G43+E44-F44 -> 0 | N44: =+N43*16 -> 2576
...

Sheet Lõi 80
A1: Công ty TNHH Giấy Đông Á
A2: Thôn Mộc Ty, xã Trưng Trắc, huyện Văn Lâm, tỉnh Hưng Yên
A4: =+'[1]Hộp CB nền bạc'!A4:I5 -> THẺ KHO NGUYÊN VẬT LIỆU
A7: STT | B7: Ngày tháng | C7: Tên nguyên vật liệu | D7: ĐVT | E7: Số lượng nhập | F7: Số lượng xuất | G7: Tồn | H7: Người nhận | I7: Ghi chú
C8: Tồn đầu kỳ
A9: 1 | B9: 45709 | C9: Lỗi 80 k2850 | D9: ống | E9: 290 | G9: =+G8+E9-F9 -> 290
A10: =+A9+1 -> 2 | B10: 45710 | F10: 162 | G10: =+G9+E10-F10 -> 128
A11: =+A10+1 -> 3 | B11: 45712 | F11: 60 | G11: =+G10+E11-F11 -> 68
A12: =+A11+1 -> 4 | B12: 45712 | E12: 120 | G12: =+G11+E12-F12 -> 188
A13: =+A12+1 -> 5 | B13: 45713 | F13: 118 | G13: =+G12+E13-F13 -> 70
A14: =+A13+1 -> 6 | B14: 45715 | E14: 500 | F14: 35 | G14: =+G13+E14-F14 -> 535
A15: =+A14+1 -> 7 | B15: 45716 | F15: 48 | G15: =+G14+E15-F15 -> 487
A16: =+A15+1 -> 8 | B16: 45717 | F16: 86 | G16: =+G15+E16-F16 -> 401
A17: =+A16+1 -> 9 | B17: 45719 | F17: 127 | G17: =+G16+E17-F17 -> 274
A18: =+A17+1 -> 10 | B18: 45720 | F18: 97 | G18: =+G17+E18-F18 -> 177
A19: =+A18+1 -> 11 | B19: 45723 | F19: 87 | G19: =+G18+E19-F19 -> 90
A20: =+A19+1 -> 12 | B20: 45724 | F20: 14 | G20: =+G19+E20-F20 -> 76
A21: =+A20+1 -> 13 | B21: 45728 | C21: Nhập lại sx | E21: 9 | F21: 85 | G21: =+G20+E21-F21 -> 0
A22: =+A21+1 -> 14 | B22: 45729 | E22: 240 | F22: =95+ (58-14) -> 139 | G22: =+G21+E22-F22 -> 101
A23: =+A22+1 -> 15 | B23: 45730 | E23: 500 | F23: 172 | G23: =+G22+E23-F23 -> 429
A24: =+A23+1 -> 16 | B24: 45735 | F24: 69 | G24: =+G23+E24-F24 -> 360
A25: =+A24+1 -> 17 | B25: 45736 | E25: 1000 | F25: 110 | G25: =+G24+E25-F25 -> 1250
A26: =+A25+1 -> 18 | B26: 45737 | F26: 140 | G26: =+G25+E26-F26 -> 1110
A27: =+A26+1 -> 19 | B27: 45738 | F27: 73 | G27: =+G26+E27-F27 -> 1037
A28: =+A27+1 -> 20 | B28: 45739 | F28: 39 | G28: =+G27+E28-F28 -> 998
B29: 45740 | F29: 138 | G29: =+G28+E29-F29 -> 860
A30: =+A28+1 -> 21 | B30: 45743 | F30: 71 | G30: =+G29+E30-F30 -> 789
A31: =+A30+1 -> 22 | B31: 45744 | F31: 111 | G31: =+G30+E31-F31 -> 678
A32: =+A31+1 -> 23 | B32: 45746 | F32: 143 | G32: =+G31+E32-F32 -> 535 | L32: =4*20+31 -> 111
A33: =+A32+1 -> 24 | B33: 45747 | F33: 169 | G33: =+G32+E33-F33 -> 366 | L33: =+L32+M32 -> 111
A34: =+A33+1 -> 25 | B34: 45748 | F34: 143 | G34: =+G33+E34-F34 -> 223
A35: =+A34+1 -> 26 | B35: 45750 | F35: 152 | G35: =+G34+E35-F35 -> 71 | P35: =158-15 -> 143
A36: =+A35+1 -> 27 | B36: 45759 | E36: 510 | G36: =+G35+E36-F36 -> 581
B37: 45762 | F37: 19 | G37: =+G36+E37-F37 -> 562
A38: =+A36+1 -> 28 | B38: 45764 | F38: 140 | G38: =+G37+E38-F38 -> 422
A39: =+A38+1 -> 29 | B39: 45765 | F39: 139 | G39: =+G38+E39-F39 -> 283
A40: =+A39+1 -> 30 | B40: 45766 | F40: 154 | G40: =+G39+E40-F40 -> 129
A41: =+A40+1 -> 31 | B41: 45768 | F41: 40 | G41: =+G40+E41-F41 -> 89
A42: =+A41+1 -> 32 | B42: 45769 | E42: 100 | F42: 16 | G42: =+G41+E42-F42 -> 173
A43: =+A42+1 -> 33 | B43: 45770 | E43: 100 | F43: 72 | G43: =+G42+E43-F43 -> 201
...

Sheet Lõi 87
A1: Công ty TNHH Giấy Đông Á
A2: Thôn Mộc Ty, xã Trưng Trắc, huyện Văn Lâm, tỉnh Hưng Yên
A4: =+'[1]Hộp CB nền bạc'!A4:I5 -> THẺ KHO NGUYÊN VẬT LIỆU
A7: STT | B7: Ngày tháng | C7: Tên nguyên vật liệu | D7: ĐVT | E7: Số lượng nhập | F7: Số lượng xuất | G7: Tồn | H7: Người nhận | I7: Ghi chú
C8: Tồn đầu kỳ
A9: 1 | B9: 45790 | C9: Lõi 87 k 2860 | E9: 290 | G9: =+G8+E9-F9 -> 290
A10: =+A9+1 -> 2 | B10: 45793 | E10: 293 | F10: 5 | G10: =+G9+E10-F10 -> 578
A11: =+A10+1 -> 3 | B11: 45796 | F11: 166 | G11: =+G10+E11-F11 -> 412
A12: =+A11+1 -> 4 | B12: 45817 | F12: 35 | G12: =+G11+E12-F12 -> 377
A13: =+A12+1 -> 5 | B13: 45821 | F13: 144 | G13: =+G12+E13-F13 -> 233
A14: =+A13+1 -> 6 | B14: 45834 | E14: 300 | G14: =+G13+E14-F14 -> 533
A15: =+A14+1 -> 7 | B15: 45847 | C15: Xuất trả nhà cung cấp 7 ống bị lỗi | F15: 7 | G15: =+G14+E15-F15 -> 526
A16: =+A15+1 -> 8 | B16: 45847 | F16: 109 | G16: =+G15+E16-F16 -> 417 | I16: Có 1 cây sx làm hỏng
A17: =+A16+1 -> 9 | B17: 45864 | F17: 66 | G17: =+G16+E17-F17 -> 351
A18: =+A17+1 -> 10 | B18: 45866 | F18: 140 | G18: =+G17+E18-F18 -> 211
A19: =+A18+1 -> 11 | B19: 45918 | F19: 70 | G19: =+G18+E19-F19 -> 141
A20: =+A19+1 -> 12 | B20: 45919 | F20: 139 | G20: =+G19+E20-F20 -> 2
A21: =+A20+1 -> 13 | B21: 45920 | F21: 16 | G21: =+G20+E21-F21 -> -14
A22: =+A21+1 -> 14 | G22: =+G21+E22-F22 -> -14 | L22: =3224*91 -> 293384
A23: =+A22+1 -> 15 | G23: =+G22+E23-F23 -> -14 | L23: =+L22/2821 -> 104
A24: =+A23+1 -> 16 | G24: =+G23+E24-F24 -> -14
A25: =+A24+1 -> 17 | G25: =+G24+E25-F25 -> -14
A26: =+A25+1 -> 18 | G26: =+G25+E26-F26 -> -14
A27: =+A26+1 -> 19 | G27: =+G26+E27-F27 -> -14
A28: =+A27+1 -> 20 | G28: =+G27+E28-F28 -> -14 | O28: =1296*91 -> 117936
G29: =+G28+E29-F29 -> -14 | O29: =+O28/2821 -> 41.806452
A30: =+A28+1 -> 21 | G30: =+G29+E30-F30 -> -14
A31: =+A30+1 -> 22 | G31: =+G30+E31-F31 -> -14
A32: =+A31+1 -> 23 | G32: =+G31+E32-F32 -> -14 | L32: =4*20+31 -> 111
A33: =+A32+1 -> 24 | G33: =+G32+E33-F33 -> -14 | L33: =+L32+M32 -> 111
A34: =+A33+1 -> 25 | G34: =+G33+E34-F34 -> -14
A35: =+A34+1 -> 26 | G35: =+G34+E35-F35 -> -14 | P35: =158-15 -> 143
A36: =+A35+1 -> 27 | G36: =+G35+E36-F36 -> -14
A37: =+A36+1 -> 28 | G37: =+G36+E37-F37 -> -14
A38: =+A37+1 -> 29 | G38: =+G37+E38-F38 -> -14
A39: =+A38+1 -> 30 | G39: =+G38+E39-F39 -> -14
A40: =+A39+1 -> 31 | G40: =+G39+E40-F40 -> -14
A41: =+A40+1 -> 32 | G41: =+G40+E41-F41 -> -14
A42: =+A41+1 -> 33 | G42: =+G41+E42-F42 -> -14
A43: =+A42+1 -> 34 | G43: =+G42+E43-F43 -> -14
...

Sheet Bao trắng 600g,bb,80 
A1: Cty TNHH Đông Á
A2: Thôn Mộc Ty, xã Trưng Trắc, huyện Văn Lâm, tỉnh Hưng Yên
A4: =+'[1]Hộp oto'!A4:I5 -> THẺ KHO NGUYÊN VẬT LIỆU
A7: STT | B7: Ngày tháng | C7: Tên nguyên vật liệu | D7: ĐVT | E7: Số lượng nhập | F7: Số lượng xuất | G7: Tồn | H7: Người nhận | I7: Ghi chú
C8: Tồn đầu kỳ | D8: kg
B9: 45714 | C9: Bao trắng otakami GVS 600G -BB /80(1020*470*19) | D9: Kg | E9: 53.6 | G9: =+G8+E9-F9 -> 53.6 | J9: Nhập lại kho cho khớp vưới kk ngày 28/02/2019
B10: 45715 | C10: Bao trắng otakami GVS 600G -BB /80(1020*470*19) | F10: 4.1 | G10: =+G9+E10-F10 -> 49.5
B11: 45730 | F11: 11.5 | G11: =+G10+E11-F11 -> 38
B12: 45769 | F12: 1.8 | G12: =+G11+E12-F12 -> 36.2
B13: 45770 | F13: 4.1 | G13: =+G12+E13-F13 -> 32.1
B14: 45771 | F14: 1 | G14: =+G13+E14-F14 -> 31.1 | H14: Chạy canon
B15: 45772 | F15: =1.2+1 -> 2.2 | G15: =+G14+E15-F15 -> 28.9
B16: 45773 | E16: 83 | G16: =+G15+E16-F16 -> 111.9
B17: 45791 | F17: 2.7 | G17: =+G16+E17-F17 -> 109.2
B18: 45791 | F18: 8.5 | G18: =+G17+E18-F18 -> 100.7
B19: 45792 | F19: 2.8 | G19: =+G18+E19-F19 -> 97.9
B20: 45798 | F20: 5 | G20: =+G19+E20-F20 -> 92.9
B21: 45806 | F21: 6 | G21: =+G20+E21-F21 -> 86.9
B22: 45929 | F22: =13.8-5.6 -> 8.2 | G22: =+G21+E22-F22 -> 78.7 | O22: =2*16+10 -> 42
B23: 45930 | F23: 7.2 | G23: =+G22+E23-F23 -> 71.5
B24: 45934 | F24: 7.6 | G24: =+G23+E24-F24 -> 63.9
G25: =+G24+E25-F25 -> 63.9
G26: =+G25+E26-F26 -> 63.9
G27: =+G26+E27-F27 -> 63.9
G28: =+G27+E28-F28 -> 63.9
G29: =+G28+E29-F29 -> 63.9
G30: =+G29+E30-F30 -> 63.9
G31: =+G30+E31-F31 -> 63.9
G32: =+G31+E32-F32 -> 63.9
G33: =+G32+E33-F33 -> 63.9
G34: =+G33+E34-F34 -> 63.9
G35: =+G34+E35-F35 -> 63.9
G36: =+G35+E36-F36 -> 63.9
... G146: =+G145+E146-F146 -> 63.9
D147: kg | G147: =+G146+E147-F147 -> 63.9
D148: kg | G148: =+G147+E148-F148 -> 63.9
D149: kg | G149: =+G148+E149-F149 -> 63.9
D150: kg | G150: =+G149+E150-F150 -> 63.9
D151: kg | G151: =+G150+E151-F151 -> 63.9
D152: kg | G152: =+G151+E152-F152 -> 63.9
...

Sheet Bao trắng 320 M ,C 
A1: Cty TNHH Đông Á
A2: Thôn Mộc Ty, xã Trưng Trắc, huyện Văn Lâm, tỉnh Hưng Yên
A4: =+'[1]Hộp oto'!A4:I5 -> THẺ KHO NGUYÊN VẬT LIỆU
A7: STT | B7: Ngày tháng | C7: Tên nguyên vật liệu | D7: ĐVT | E7: Số lượng nhập | F7: Số lượng xuất | G7: Tồn | H7: Người nhận | I7: Ghi chú
C8: Tồn đầu kỳ | D8: kg
B9: 45714 | C9: Bao trắng otakami GVS CN 320 M -C: TD (890*490*195) | D9: kg | E9: 41.6 | G9: =+G8+E9-F9 -> 41.6 | H9: Nguyễn Thị Liên | I9: SX
B10: 45724 | C10: Bao trắng otakami GVS CN 320 M -C: TD (890*490*195) | D10: kg | F10: 7.5 | G10: =+G9+E10-F10 -> 34.1 | H10: Nguyễn Thị Liên | I10: SX
B11: 45726 | C11: Bao trắng otakami GVS CN 320 M -C: TD (890*490*195) | D11: kg | F11: 12 | G11: =+G10+E11-F11 -> 22.1 | H11: Nguyễn Thị Liên | I11: SX
B12: 45727 | F12: 11.3 | G12: =+G11+E12-F12 -> 10.8 | H12: Nguyễn Thị Liên | I12: SX
B13: 45728 | F13: 11.7 | G13: =+G12+E13-F13 -> -0.9 | H13: Nguyễn Thị Liên | I13: SX
G14: =+G13+E14-F14 -> -0.9 | H14: Nguyễn Thị Liên | I14: SX
G15: =+G14+E15-F15 -> -0.9 | H15: Nguyễn Thị Liên | I15: SX
G16: =+G15+E16-F16 -> -0.9 | H16: Nguyễn Thị Liên | I16: SX
G17: =+G16+E17-F17 -> -0.9 | H17: Nguyễn Thị Liên | I17: SX
G18: =+G17+E18-F18 -> -0.9 | H18: Nguyễn Thị Liên | I18: Bao Bì minh Sơn
G19: =+G18+E19-F19 -> -0.9 | H19: Nguyễn Thị Liên | I19: SX
G20: =+G19+E20-F20 -> -0.9 | H20: Nguyễn Thị Liên | I20: SX
G21: =+G20+E21-F21 -> -0.9 | H21: Nguyễn Thị Liên | I21: SX
G22: =+G21+E22-F22 -> -0.9 | H22: Nguyễn Thị Liên | I22: SX
G23: =+G22+E23-F23 -> -0.9 | H23: Nguyễn Thị Liên | I23: SX
G24: =+G23+E24-F24 -> -0.9 | H24: Nguyễn Thị Liên | I24: Đóng lại hàng linh an
G25: =+G24+E25-F25 -> -0.9 | H25: Nguyễn Thị Liên | I25: SX
... G74: =+G73+E74-F74 -> -0.9 | H74: Nguyễn Thị ,Tâm | I74: SX
G75: =+G74+E75-F75 -> -0.9
G76: =+G75+E76-F76 -> -0.9
G77: =+G76+E77-F77 -> -0.9
G78: =+G77+E78-F78 -> -0.9
G79: =+G78+E79-F79 -> -0.9
G80: =+G79+E80-F80 -> -0.9
G81: =+G80+E81-F81 -> -0.9
G82: =+G81+E82-F82 -> -0.9
G83: =+G82+E83-F83 -> -0.9
G84: =+G83+E84-F84 -> -0.9
G85: =+G84+E85-F85 -> -0.9
G86: =+G85+E86-F86 -> -0.9
... G150: =+G149+E150-F150 -> -0.9
D151: kg | G151: =+G150+E151-F151 -> -0.9
D152: kg | G152: =+G151+E152-F152 -> -0.9
C153: Tổng cộng | E153: =SUM(E9:E152) -> 41.6 | F153: =SUM(F9:F152) -> 42.5 | G153: =E153-F153+G8 -> -0.9

Sheet Bao 320 M ,76 MTL
A1: Cty TNHH Đông Á
A2: Thôn Mộc Ty, xã Trưng Trắc, huyện Văn Lâm, tỉnh Hưng Yên
A4: =+'[1]Hộp oto'!A4:I5 -> THẺ KHO NGUYÊN VẬT LIỆU
