Workbook

Sheet Bảng tổng
A1: Công ty TNHH Giấy Đông Á
A2: Thôn Mộc Ty, xã Trưng Trắc, huyện Văn Lâm, tỉnh Hưng Yên
A3: XUẤT NHẬP TỒN NĂM 2025
A7: STT | B7: Tên nguyên vật liệu | C7: Đơn vị tính | D7: Tồn đầu kỳ | E7: Số lượng nhập | F7: Số lượng xuất | G7: Tồn cuối | H7: Ghi chú
A9: 1 | B9: Vỏ hộp giấy ăn Shelton 120 vuông trắng 117*117*125mm | C9: Cái | D9: ='Hộp 120 Trắng'!G8 -> 0 | E9: ='Hộp 120 Trắng'!E56 -> 20980 | F9: ='Hộp 120 Trắng'!F56 -> 15173 | G9: =D9+E9-F9 -> 5807 | I9: =+G9/60 -> 96.783333
A10: =+A9+1 -> 2 | B10: Vỏ hộp giấy ăn Shelton 120 vuông lá xanh 114*125*130mm | C10: Cái | D10: ='Hộp 120 Xanh'!G9 -> 691 | E10: ='Hộp 120 Xanh'!E83 -> 21130 | F10: ='Hộp 120 Xanh'!F83 -> 17737 | G10: =D10+E10-F10 -> 4084 | I10: =+G10/60 -> 68.066667
A11: =+A10+1 -> 3 | B11: Vỏ hộp Shelton Hồng Vàng 180 tờ (90*120*220mm) | C11: Cái | D11: ='Hộp HV'!G8 -> 5672 | E11: ='Hộp HV'!E61 -> 0 | F11: ='Hộp HV'!F61 -> 3709 | G11: =D11+E11-F11 -> 1963
A12: =+A11+1 -> 4 | B12: Vỏ hộp Shelton Hồng Đỏ 180 tờ ( 90*120*220mm) | C12: Cái | D12: ='Hộp hồng đỏ'!G8 -> 8676 | E12: ='Hộp hồng đỏ'!E43 -> 0 | F12: ='Hộp hồng đỏ'!F43 -> 0 | G12: =D12+E12-F12 -> 8676
A13: =+A12+1 -> 5 | B13: Vỏ hộp Shelton Cánh bướm trắng 180 tờ (90*120*220mm) | C13: Cái | D13: ='Hộp bướm bạc'!G9 -> 762 | E13: ='Hộp bướm bạc'!E47 -> 0 | F13: ='Hộp bướm bạc'!F47 -> 420 | G13: =D13+E13-F13 -> 342 | J13: =110+266 -> 376
A14: =+A13+1 -> 6 | B14: Vỏ hộp Shelton hoa nhí Xanh 180 tờ (90*120*220mm) | C14: Cái | D14: ='Hộp NX'!G8 -> 1364 | E14: ='Hộp NX'!E58 -> 10130 | F14: ='Hộp NX'!F58 -> 4764 | G14: =D14+E14-F14 -> 6730
A15: =+A14+1 -> 7 | B15: vỏ hộp Shelton oto đen 180 tờ | C15: Cái | D15: ='Hộp oto'!G8 -> 649 | E15: ='Hộp oto'!E31 -> 0 | F15: ='Hộp oto'!F31 -> 0 | G15: =D15+E15-F15 -> 649
A16: =+A15+1 -> 8 | B16: Vỏ hộp Shelton cánh bướm đen 180 tờ | C16: Cái | D16: ='Hộp bướm đen'!G9 -> 6237 | E16: ='Hộp bướm đen'!E42 -> 0 | F16: ='Hộp bướm đen'!F42 -> 0 | G16: =D16+E16-F16 -> 6237
A17: =+A16+1 -> 9 | B17: Túi Nilong trắng đựng hộp 180 | C17: Kg | D17: ='Bao Trắng 180'!G8 -> 375 | E17: ='Bao Trắng 180'!E155 -> 0 | F17: ='Bao Trắng 180'!F155 -> 181.6 | G17: =D17+E17-F17 -> 193.4
A18: =+A17+1 -> 10 | B18: Túi nilong trắng đựng hộp 120 vuông | C18: Kg | D18: ='Bao Trắng 120'!G9 -> 189.1 | E18: ='Bao Trắng 120'!E91 -> 0 | F18: ='Bao Trắng 120'!F91 -> 123.2 | G18: =D18+E18-F18 -> 65.9
A19: =+A18+1 -> 11 | B19: Túi nilong NK 33*33 lá xanh | C19: Kg | D19: ='Nilon NK Lá cây'!G8 -> 44.9 | E19: ='Nilon NK Lá cây'!E41 -> 0 | F19: ='Nilon NK Lá cây'!F41 -> 4.6 | G19: =D19+E19-F19 -> 40.3
A20: =+A19+1 -> 12 | B20: Túi nilong Napkin hoa văn tròn 33*33 | C20: Kg | D20: ='Túi nilong tròn 33'!G8 -> 360.9 | E20: ='Túi nilong tròn 33'!E34 -> 0 | F20: ='Túi nilong tròn 33'!F34 -> 9.3 | G20: =D20+E20-F20 -> 351.6 | K20: =4*30+26+8 -> 154
A21: =+A20+1 -> 13 | B21: Túi nilong Napkin hoa văn tròn 23*23 | C21: Kg | D21: ='Túi nilong tròn 23'!G8 -> 366 | E21: ='Túi nilong tròn 23'!E35 -> 0 | F21: ='Túi nilong tròn 23'!F35 -> 0 | G21: =D21+E21-F21 -> 366
A22: =+A21+1 -> 14 | B22: Túi nilong Napkin 33*33 Cánh Bướm | C22: Cái | D22: ='Nilon NK cánh bướm'!G8 -> 10 | E22: ='Nilon NK cánh bướm'!E37 -> 0 | F22: ='Nilon NK cánh bướm'!F37 -> 0 | G22: =D22+E22-F22 -> 10
A23: =+A22+1 -> 15 | B23: Nilong soft back lá xanh 250 tờ | C23: Cái | D23: ='Nilon SP Lá cây'!G8 -> 132 | E23: ='Nilon SP Lá cây'!E91 -> 0 | F23: ='Nilon SP Lá cây'!F91 -> 0 | G23: =D23+E23-F23 -> 132
A24: =+A23+1 -> 16 | B24: Nilong soft back hoa văn tròn 250 tờ | C24: Cái | D24: ='Nilon SP Tròn'!G8 -> 64.2 | E24: ='Nilon SP Tròn'!E113 -> 0 | F24: ='Nilon SP Tròn'!F113 -> 6.8 | G24: =D24+E24-F24 -> 57.4
B25: Túi Giấy Vệ Sinh 207*710*94 10 cuộn | C25: Kg | D25: ='Túi GVS 2 lớp 10 cuộn Có lõi'!G8 -> 342.3 | E25: ='Túi GVS 2 lớp 10 cuộn Có lõi'!E35 -> 0 | F25: ='Túi GVS 2 lớp 10 cuộn Có lõi'!F35 -> 0 | G25: =D25+E25-F25 -> 342.3
B26: Túi giấy vệ sinh 3 lớp có lõi xanh ngọc | C26: Kg | D26: ='Túi GVS 10 cuộn 3 lớp Có lõi '!G8 -> 73.5 | E26: ='Túi GVS 10 cuộn 3 lớp Có lõi '!E58 -> 384 | F26: ='Túi GVS 10 cuộn 3 lớp Có lõi '!F58 -> 372.1 | G26: =D26+E26-F26 -> 85.4
B27: Túi giấy vệ sinh 3 lớp không lõi xanh dương | C27: Kg | D27: ='Túi GVS 10 cuộn 3 lớp không lõi'!G8 -> 221 | E27: ='Túi GVS 10 cuộn 3 lớp không lõi'!E34 -> 0 | F27: ='Túi GVS 10 cuộn 3 lớp không lõi'!F34 -> 101.3 | G27: =D27+E27-F27 -> 119.7
B28: Túi giấy vệ sinh 3 lớp 12 cuộn có lõi xanh ngọc M956 | C28: Kg | D28: ='Túi GVS 12 cuộn 3 lớp Có lõi. '!G8 -> 273.8 | E28: ='Túi GVS 12 cuộn 3 lớp Có lõi. '!E56 -> 0 | F28: ='Túi GVS 12 cuộn 3 lớp Có lõi. '!F56 -> 0.7 | G28: =D28+E28-F28 -> 273.1
B29: Túi giấy vệ sinh 3 lớp 12 cuộn không lõi xanh dương M934 | C29: Kg | D29: ='Túi GVS 12 cuộn 3 lớp không lõi'!G8 -> 274.9 | E29: ='Túi GVS 12 cuộn 3 lớp không lõi'!E61 -> 448 | F29: ='Túi GVS 12 cuộn 3 lớp không lõi'!F61 -> 381 | G29: =D29+E29-F29 -> 341.9
B30: Màng bọc cuộn CN POE khổ 45cm | C30: Kg | D30: ='Màng bọc cuộn CN'!G8 -> 147.1 | E30: ='Màng bọc cuộn CN'!E113 -> 781.74 | F30: ='Màng bọc cuộn CN'!F113 -> 940.45 | G30: =D30+E30-F30 -> -11.61
B31: Mạng CPP K315*40 Đa Năng 100 tờ | C31: Kg | D31: ='Màng ĐN 100 tờ'!G8 -> 359.7 | E31: ='Màng ĐN 100 tờ'!E113 -> 25.5 | F31: ='Màng ĐN 100 tờ'!F113 -> 211.9 | G31: =D31+E31-F31 -> 173.3
B32: Màng cuộn SP 250 tờ M871 CPP Mờ(175*175) | C32: Kg | D32: ='MÀNG SP 250 TỜ 2 LỚP M871'!G8 -> 171.8 | E32: ='MÀNG SP 250 TỜ 2 LỚP M871'!E114 -> 0 | F32: ='MÀNG SP 250 TỜ 2 LỚP M871'!F114 -> 0 | G32: =D32+E32-F32 -> 171.8
B33: Màng cuộn SP 100 tờ 4 lớp M857 CPP Mờ(115*175) | C33: Kg | D33: ='MÀNG SP 100 TỜ 4 LỚP M857'!G8 -> 256.6 | E33: ='MÀNG SP 100 TỜ 4 LỚP M857'!E113 -> 0 | F33: ='MÀNG SP 100 TỜ 4 LỚP M857'!F113 -> 37.1 | G33: =D33+E33-F33 -> 219.5
B34: Màng cuộn SP 100 tờ 3 lớp M864 CPP Mờ( 115*175) | C34: Kg | D34: ='MÀNG SP 100 TỜ 3 LỚP M864'!G8 -> 208.4 | E34: ='MÀNG SP 100 TỜ 3 LỚP M864'!E113 -> 4.7 | F34: ='MÀNG SP 100 TỜ 3 LỚP M864'!F113 -> 141.5 | G34: =D34+E34-F34 -> 71.6
B35: Màng cuộn SP 180 tờ 3 lớp M864 CPP Mờ( 195*175) | C35: Kg | D35: ='MÀNG SP 180 TỜ 3 LỚP '!G8 -> 227 | E35: ='MÀNG SP 180 TỜ 3 LỚP '!E113 -> 0 | F35: ='MÀNG SP 180 TỜ 3 LỚP '!F113 -> 47.6 | G35: =D35+E35-F35 -> 179.4
B36: Túi vệ sinh rút đáy M987 | C36: Kg | D36: ='TÚI VỆ SINH RÚT ĐÁY'!G8 -> 223.5 | E36: ='TÚI VỆ SINH RÚT ĐÁY'!E113 -> 0 | F36: ='TÚI VỆ SINH RÚT ĐÁY'!F113 -> 0 | G36: =D36+E36-F36 -> 223.5
B37: Túi đa năng rút M796 | C37: Kg | D37: ='TÚI RÚT ĐA NĂNG'!G8 -> 223.3 | E37: ='TÚI RÚT ĐA NĂNG'!E113 -> 0 | F37: ='TÚI RÚT ĐA NĂNG'!F113 -> 33.6 | G37: =D37+E37-F37 -> 189.7
B38: Túi GVS Shera 12 cuộn (70g) | C38: Kg | D38: ='Túi GVS có lõi Shera 12 cuộn'!G8 -> 250.3 | E38: ='Túi GVS có lõi Shera 12 cuộn'!E62 -> 7.6 | F38: ='Túi GVS có lõi Shera 12 cuộn'!F62 -> 145.3 | G38: =D38+E38-F38 -> 112.6
B39: Bao vô cây cuộn CN 47*95 | C39: Kg | D39: ='Bao vô cây CN '!G8 -> 552 | E39: ='Bao vô cây CN '!E153 -> 176.3 | F39: ='Bao vô cây CN '!F153 -> 357.5 | G39: =D39+E39-F39 -> 370.8
B40: Bao 5 cuộn 29*70 | C40: Kg | D40: ='Bao 5 cuộn CN'!G8 -> 523 | E40: ='Bao 5 cuộn CN'!E154 -> 334.5 | F40: ='Bao 5 cuộn CN'!F154 -> 347.4 | G40: =D40+E40-F40 -> 510.1
B41: Bao vô cây cuộn CN 55,8*72 | C41: Kg | D41: ='Bao vô cây CN 10 cuộn'!G8 -> 119 | E41: ='Bao vô cây CN 10 cuộn'!E153 -> 474 | F41: ='Bao vô cây CN 10 cuộn'!F153 -> 394.7 | G41: =D41+E41-F41 -> 198.3
B42: Bao vô cây 12 cuộn 665*105 | C42: Kg | D42: ='Bao vô cây 12 cuộn'!G8 -> 337 | E42: ='Bao vô cây 12 cuộn'!E153 -> 0 | F42: ='Bao vô cây 12 cuộn'!F153 -> 216.9 | G42: =D42+E42-F42 -> 120.1
B43: Bao vô cây 10 cuộn 555*100 | C43: Kg | D43: ='Bao vô cây 10 cuộn'!G8 -> 629 | E43: ='Bao vô cây 10 cuộn'!E155 -> 0 | F43: ='Bao vô cây 10 cuộn'!F155 -> 385.1 | G43: =D43+E43-F43 -> 243.9
B44: Bao trăng sp cân 3 lớp 200*175 | C44: Kg | D44: ='Bao trăng sp cân.3 lơp'!G9 -> 39.9 | E44: ='Bao trăng sp cân.3 lơp'!E91 -> 99 | F44: ='Bao trăng sp cân.3 lơp'!F91 -> 60 | G44: =D44+E44-F44 -> 78.9
...

Sheet Hộp 120 Trắng
A1: Công ty TNHH Giấy Đông Á
A2: Thôn Mộc Ty, xã Trưng Trắc, huyện Văn Lâm, tỉnh Hưng Yên
A3: THẺ KHO NGUYÊN VẬT LIỆU
A7: STT | B7: Ngày tháng | C7: Tên nguyên vật liệu | D7: ĐVT | E7: Số lượng nhập | F7: Số lượng xuất | G7: Tồn | H7: Người nhận | I7: Ghi chú
B8: 45658 | C8: Tồn đầu kỳ
A9: 1 | B9: 45660 | C9: Vỏ hộp giấy ăn Shelton 120 vuông trắng 117*117*125mm | D9: cái | E9: =26*400+80 -> 10480 | G9: =+G8+E9-F9 -> 10480 | H9: Nguyễn Thanh Tâm | I9: SX
A10: =+A9+1 -> 2 | B10: 45664 | C10: Vỏ hộp giấy ăn Shelton 120 vuông trắng 117*117*125mm | D10: cái | F10: 420 | G10: =+G9+E10-F10 -> 10060 | H10: Nguyễn Thanh Tâm | I10: SX
A11: =+A10+1 -> 3 | B11: 45665 | C11: Vỏ hộp giấy ăn Shelton 120 vuông trắng 117*117*125mm | D11: cái | F11: 1380 | G11: =+G10+E11-F11 -> 8680 | H11: Nguyễn Thanh Tâm | I11: SX
A12: =+A11+1 -> 4 | B12: 45666 | C12: Vỏ hộp giấy ăn Shelton 120 vuông trắng 117*117*125mm | D12: cái | F12: 1260 | G12: =+G11+E12-F12 -> 7420 | H12: Nguyễn Thanh Tâm | I12: SX
A13: =+A12+1 -> 5 | B13: 45667 | C13: Vỏ hộp giấy ăn Shelton 120 vuông trắng 117*117*125mm | D13: cái | F13: 1261 | G13: =+G12+E13-F13 -> 6159 | H13: Nguyễn Thanh Tâm | I13: SX
A14: =+A13+1 -> 6 | B14: 45668 | C14: Vỏ hộp giấy ăn Shelton 120 vuông trắng 117*117*125mm | D14: cái | F14: 1572 | G14: =+G13+E14-F14 -> 4587 | H14: Nguyễn Thanh Tâm | I14: SX
A15: =+A14+1 -> 7 | B15: 45759 | C15: Vỏ hộp giấy ăn Shelton 120 vuông trắng 117*117*125mm | D15: cái | F15: 420 | G15: =+G14+E15-F15 -> 4167 | H15: Nguyễn Thanh Tâm | I15: SX
A16: =+A15+1 -> 8 | B16: 45762 | C16: Vỏ hộp giấy ăn Shelton 120 vuông trắng 117*117*125mm | D16: cái | F16: 720 | G16: =+G15+E16-F16 -> 3447 | H16: Nguyễn Thanh Tâm | I16: SX
A17: =+A16+1 -> 9 | B17: 45763 | C17: Vỏ hộp giấy ăn Shelton 120 vuông trắng 115*115*115mm | D17: cái | F17: 360 | G17: =+G16+E17-F17 -> 3087
A18: =+A17+1 -> 10 | B18: 45764 | C18: Vỏ hộp giấy ăn Shelton 120 vuông trắng 115*115*115mm | D18: cái | F18: =18*60 -> 1080 | G18: =+G17+E18-F18 -> 2007 | H18: Nguyễn Thanh Tâm | I18: SX
A19: =+A18+1 -> 11 | B19: 45772 | C19: Vỏ hộp giấy ăn Shelton 120 vuông trắng 115*115*115mm | D19: cái | F19: 540 | G19: =+G18+E19-F19 -> 1467
A20: =+A19+1 -> 12 | B20: 45775 | C20: Vỏ hộp giấy ăn Shelton 120 vuông trắng 115*115*115mm | D20: cái | F20: 780 | G20: =+G19+E20-F20 -> 687 | H20: Nguyễn Thanh Tâm | I20: SX
A21: =+A20+1 -> 13 | B21: 45776 | C21: Vỏ hộp giấy ăn Shelton 120 vuông trắng 115*115*115mm | D21: cái | F21: 660 | G21: =+G20+E21-F21 -> 27 | H21: Nguyễn Thanh Tâm | I21: SX
A22: =+A21+1 -> 14 | B22: 45797 | C22: Vỏ hộp giấy ăn Shelton 120 vuông trắng 115*115*115mm | D22: cái | E22: 10500 | G22: =+G21+E22-F22 -> 10527 | H22: Nguyễn Thanh Tâm | I22: SX
A23: =+A22+1 -> 15 | B23: 45805 | C23: Vỏ hộp giấy ăn Shelton 120 vuông trắng 115*115*115mm | D23: cái | F23: 1720 | G23: =+G22+E23-F23 -> 8807 | H23: Nguyễn Thanh Tâm | I23: SX
A24: =+A23+1 -> 16 | B24: 45806 | C24: Vỏ hộp giấy ăn Shelton 120 vuông trắng 115*115*115mm | D24: cái | F24: 1140 | G24: =+G23+E24-F24 -> 7667 | H24: Nguyễn Thanh Tâm | I24: SX
A25: =+A24+1 -> 17 | B25: 45807 | C25: Vỏ hộp giấy ăn Shelton 120 vuông trắng 115*115*115mm | D25: cái | F25: 1560 | G25: =+G24+E25-F25 -> 6107 | H25: Nguyễn Thanh Tâm | I25: SX
A26: =+A25+1 -> 18 | B26: 45809 | C26: Vỏ hộp giấy ăn Shelton 120 vuông trắng 115*115*115mm | D26: cái | F26: 300 | G26: =+G25+E26-F26 -> 5807 | H26: Nguyễn Thanh Tâm | I26: SX
A27: =+A26+1 -> 19 | C27: Vỏ hộp giấy ăn Shelton 120 vuông trắng 115*115*115mm | D27: cái | G27: =+G26+E27-F27 -> 5807 | H27: Nguyễn Thanh Tâm | I27: SX
A28: =+A27+1 -> 20 | C28: Vỏ hộp giấy ăn Shelton 120 vuông trắng 115*115*115mm | D28: cái | G28: =+G27+E28-F28 -> 5807 | H28: Nguyễn Thanh Tâm | I28: SX
A29: =+A28+1 -> 21 | C29: Vỏ hộp giấy ăn Shelton 120 vuông trắng 115*115*115mm | D29: cái | G29: =+G28+E29-F29 -> 5807 | H29: Nguyễn Thanh Tâm | I29: SX
A30: =+A29+1 -> 22 | C30: Vỏ hộp giấy ăn Shelton 120 vuông trắng 115*115*115mm | D30: cái | G30: =+G29+E30-F30 -> 5807 | H30: Nguyễn Thanh Tâm | I30: SX
A31: =+A30+1 -> 23 | C31: Vỏ hộp giấy ăn Shelton 120 vuông trắng 115*115*115mm | D31: cái | G31: =+G30+E31-F31 -> 5807 | H31: Nguyễn Thanh Tâm | I31: SX | O31: =1478-660 -> 818
A32: =+A31+1 -> 24 | C32: Vỏ hộp giấy ăn Shelton 120 vuông trắng 115*115*115mm | D32: cái | G32: =+G31+E32-F32 -> 5807 | H32: Nguyễn Thanh Tâm | I32: SX
A33: =+A32+1 -> 25 | C33: Vỏ hộp giấy ăn Shelton 120 vuông trắng 115*115*115mm | D33: cái | G33: =+G32+E33-F33 -> 5807 | H33: Nguyễn Thanh Tâm | I33: SX
A34: =+A33+1 -> 26 | C34: Vỏ hộp giấy ăn Shelton 120 vuông trắng 115*115*115mm | D34: cái | G34: =+G33+E34-F34 -> 5807
A35: =+A34+1 -> 27 | C35: Vỏ hộp giấy ăn Shelton 120 vuông trắng 115*115*115mm | D35: cái | G35: =+G34+E35-F35 -> 5807
A36: =+A35+1 -> 28 | C36: Vỏ hộp giấy ăn Shelton 120 vuông trắng 115*115*115mm | D36: cái | G36: =+G35+E36-F36 -> 5807
A37: =+A36+1 -> 29 | C37: Vỏ hộp giấy ăn Shelton 120 vuông trắng 115*115*115mm | D37: cái | G37: =+G36+E37-F37 -> 5807
A38: =+A37+1 -> 30 | D38: cái | G38: =+G37+E38-F38 -> 5807
A39: =+A38+1 -> 31 | D39: cái | G39: =+G38+E39-F39 -> 5807
A40: =+A39+1 -> 32 | D40: cái | G40: =+G39+E40-F40 -> 5807
A41: =+A40+1 -> 33 | D41: cái | G41: =+G40+E41-F41 -> 5807
A42: =+A41+1 -> 34 | D42: cái | G42: =+G41+E42-F42 -> 5807
A43: =+A42+1 -> 35 | D43: cái | G43: =+G42+E43-F43 -> 5807
...

Sheet Hộp 80 Trắng 10,10
A1: Công ty TNHH Giấy Đông Á
A2: Thôn Mộc Ty, xã Trưng Trắc, huyện Văn Lâm, tỉnh Hưng Yên
A3: THẺ KHO NGUYÊN VẬT LIỆU
A7: STT | B7: Ngày tháng | C7: Tên nguyên vật liệu | D7: ĐVT | E7: Số lượng nhập | F7: Số lượng xuất | G7: Tồn | H7: Người nhận | I7: Ghi chú
B8: 45658 | C8: Tồn đầu kỳ | G8: 4
A9: 1 | C9: Vỏ hộp giấy ăn Shelton 120 vuông trắng 117*117*125mm | D9: cái | G9: =+G8+E9-F9 -> 4 | H9: Nguyễn Thanh Tâm | I9: SX
A10: =+A9+1 -> 2 | C10: Vỏ hộp giấy ăn Shelton 120 vuông trắng 117*117*125mm | D10: cái | G10: =+G9+E10-F10 -> 4 | H10: Nguyễn Thanh Tâm | I10: SX
A11: =+A10+1 -> 3 | C11: Vỏ hộp giấy ăn Shelton 120 vuông trắng 117*117*125mm | D11: cái | G11: =+G10+E11-F11 -> 4 | H11: Nguyễn Thanh Tâm | I11: SX
A12: =+A11+1 -> 4 | C12: Vỏ hộp giấy ăn Shelton 120 vuông trắng 117*117*125mm | D12: cái | G12: =+G11+E12-F12 -> 4 | H12: Nguyễn Thanh Tâm | I12: SX
A13: =+A12+1 -> 5 | C13: Vỏ hộp giấy ăn Shelton 120 vuông trắng 117*117*125mm | D13: cái | G13: =+G12+E13-F13 -> 4 | H13: Nguyễn Thanh Tâm | I13: SX
A14: =+A13+1 -> 6 | C14: Vỏ hộp giấy ăn Shelton 120 vuông trắng 117*117*125mm | D14: cái | G14: =+G13+E14-F14 -> 4 | H14: Nguyễn Thanh Tâm | I14: SX
A15: =+A14+1 -> 7 | C15: Vỏ hộp giấy ăn Shelton 120 vuông trắng 117*117*125mm | D15: cái | G15: =+G14+E15-F15 -> 4 | H15: Nguyễn Thanh Tâm | I15: SX
A16: =+A15+1 -> 8 | C16: Vỏ hộp giấy ăn Shelton 120 vuông trắng 117*117*125mm | D16: cái | G16: =+G15+E16-F16 -> 4 | H16: Nguyễn Thanh Tâm | I16: SX
A17: =+A16+1 -> 9 | C17: Vỏ hộp giấy ăn Shelton 120 vuông trắng 117*117*125mm | D17: cái | G17: =+G16+E17-F17 -> 4
A18: =+A17+1 -> 10 | C18: Vỏ hộp giấy ăn Shelton 120 vuông trắng 117*117*125mm | D18: cái | G18: =+G17+E18-F18 -> 4 | H18: Nguyễn Thanh Tâm | I18: SX
A19: =+A18+1 -> 11 | C19: Vỏ hộp giấy ăn Shelton 120 vuông trắng 117*117*125mm | D19: cái | G19: =+G18+E19-F19 -> 4 | H19: Nguyễn Thanh Tâm | I19: SX
A20: =+A19+1 -> 12 | C20: Vỏ hộp giấy ăn Shelton 120 vuông trắng 117*117*125mm | D20: cái | G20: =+G19+E20-F20 -> 4 | H20: Nguyễn Thanh Tâm | I20: SX
A21: =+A20+1 -> 13 | C21: Vỏ hộp giấy ăn Shelton 120 vuông trắng 117*117*125mm | D21: cái | G21: =+G20+E21-F21 -> 4 | H21: Nguyễn Thanh Tâm | I21: SX
A22: =+A21+1 -> 14 | C22: Vỏ hộp giấy ăn Shelton 120 vuông trắng 117*117*125mm | D22: cái | G22: =+G21+E22-F22 -> 4 | H22: Nguyễn Thanh Tâm | I22: SX
A23: =+A22+1 -> 15 | C23: Vỏ hộp giấy ăn Shelton 120 vuông trắng 117*117*125mm | D23: cái | G23: =+G22+E23-F23 -> 4
A24: =+A23+1 -> 16 | C24: Vỏ hộp giấy ăn Shelton 120 vuông trắng 117*117*125mm | D24: cái | G24: =+G23+E24-F24 -> 4
A25: =+A24+1 -> 17 | C25: Vỏ hộp giấy ăn Shelton 120 vuông trắng 117*117*125mm | D25: cái | G25: =+G24+E25-F25 -> 4
A26: =+A25+1 -> 18 | C26: Vỏ hộp giấy ăn Shelton 120 vuông trắng 117*117*125mm | D26: cái | G26: =+G25+E26-F26 -> 4
A27: =+A26+1 -> 19 | C27: Vỏ hộp giấy ăn Shelton 120 vuông trắng 117*117*125mm | D27: cái | G27: =+G26+E27-F27 -> 4
A28: =+A27+1 -> 20 | C28: Vỏ hộp giấy ăn Shelton 120 vuông trắng 117*117*125mm | D28: cái | G28: =+G27+E28-F28 -> 4
A29: =+A28+1 -> 21 | C29: Vỏ hộp giấy ăn Shelton 120 vuông trắng 117*117*125mm | D29: cái | G29: =+G28+E29-F29 -> 4
A30: =+A29+1 -> 22 | C30: Vỏ hộp giấy ăn Shelton 120 vuông trắng 117*117*125mm | D30: cái | G30: =+G29+E30-F30 -> 4
A31: =+A30+1 -> 23 | C31: Vỏ hộp giấy ăn Shelton 120 vuông trắng 117*117*125mm | D31: cái | G31: =+G30+E31-F31 -> 4
A32: =+A31+1 -> 24 | C32: Vỏ hộp giấy ăn Shelton 120 vuông trắng 117*117*125mm | D32: cái | G32: =+G31+E32-F32 -> 4
A33: =+A32+1 -> 25 | C33: Vỏ hộp giấy ăn Shelton 120 vuông trắng 117*117*125mm | D33: cái | G33: =+G32+E33-F33 -> 4
A34: =+A33+1 -> 26 | C34: Vỏ hộp giấy ăn Shelton 120 vuông trắng 117*117*125mm | D34: cái | G34: =+G33+E34-F34 -> 4
... A37: =+A36+1 -> 29 | C37: Vỏ hộp giấy ăn Shelton 120 vuông trắng 117*117*125mm | D37: cái | G37: =+G36+E37-F37 -> 4
A38: =+A37+1 -> 30 | D38: cái | G38: =+G37+E38-F38 -> 4
A39: =+A38+1 -> 31 | D39: cái | G39: =+G38+E39-F39 -> 4
A40: =+A39+1 -> 32 | D40: cái | G40: =+G39+E40-F40 -> 4
A41: =+A40+1 -> 33 | D41: cái | G41: =+G40+E41-F41 -> 4
A42: =+A41+1 -> 34 | D42: cái | G42: =+G41+E42-F42 -> 4
A43: =+A42+1 -> 35 | D43: cái | G43: =+G42+E43-F43 -> 4
A44: =+A43+1 -> 36 | D44: cái | G44: =+G43+E44-F44 -> 4
A45: =+A44+1 -> 37 | D45: cái | G45: =+G44+E45-F45 -> 4
...

Sheet Hộp 120 Xanh
A1: Công ty TNHH Giấy Đông Á
A2: Thôn Mộc Ty, xã Trưng Trắc, huyện Văn Lâm, tỉnh Hưng Yên
A4: THẺ KHO NGUYÊN VẬT LIỆU
A8: STT | B8: Ngày tháng | C8: Tên nguyên vật liệu | D8: ĐVT | E8: Số lượng nhập | F8: Số lượng xuất | G8: Tồn | H8: Người nhận | I8: Ghi chú
B9: 45658 | C9: Tồn đầu kỳ | G9: 691
A10: 1 | C10: Vỏ hộp giấy ăn Shelton 120 vuông lá xanh 114*125*130mm | D10: Cái | F10: 660 | G10: =+G9+E10-F10 -> 31 | H10: Nguyễn Thanh Tâm | I10: SX
A11: 2 | B11: 45681 | C11: Vỏ hộp giấy ăn Shelton 120 vuông Xanh 114*125*130mm | D11: Cái | E11: 10730 | G11: =+G10+E11-F11 -> 10761 | H11: Nguyễn Thanh Tâm | I11: SX
A12: =+A11+1 -> 3 | B12: 45695 | C12: Vỏ hộp giấy ăn Shelton 120 vuông Xanh 114*125*130mm | D12: Cái | F12: 720 | G12: =+G11+E12-F12 -> 10041 | H12: Nguyễn Thanh Tâm | I12: SX
A13: =+A12+1 -> 4 | B13: 45696 | C13: Vỏ hộp giấy ăn Shelton 120 vuông Xanh 114*125*130mm | D13: Cái | F13: 1204 | G13: =+G12+E13-F13 -> 8837 | H13: Nguyễn Thanh Tâm | I13: SX
A14: =+A13+1 -> 5 | B14: 45698 | C14: Vỏ hộp giấy ăn Shelton 120 vuông Xanh 114*125*130mm | D14: Cái | F14: 1674 | G14: =+G13+E14-F14 -> 7163 | H14: Nguyễn Thanh Tâm | I14: SX
A15: =+A14+1 -> 6 | B15: 45699 | C15: Vỏ hộp giấy ăn Shelton 120 vuông Xanh 114*125*130mm | D15: Cái | F15: 1501 | G15: =+G14+E15-F15 -> 5662 | H15: Nguyễn Thanh Tâm | I15: SX
A16: =+A15+1 -> 7 | B16: 45700 | C16: Vỏ hộp giấy ăn Shelton 120 vuông Xanh 114*125*130mm | D16: Cái | F16: 1540 | G16: =+G15+E16-F16 -> 4122
A17: =+A16+1 -> 8 | B17: 45757 | C17: Vỏ hộp giấy ăn Shelton 120 vuông Xanh 114*125*130mm | D17: Cái | F17: 1388 | G17: =+G16+E17-F17 -> 2734 | H17: Nguyễn Thanh Tâm | I17: SX
A18: =+A17+1 -> 9 | B18: 45758 | C18: Vỏ hộp giấy ăn Shelton 120 vuông Xanh 114*125*130mm | D18: Cái | F18: 1560 | G18: =+G17+E18-F18 -> 1174 | H18: Nguyễn Thanh Tâm | I18: SX | J18: Hỏng 1 hộp
A19: =+A18+1 -> 10 | B19: 45759 | C19: Vỏ hộp giấy ăn Shelton 120 vuông Xanh 114*125*130mm | D19: Cái | F19: 1200 | G19: =+G18+E19-F19 -> -26 | H19: Nguyễn Thanh Tâm | I19: SX
A20: =+A19+1 -> 11 | B20: 45789 | C20: Vỏ hộp giấy ăn Shelton 120 vuông Xanh 114*125*130mm | D20: Cái | E20: 10400 | G20: =+G19+E20-F20 -> 10374 | H20: Nguyễn Thanh Tâm | I20: SX
A21: =+A20+1 -> 12 | B21: 45809 | C21: Vỏ hộp giấy ăn Shelton 120 vuông Xanh 114*125*130mm | D21: Cái | F21: 2174 | G21: =+G20+E21-F21 -> 8200 | H21: Nguyễn Thanh Tâm | I21: SX | J21: Hỏng 2 cái
A22: =+A21+1 -> 13 | B22: 45939 | C22: Vỏ hộp giấy ăn Shelton 120 vuông Xanh 114*125*130mm | D22: Cái | F22: 1414 | G22: =+G21+E22-F22 -> 6786 | H22: Nguyễn Thanh Tâm | I22: SX
A23: =+A22+1 -> 14 | B23: 45940 | C23: Vỏ hộp giấy ăn Shelton 120 vuông Xanh 114*125*130mm | D23: Cái | F23: 2702 | G23: =+G22+E23-F23 -> 4084 | H23: Nguyễn Thanh Tâm | I23: SX
A24: =+A23+1 -> 15 | C24: Vỏ hộp giấy ăn Shelton 120 vuông Xanh 114*125*130mm | D24: Cái | G24: =+G23+E24-F24 -> 4084 | H24: Nguyễn Thanh Tâm | I24: SX
A25: =+A24+1 -> 16 | C25: Vỏ hộp giấy ăn Shelton 120 vuông Xanh 114*125*130mm | D25: Cái | G25: =+G24+E25-F25 -> 4084 | H25: Nguyễn Thanh Tâm | I25: SX
A26: =+A25+1 -> 17 | C26: Vỏ hộp giấy ăn Shelton 120 vuông Xanh 114*125*130mm | D26: Cái | G26: =+G25+E26-F26 -> 4084 | H26: Nguyễn Thanh Tâm | I26: SX | J26: hỏng 1 hộp
A27: =+A26+1 -> 18 | C27: Vỏ hộp giấy ăn Shelton 120 vuông Xanh 114*125*130mm | D27: Cái | G27: =+G26+E27-F27 -> 4084 | H27: Nguyễn Thanh Tâm | I27: SX | J27: hỏng 2 hộp
A28: =+A27+1 -> 19 | C28: Vỏ hộp giấy ăn Shelton 120 vuông Xanh 114*125*130mm | D28: Cái | G28: =+G27+E28-F28 -> 4084 | H28: Nguyễn Thanh Tâm | I28: SX
A29: =+A28+1 -> 20 | C29: Vỏ hộp giấy ăn Shelton 120 vuông Xanh 114*125*130mm | D29: Cái | G29: =+G28+E29-F29 -> 4084 | H29: Nguyễn Thị Liên | I29: Thử máy
A30: =+A29+1 -> 21 | C30: Vỏ hộp giấy ăn Shelton 120 vuông Xanh 114*125*130mm | D30: Cái | G30: =+G29+E30-F30 -> 4084 | H30: Nguyễn Thị Liên | I30: SX | J30: Hỏng 10 cái
A31: =+A30+1 -> 22 | C31: Vỏ hộp giấy ăn Shelton 120 vuông Xanh 114*125*130mm | D31: Cái | G31: =+G30+E31-F31 -> 4084 | H31: Nguyễn Thị Liên | I31: SX
A32: =+A31+1 -> 23 | C32: Vỏ hộp giấy ăn Shelton 120 vuông Xanh 114*125*130mm | D32: cái | G32: =+G31+E32-F32 -> 4084 | H32: Nguyễn thị Liên | I32: SX
A33: =+A32+1 -> 24 | C33: Vỏ hộp giấy ăn Shelton 120 vuông Xanh 114*125*130mm | D33: cái | G33: =+G32+E33-F33 -> 4084
A34: =+A33+1 -> 25 | C34: Vỏ hộp giấy ăn Shelton 120 vuông Xanh 114*125*130mm | D34: cái | G34: =+G33+E34-F34 -> 4084 | H34: Nguyễn Thanh Tâm | I34: SX
A35: =+A34+1 -> 26 | C35: Vỏ hộp giấy ăn Shelton 120 vuông Xanh 114*125*130mm | D35: cái | G35: =+G34+E35-F35 -> 4084 | H35: Nguyễn Thanh Tâm | I35: SX
C36: Vỏ hộp giấy ăn Shelton 120 vuông Xanh 114*125*130mm | D36: cái | G36: =+G35+E36-F36 -> 4084 | H36: Nguyễn Thanh Tâm | I36: SX
A37: =+A35+1 -> 27 | C37: Vỏ hộp giấy ăn Shelton 120 vuông Xanh 114*125*130mm | D37: cái | G37: =+G36+E37-F37 -> 4084 | H37: Nguyễn Thanh Tâm | I37: SX
A38: =+A37+1 -> 28 | C38: Vỏ hộp giấy ăn Shelton 120 vuông Xanh 114*125*130mm | D38: cái | G38: =+G37+E38-F38 -> 4084 | H38: Nguyễn Thanh Tâm | I38: SX
A39: =+A38+1 -> 29 | C39: Vỏ hộp giấy ăn Shelton 120 vuông Xanh 114*125*130mm | D39: cái | G39: =+G38+E39-F39 -> 4084 | H39: Nguyễn Thanh Tâm | I39: SX
C40: Vỏ hộp giấy ăn Shelton 120 vuông Xanh 114*125*130mm | D40: cái | G40: =+G39+E40-F40 -> 4084 | H40: Nguyễn Thanh Tâm | I40: SX
C41: Vỏ hộp giấy ăn Shelton 120 vuông Xanh 114*125*130mm | D41: cái | G41: =+G40+E41-F41 -> 4084 | H41: Nguyễn Thanh Tâm | I41: SX
C42: Vỏ hộp giấy ăn Shelton 120 vuông Xanh 114*125*130mm | D42: cái | G42: =+G41+E42-F42 -> 4084
C43: Vỏ hộp giấy ăn Shelton 120 vuông Xanh 114*125*130mm | D43: cái | G43: =+G42+E43-F43 -> 4084
C44: Vỏ hộp giấy ăn Shelton 120 vuông Xanh 114*125*130mm | D44: cái | G44: =+G43+E44-F44 -> 4084
...

Sheet Hộp bướm đen
A1: Công ty TNHH Giấy Đông Á
A2: Thôn Mộc Ty, xã Trưng Trắc, huyện Văn Lâm, tỉnh Hưng Yên
A4: THẺ KHO NGUYÊN VẬT LIỆU
A8: STT | B8: Ngày tháng | C8: Tên nguyên vật liệu | D8: ĐVT | E8: Số lượng nhập | F8: Số lượng xuất | G8: Tồn | H8: Người nhận | I8: Ghi chú
B9: 45658 | C9: Tồn đầu kỳ | G9: 6237
A10: 1 | C10: Vỏ hộp Shelton cánh bướm đen 180 tờ | D10: cái | G10: =+G9+E10-F10 -> 6237
A11: =+A10+1 -> 2 | C11: Vỏ hộp Shelton cánh bướm đen 180 tờ | D11: cái | G11: =+G10+E11-F11 -> 6237
A12: =+A11+1 -> 3 | C12: Vỏ hộp Shelton cánh bướm đen 180 tờ | D12: cái | G12: =+G11+E12-F12 -> 6237
A13: =+A12+1 -> 4 | C13: Vỏ hộp Shelton cánh bướm đen 180 tờ | D13: cái | G13: =+G12+E13-F13 -> 6237
A14: =+A13+1 -> 5 | C14: Vỏ hộp Shelton cánh bướm đen 180 tờ | D14: cái | G14: =+G13+E14-F14 -> 6237
A15: =+A14+1 -> 6 | C15: Vỏ hộp Shelton cánh bướm đen 180 tờ | D15: cái | G15: =+G14+E15-F15 -> 6237
A16: =+A15+1 -> 7 | C16: Vỏ hộp Shelton cánh bướm đen 180 tờ | D16: cái | G16: =+G15+E16-F16 -> 6237
A17: =+A16+1 -> 8 | C17: Vỏ hộp Shelton cánh bướm đen 180 tờ | D17: cái | G17: =+G16+E17-F17 -> 6237
A18: =+A17+1 -> 9 | C18: Vỏ hộp Shelton cánh bướm đen 180 tờ | D18: cái | G18: =+G17+E18-F18 -> 6237
A19: =+A18+1 -> 10 | C19: Vỏ hộp Shelton cánh bướm đen 180 tờ | D19: cái | G19: =+G18+E19-F19 -> 6237
A20: =+A19+1 -> 11 | C20: Vỏ hộp Shelton cánh bướm đen 180 tờ | D20: cái | G20: =+G19+E20-F20 -> 6237
A21: =+A20+1 -> 12 | C21: Vỏ hộp Shelton cánh bướm đen 180 tờ | D21: cái | G21: =+G20+E21-F21 -> 6237
A22: =+A21+1 -> 13 | C22: Vỏ hộp Shelton cánh bướm đen 180 tờ | D22: cái | G22: =+G21+E22-F22 -> 6237
... A41: =+A40+1 -> 32 | C41: Vỏ hộp Shelton cánh bướm đen 180 tờ | D41: cái | G41: =+G40+E41-F41 -> 6237
C42: Tổng cộng | E42: =SUM(E10:E41) -> 0 | F42: =SUM(F10:F41) -> 0 | G42: =+E42-F42+G9 -> 6237

Sheet Hộp HV
A1: Công ty TNHH Giấy Đông Á
A2: Thôn Mộc Ty, xã Trưng Trắc, huyện Văn Lâm, tỉnh Hưng Yên
A4: =+'[1]Hộp CB'!A4:I5 -> THẺ KHO NGUYÊN VẬT LIỆU
J5: =5+10+5+2+10+10+3+7+8 -> 60
A7: STT | B7: Ngày tháng | C7: Tên nguyên vật liệu | D7: ĐVT | E7: Số lượng nhập | F7: Số lượng xuất | G7: Tồn | H7: Người nhận | I7: Ghi chú | J7: =600+60 -> 660
B8: 45658 | C8: Tồn đầu kỳ | G8: 5672
A9: 1 | B9: 45674 | C9: Vỏ hộp Shelton Hồng Vàng 180 tờ ( 90*120*220mm) | D9: Cái | F9: 100 | G9: =+G8+E9-F9 -> 5572 | H9: Nguyễn Thanh Tâm | I9: Sản xuất
A10: =+A9+1 -> 2 | B10: 45675 | C10: Vỏ hộp Shelton Hồng Vàng 180 tờ ( 90*120*220mm) | D10: Cái | F10: 350 | G10: =+G9+E10-F10 -> 5222 | H10: Nguyễn Thanh Tâm | I10: Sản xuất
A11: =+A10+1 -> 3 | B11: 45776 | C11: Vỏ hộp Shelton Hồng Vàng 180 tờ ( 90*120*220mm) | D11: Cái | F11: 1426 | G11: =+G10+E11-F11 -> 3796 | H11: Nguyễn Thanh Tâm | I11: Sản xuất
A12: =+A11+1 -> 4 | B12: 45869 | C12: Vỏ hộp Shelton Hồng Vàng 180 tờ ( 90*120*220mm) | D12: Cái | F12: 23 | G12: =+G11+E12-F12 -> 3773 | H12: Nguyễn Thanh Tâm | I12: Sản xuất | J12: Hỏng 1 hộp
A13: =+A12+1 -> 5 | B13: 45898 | C13: Vỏ hộp Shelton Hồng Vàng 180 tờ ( 90*120*220mm) | D13: Cái | F13: 420 | G13: =+G12+E13-F13 -> 3353
A14: =+A13+1 -> 6 | B14: 45899 | C14: Vỏ hộp Shelton Hồng Vàng 180 tờ ( 90*120*220mm) | D14: Cái | F14: 1380 | G14: =+G13+E14-F14 -> 1973 | H14: Nguyễn Thanh Tâm | I14: Sản xuất | K14: =9*400+202 -> 3802
A15: =+A14+1 -> 7 | B15: 45912 | C15: Vỏ hộp Shelton Hồng Vàng 180 tờ ( 90*120*220mm) | D15: Cái | F15: 10 | G15: =+G14+E15-F15 -> 1963 | H15: Nguyễn Thanh Tâm | I15: Sản xuất | J15: =360+585 -> 945
A16: =+A15+1 -> 8 | C16: Vỏ hộp Shelton Hồng Vàng 180 tờ ( 90*120*220mm) | D16: Cái | G16: =+G15+E16-F16 -> 1963 | H16: Nguyễn Thanh Tâm | I16: Sản xuất | J16: =360+585 -> 945
A17: =+A16+1 -> 9 | C17: Vỏ hộp Shelton Hồng Vàng 180 tờ ( 90*120*220mm) | D17: Cái | G17: =+G16+E17-F17 -> 1963 | H17: Nguyễn Thanh Tâm | I17: Sản xuất
A18: =+A17+1 -> 10 | C18: Vỏ hộp Shelton Hồng Vàng 180 tờ ( 90*120*220mm) | D18: Cái | G18: =+G17+E18-F18 -> 1963
A19: =+A18+1 -> 11 | C19: Vỏ hộp Shelton Hồng Vàng 180 tờ ( 90*120*220mm) | D19: Cái | G19: =+G18+E19-F19 -> 1963 | K19: =17*450+426 -> 8076
A20: =+A19+1 -> 12 | C20: Vỏ hộp Shelton Hồng Vàng 180 tờ ( 90*120*220mm) | D20: Cái | G20: =+G19+E20-F20 -> 1963
A21: =+A20+1 -> 13 | C21: Vỏ hộp Shelton Hồng Vàng 180 tờ ( 90*120*220mm) | D21: Cái | G21: =+G20+E21-F21 -> 1963
A22: =+A21+1 -> 14 | C22: Vỏ hộp Shelton Hồng Vàng 180 tờ ( 90*120*220mm) | D22: Cái | G22: =+G21+E22-F22 -> 1963
A23: =+A22+1 -> 15 | C23: Vỏ hộp Shelton Hồng Vàng 180 tờ ( 90*120*220mm) | D23: Cái | G23: =+G22+E23-F23 -> 1963
A24: =+A23+1 -> 16 | C24: Vỏ hộp Shelton Hồng Vàng 180 tờ ( 90*120*220mm) | D24: Cái | G24: =+G23+E24-F24 -> 1963
A25: =+A24+1 -> 17 | C25: Vỏ hộp Shelton Hồng Vàng 180 tờ ( 90*120*220mm) | D25: Cái | G25: =+G24+E25-F25 -> 1963
A26: =+A25+1 -> 18 | C26: Vỏ hộp Shelton Hồng Vàng 180 tờ ( 90*120*220mm) | D26: Cái | G26: =+G25+E26-F26 -> 1963
A27: =+A26+1 -> 19 | C27: Vỏ hộp Shelton Hồng Vàng 180 tờ ( 90*120*220mm) | D27: Cái | G27: =+G26+E27-F27 -> 1963
A28: =+A27+1 -> 20 | C28: Vỏ hộp Shelton Hồng Vàng 180 tờ ( 90*120*220mm) | D28: Cái | G28: =+G27+E28-F28 -> 1963
A29: =+A28+1 -> 21 | C29: Vỏ hộp Shelton Hồng Vàng 180 tờ ( 90*120*220mm) | D29: Cái | G29: =+G28+E29-F29 -> 1963
A30: =+A29+1 -> 22 | C30: Vỏ hộp Shelton Hồng Vàng 180 tờ ( 90*120*220mm) | D30: Cái | G30: =+G29+E30-F30 -> 1963
A31: =+A30+1 -> 23 | C31: Vỏ hộp Shelton Hồng Vàng 180 tờ ( 90*120*220mm) | D31: Cái | G31: =+G30+E31-F31 -> 1963
... A51: =+A50+1 -> 43 | C51: Vỏ hộp Shelton Hồng Vàng 180 tờ ( 90*120*220mm) | D51: Cái | G51: =+G50+E51-F51 -> 1963
A52: =+A51+1 -> 44 | G52: =+G51+E52-F52 -> 1963
A53: =+A52+1 -> 45 | G53: =+G52+E53-F53 -> 1963
A54: =+A53+1 -> 46 | G54: =+G53+E54-F54 -> 1963
A55: =+A54+1 -> 47 | G55: =+G54+E55-F55 -> 1963
A56: =+A55+1 -> 48 | G56: =+G55+E56-F56 -> 1963
A57: =+A56+1 -> 49 | G57: =+G56+E57-F57 -> 1963
A58: =+A57+1 -> 50 | G58: =+G57+E58-F58 -> 1963
A59: =+A58+1 -> 51 | G59: =+G58+E59-F59 -> 1963
A60: =+A59+1 -> 52 | G60: =+G59+E60-F60 -> 1963
C61: Tổng cộng | E61: =SUM(E9:E60) -> 0 | F61: =SUM(F9:F60) -> 3709 | G61: =+G8+E61-F61 -> 1963
...

Sheet Hộp hồng đỏ
A1: Công ty TNHH Giấy Đông Á
A2: Thôn Mộc Ty, xã Trưng Trắc, huyện Văn Lâm, tỉnh Hưng Yên
A4: =+'[1]Hộp CB'!A4:I5 -> THẺ KHO NGUYÊN VẬT LIỆU
J5: =5+10+5+2+10+10+3+7+8 -> 60
A7: STT | B7: Ngày tháng | C7: Tên nguyên vật liệu | D7: ĐVT | E7: Số lượng nhập | F7: Số lượng xuất | G7: Tồn | H7: Người nhận | I7: Ghi chú
B8: 45658 | C8: Tồn đầu kỳ | G8: 8676
A9: 1 | C9: Vỏ hộp Shelton Hồng Đỏ 180 tờ (90*120*220mm) | D9: Cái | G9: =+G8+E9-F9 -> 8676 | H9: Nguyễn thanh Tâm | I9: SX
A10: =+A9+1 -> 2 | C10: Vỏ hộp Shelton Hồng Đỏ 180 tờ (90*120*220mm) | D10: Cái | G10: =+G9+E10-F10 -> 8676 | H10: Nguyễn Thị Liên | I10: SX
A11: =+A10+1 -> 3 | C11: Vỏ hộp Shelton Hồng Đỏ 180 tờ (90*120*220mm) | G11: =+G10+E11-F11 -> 8676 | H11: Nguyễn thanh Tâm | I11: SX
A12: =+A11+1 -> 4 | C12: Vỏ hộp Shelton Hồng Đỏ 180 tờ (90*120*220mm) | G12: =+G11+E12-F12 -> 8676 | H12: Nguyễn thanh Tâm | I12: SX
A13: =+A12+1 -> 5 | C13: Vỏ hộp Shelton Hồng Đỏ 180 tờ (90*120*220mm) | G13: =+G12+E13-F13 -> 8676 | H13: Nguyễn thanh Tâm | I13: SX
A14: =+A13+1 -> 6 | C14: Vỏ hộp Shelton Hồng Đỏ 180 tờ (90*120*220mm) | G14: =+G13+E14-F14 -> 8676 | H14: Nguyễn thanh Tâm | I14: SX
A15: =+A14+1 -> 7 | C15: Vỏ hộp Shelton Hồng Đỏ 180 tờ (90*120*220mm) | G15: =+G14+E15-F15 -> 8676
A16: =+A15+1 -> 8 | C16: Vỏ hộp Shelton Hồng Đỏ 180 tờ (90*120*220mm) | G16: =+G15+E16-F16 -> 8676
A17: =+A16+1 -> 9 | C17: Vỏ hộp Shelton Hồng Đỏ 180 tờ (90*120*220mm) | G17: =+G16+E17-F17 -> 8676
A18: =+A17+1 -> 10 | C18: Vỏ hộp Shelton Hồng Đỏ 180 tờ (90*120*220mm) | G18: =+G17+E18-F18 -> 8676
A19: =+A18+1 -> 11 | C19: Vỏ hộp Shelton Hồng Đỏ 180 tờ (90*120*220mm) | G19: =+G18+E19-F19 -> 8676
A20: =+A19+1 -> 12 | C20: Vỏ hộp Shelton Hồng Đỏ 180 tờ (90*120*220mm) | G20: =+G19+E20-F20 -> 8676
A21: =+A20+1 -> 13 | C21: Vỏ hộp Shelton Hồng Đỏ 180 tờ (90*120*220mm) | G21: =+G20+E21-F21 -> 8676
A22: =+A21+1 -> 14 | C22: Vỏ hộp Shelton Hồng Đỏ 180 tờ (90*120*220mm) | G22: =+G21+E22-F22 -> 8676
A23: =+A22+1 -> 15 | C23: Vỏ hộp Shelton Hồng Đỏ 180 tờ (90*120*220mm) | G23: =+G22+E23-F23 -> 8676
A24: =+A23+1 -> 16 | G24: =+G23+E24-F24 -> 8676
A25: =+A24+1 -> 17 | G25: =+G24+E25-F25 -> 8676
A26: =+A25+1 -> 18 | G26: =+G25+E26-F26 -> 8676
A27: =+A26+1 -> 19 | G27: =+G26+E27-F27 -> 8676
A28: =+A27+1 -> 20 | G28: =+G27+E28-F28 -> 8676
A29: =+A28+1 -> 21 | G29: =+G28+E29-F29 -> 8676
A30: =+A29+1 -> 22 | G30: =+G29+E30-F30 -> 8676
A31: =+A30+1 -> 23 | G31: =+G30+E31-F31 -> 8676
A32: =+A31+1 -> 24 | G32: =+G31+E32-F32 -> 8676
A33: =+A32+1 -> 25 | G33: =+G32+E33-F33 -> 8676
A34: =+A33+1 -> 26 | G34: =+G33+E34-F34 -> 8676
A35: =+A34+1 -> 27 | G35: =+G34+E35-F35 -> 8676
... A41: =+A40+1 -> 33 | G41: =+G40+E41-F41 -> 8676
G42: =+G41+E42-F42 -> 8676
C43: Tổng cộng | E43: =SUM(E9:E42) -> 0 | F43: =SUM(F9:F42) -> 0 | G43: =+G8+E43-F43 -> 8676
F44: =18676-18566 -> 110
F54: =481-442 -> 39
G60: =442-360 -> 82

Sheet Hộp bướm bạc
A1: Công ty TNHH Giấy Đông Á
A2: Thôn Mộc Ty, xã Trưng Trắc, huyện Văn Lâm, tỉnh Hưng Yên
A4: THẺ KHO NGUYÊN VẬT LIỆU
A8: STT | B8: Ngày tháng | C8: Tên nguyên vật liệu | D8: ĐVT | E8: Số lượng nhập | F8: Số lượng xuất | G8: Tồn | H8: Người nhận | I8: Ghi chú
B9: 45658 | C9: Tồn đầu kỳ | G9: 762
A10: 1 | B10: 45674 | C10: Vỏ hộp Shelton Cánh bướm trắng 180 tờ (90*120*220mm) | D10: Hộp | F10: 100 | G10: =+G9+E10-F10 -> 662 | H10: Nguyễn Thanh Tâm | I10: SX
A11: =+A10+1 -> 2 | B11: 45675 | C11: Vỏ hộp Shelton Cánh bướm trắng 180 tờ (90*120*220mm) | D11: Hộp | F11: 320 | G11: =+G10+E11-F11 -> 342 | H11: Nguyễn Thanh Tâm | I11: SX
A12: =+A11+1 -> 3 | C12: Vỏ hộp Shelton Cánh bướm trắng 180 tờ (90*120*220mm) | D12: Hộp | G12: =+G11+E12-F12 -> 342 | H12: Nguyễn Thanh Tâm | I12: SX
A13: =+A12+1 -> 4 | C13: Vỏ hộp Shelton Cánh bướm trắng 180 tờ (90*120*220mm) | D13: Hộp | G13: =+G12+E13-F13 -> 342 | H13: Nguyễn Thanh Tâm | I13: SX
A14: =+A13+1 -> 5 | C14: Vỏ hộp Shelton Cánh bướm trắng 180 tờ (90*120*220mm) | D14: Hộp | G14: =+G13+E14-F14 -> 342 | H14: Nguyễn Thanh Tâm | I14: SX
A15: =+A14+1 -> 6 | C15: Vỏ hộp Shelton Cánh bướm trắng 180 tờ (90*120*220mm) | D15: Hộp | G15: =+G14+E15-F15 -> 342 | H15: Nguyễn Thanh Tâm | I15: SX | J15: Hỏng 5 hộp
A16: =+A15+1 -> 7 | G16: =+G15+E16-F16 -> 342
A17: =+A16+1 -> 8 | G17: =+G16+E17-F17 -> 342
A18: =+A17+1 -> 9 | G18: =+G17+E18-F18 -> 342
A19: =+A18+1 -> 10 | G19: =+G18+E19-F19 -> 342
A20: =+A19+1 -> 11 | G20: =+G19+E20-F20 -> 342
A21: =+A20+1 -> 12 | G21: =+G20+E21-F21 -> 342
A22: =+A21+1 -> 13 | G22: =+G21+E22-F22 -> 342
A23: =+A22+1 -> 14 | G23: =+G22+E23-F23 -> 342
A24: =+A23+1 -> 15 | G24: =+G23+E24-F24 -> 342
A25: =+A24+1 -> 16 | G25: =+G24+E25-F25 -> 342
A26: =+A25+1 -> 17 | G26: =+G25+E26-F26 -> 342
A27: =+A26+1 -> 18 | G27: =+G26+E27-F27 -> 342
... A36: =+A35+1 -> 27 | G36: =+G35+E36-F36 -> 342
G37: =+G36+E37-F37 -> 342
G38: =+G37+E38-F38 -> 342
G39: =+G38+E39-F39 -> 342
G40: =+G39+E40-F40 -> 342
G41: =+G40+E41-F41 -> 342
A42: =+A36+1 -> 28 | G42: =+G41+E42-F42 -> 342
A43: =+A42+1 -> 29 | G43: =+G42+E43-F43 -> 342
A44: =+A43+1 -> 30 | G44: =+G43+E44-F44 -> 342
A45: =+A44+1 -> 31 | G45: =+G44+E45-F45 -> 342
A46: =+A45+1 -> 32 | G46: =+G45+E46-F46 -> 342
C47: Tổng cộng | E47: =SUM(E10:E46) -> 0 | F47: =SUM(F10:F46) -> 420 | G47: =+E47-F47+G9 -> 342

Sheet Hộp NX
A1: Công ty TNHH Giấy Đông Á
A2: Thôn Mộc Ty, xã Trưng Trắc, huyện Văn Lâm, tỉnh Hưng Yên
A4: =+'[1]Hộp HV'!A4:I5 -> THẺ KHO NGUYÊN VẬT LIỆU
A7: STT | B7: Ngày tháng | C7: Tên nguyên vật liệu | D7: ĐVT | E7: Số lượng nhập | F7: Số lượng xuất | G7: Tồn | H7: Người nhận | I7: Ghi chú
B8: 45658 | C8: Tồn đầu kỳ | G8: 1364
A9: 1 | B9: 45674 | C9: Vỏ hộp Shelton hoa nhí Xanh 180 tờ (90*120*220mm) | D9: Hộp | F9: 100 | G9: =+G8+E9-F9 -> 1264 | H9: Nguyễn Thanh Tâm | I9: Sản xuất
A10: =+A9+1 -> 2 | B10: 45675 | C10: Vỏ hộp Shelton hoa nhí Xanh 90*120*220mm | D10: Hộp | F10: 920 | G10: =+G9+E10-F10 -> 344 | H10: Nguyễn Thanh Tâm | I10: Sản xuất
A11: =+A10+1 -> 3 | B11: 45804 | C11: Vỏ hộp Shelton hoa nhí Xanh 90*120*220mm | F11: 360 | G11: =+G10+E11-F11 -> -16 | H11: Nguyễn Thanh Tâm | I11: Sản xuất
A12: =+A11+1 -> 4 | B12: 45853 | C12: Vỏ hộp Shelton hoa nhí Xanh 90*120*220mm | E12: 10130 | G12: =+G11+E12-F12 -> 10114 | H12: Nguyễn Thanh Tâm | I12: Sản xuất
A13: =+A12+1 -> 5 | B13: 45867 | C13: Vỏ hộp Shelton hoa nhí Xanh 90*120*220mm | F13: 240 | G13: =+G12+E13-F13 -> 9874
A14: =+A13+1 -> 6 | B14: 45868 | C14: Vỏ hộp Shelton hoa nhí Xanh 90*120*220mm | F14: 1380 | G14: =+G13+E14-F14 -> 8494
A15: =+A14+1 -> 7 | B15: 45869 | C15: Vỏ hộp Shelton hoa nhí Xanh 90*120*220mm | F15: 1380 | G15: =+G14+E15-F15 -> 7114
A16: =+A15+1 -> 8 | B16: 45839 | C16: Vỏ hộp Shelton hoa nhí Xanh 90*120*220mm | F16: 384 | G16: =+G15+E16-F16 -> 6730
A17: =+A16+1 -> 9 | C17: Vỏ hộp Shelton hoa nhí Xanh 90*120*220mm | G17: =+G16+E17-F17 -> 6730
A18: =+A17+1 -> 10 | C18: Vỏ hộp Shelton hoa nhí Xanh 90*120*220mm | G18: =+G17+E18-F18 -> 6730
A19: =+A18+1 -> 11 | G19: =+G18+E19-F19 -> 6730
A20: =+A19+1 -> 12 | G20: =+G19+E20-F20 -> 6730
A21: =+A20+1 -> 13 | G21: =+G20+E21-F21 -> 6730
A22: =+A21+1 -> 14 | G22: =+G21+E22-F22 -> 6730
A23: =+A22+1 -> 15 | G23: =+G22+E23-F23 -> 6730
A24: =+A23+1 -> 16 | G24: =+G23+E24-F24 -> 6730
A25: =+A24+1 -> 17 | G25: =+G24+E25-F25 -> 6730
A26: =+A25+1 -> 18 | G26: =+G25+E26-F26 -> 6730
A27: =+A26+1 -> 19 | G27: =+G26+E27-F27 -> 6730
A28: =+A27+1 -> 20 | G28: =+G27+E28-F28 -> 6730
A29: =+A28+1 -> 21 | G29: =+G28+E29-F29 -> 6730
A30: =+A29+1 -> 22 | G30: =+G29+E30-F30 -> 6730
... A57: =+A56+1 -> 49 | G57: =+G56+E57-F57 -> 6730
C58: Tổng cộng | E58: =SUM(E9:E57) -> 10130 | F58: =SUM(F9:F57) -> 4764 | G58: =+E58-F58+G8 -> 6730

Sheet Hộp oto
A1: Công ty TNHH Giấy Đông Á
A2: Thôn Mộc Ty, xã Trưng Trắc, huyện Văn Lâm, tỉnh Hưng Yên
A4: =+'[1]Hộp CB nền bạc'!A4:I5 -> THẺ KHO NGUYÊN VẬT LIỆU
A7: STT | B7: Ngày tháng | C7: Tên nguyên vật liệu | D7: ĐVT | E7: Số lượng nhập | F7: Số lượng xuất | G7: Tồn | H7: Người nhận | I7: Ghi chú
B8: 45658 | C8: Tồn đầu kỳ | G8: 649
A9: 1 | C9: vỏ hộp Shelton oto đen 180 tờ | D9: hộp | G9: =+G8+E9-F9 -> 649
A10: =+A9+1 -> 2 | G10: =+G9+E10-F10 -> 649
A11: =+A10+1 -> 3 | G11: =+G10+E11-F11 -> 649
A12: =+A11+1 -> 4 | G12: =+G11+E12-F12 -> 649
A13: =+A12+1 -> 5 | G13: =+G12+E13-F13 -> 649
A14: =+A13+1 -> 6 | G14: =+G13+E14-F14 -> 649
A15: =+A14+1 -> 7 | G15: =+G14+E15-F15 -> 649
A16: =+A15+1 -> 8 | G16: =+G15+E16-F16 -> 649
A17: =+A16+1 -> 9 | G17: =+G16+E17-F17 -> 649
A18: =+A17+1 -> 10 | G18: =+G17+E18-F18 -> 649
A19: =+A18+1 -> 11 | G19: =+G18+E19-F19 -> 649
G20: =+G19+E20-F20 -> 649
A21: 1 | G21: =+G20+E21-F21 -> 649
A22: =+A21+1 -> 2 | G22: =+G21+E22-F22 -> 649
A23: =+A22+1 -> 3 | G23: =+G22+E23-F23 -> 649
A24: =+A23+1 -> 4 | G24: =+G23+E24-F24 -> 649
A25: =+A24+1 -> 5 | G25: =+G24+E25-F25 -> 649
A26: =+A25+1 -> 6 | G26: =+G25+E26-F26 -> 649
A27: =+A26+1 -> 7 | G27: =+G26+E27-F27 -> 649
A28: =+A27+1 -> 8 | G28: =+G27+E28-F28 -> 649
A29: =+A28+1 -> 9 | G29: =+G28+E29-F29 -> 649
A30: =+A29+1 -> 10 | G30: =+G29+E30-F30 -> 649
C31: Tổng cộng | E31: =SUM(E20:E30) -> 0 | F31: =SUM(F9:F30) -> 0 | G31: =+E31-F31+G8 -> 649

Sheet Bao Trắng 180
A1: Cty TNHH Đông Á
A2: Thôn Mộc Ty, xã Trưng Trắc, huyện Văn Lâm, tỉnh Hưng Yên
A4: =+'[1]Hộp oto'!A4:I5 -> THẺ KHO NGUYÊN VẬT LIỆU
A7: STT | B7: Ngày tháng | C7: Tên nguyên vật liệu | D7: ĐVT | E7: Số lượng nhập | F7: Số lượng xuất | G7: Tồn | H7: Người nhận | I7: Ghi chú
B8: 45658 | C8: Tồn đầu kỳ | D8: kg | G8: 375
B9: 45668 | C9: Túi Nilong trắng đựng hộp 180 | D9: kg | F9: 0.7 | G9: =+G8+E9-F9 -> 374.3 | H9: Nguyễn Thị ,Tâm | I9: SX | J9: Nhập lại kho cho khớp vưới kk ngày 28/02/2019
B10: 45674 | C10: Túi Nilong trắng đựng hộp 180 | D10: kg | F10: 1.4 | G10: =+G9+E10-F10 -> 372.9 | H10: Nguyễn Thị ,Tâm | I10: SX
B11: 45675 | C11: Túi Nilong trắng đựng hộp 180 | D11: kg | F11: 6.7 | G11: =+G10+E11-F11 -> 366.2 | H11: Nguyễn Thị ,Tâm | I11: SX
B12: 45743 | C12: Túi Nilong trắng đựng hộp 180 | D12: kg | F12: 1.2 | G12: =+G11+E12-F12 -> 365 | H12: Liên | I12: SX.sp 3 lớp 115*175
B13: 45769 | C13: Túi Nilong trắng đựng hộp 180 | D13: kg | F13: 1.8 | G13: =+G12+E13-F13 -> 363.2 | H13: Nguyễn Thị ,Tâm | I13: SX
B14: 45770 | C14: Túi Nilong trắng đựng hộp 180 | D14: kg | F14: 1.9 | G14: =+G13+E14-F14 -> 361.3 | H14: Nguyễn Thị ,Tâm | I14: SX
B15: 45771 | C15: Túi Nilong trắng đựng hộp 180 | D15: kg | F15: 2 | G15: =+G14+E15-F15 -> 359.3 | H15: Nguyễn Thị Liên | I15: SX
B16: 45772 | C16: Túi Nilong trắng đựng hộp 180 | D16: kg | F16: 0.6 | G16: =+G15+E16-F16 -> 358.7 | H16: Nguyễn Thị Liên | I16: SX
B17: 45774 | C17: Túi Nilong trắng đựng hộp 180 | D17: kg | F17: 1.8 | G17: =+G16+E17-F17 -> 356.9 | H17: Nguyễn Thị ,Tâm | I17: Đựng phế
B18: 45775 | C18: Túi Nilong trắng đựng hộp 180 | D18: kg | F18: 1.7 | G18: =+G17+E18-F18 -> 355.2 | H18: Nguyễn Thị ,Tâm | I18: SX | O18: =2*16+10 -> 42
B19: 45776 | C19: Túi Nilong trắng đựng hộp 180 | D19: kg | F19: 9.7 | G19: =+G18+E19-F19 -> 345.5 | H19: Nguyễn Thị ,Tâm | I19: SX
B20: 45782 | C20: Túi Nilong trắng đựng hộp 180 | D20: kg | F20: 1.9 | G20: =+G19+E20-F20 -> 343.6
B21: 45783 | C21: Túi Nilong trắng đựng hộp 180 | D21: kg | F21: 1 | G21: =+G20+E21-F21 -> 342.6 | H21: Nguyễn Thị ,Tâm | I21: SX
B22: 45784 | C22: Túi Nilong trắng đựng hộp 180 | D22: kg | F22: 1.5 | G22: =+G21+E22-F22 -> 341.1 | H22: Nguyễn Thị ,Tâm | I22: SX
B23: 45785 | C23: Túi Nilong trắng đựng hộp 180 | D23: kg | F23: 3.9 | G23: =+G22+E23-F23 -> 337.2 | H23: Nguyễn Thị ,Tâm | I23: SX
B24: 45789 | C24: Túi Nilong trắng đựng hộp 180 | D24: kg | F24: 2.5 | G24: =+G23+E24-F24 -> 334.7 | H24: Nguyễn Thị ,Tâm | I24: SX
B25: 45790 | C25: Túi Nilong trắng đựng hộp 180 | F25: 1.2 | G25: =+G24+E25-F25 -> 333.5 | H25: Nguyễn Thị ,Tâm | I25: SX
B26: 45804 | C26: Túi Nilong trắng đựng hộp 180 | D26: kg | F26: 1.4 | G26: =+G25+E26-F26 -> 332.1 | H26: Nguyễn Thị ,Tâm | I26: SX
B27: 45817 | C27: Túi Nilong trắng đựng hộp 180 | D27: kg | F27: 1.7 | G27: =+G26+E27-F27 -> 330.4 | H27: Nguyến thị Liên | I27: SX
B28: 45818 | C28: Túi Nilong trắng đựng hộp 180 | D28: kg | F28: 1.5 | G28: =+G27+E28-F28 -> 328.9 | H28: Nguyễn Thị ,Tâm | I28: SX
B29: 45820 | C29: Túi Nilong trắng đựng hộp 180 | D29: kg | F29: 2.2 | G29: =+G28+E29-F29 -> 326.7 | H29: Nguyễn Thị ,Tâm | I29: SX
B30: 45821 | C30: Túi Nilong trắng đựng hộp 180 | D30: kg | F30: 3.8 | G30: =+G29+E30-F30 -> 322.9 | H30: Nguyễn Thị ,Tâm | I30: SX
B31: 45822 | C31: Túi Nilong trắng đựng hộp 180 | D31: kg | F31: 4 | G31: =+G30+E31-F31 -> 318.9 | H31: Nguyễn Thị ,Tâm | I31: SX
B32: 45824 | C32: Túi Nilong trắng đựng hộp 180 | D32: kg | F32: 3.2 | G32: =+G31+E32-F32 -> 315.7 | H32: Nguyễn Thị ,Tâm | I32: SX
B33: 45825 | C33: Túi Nilong trắng đựng hộp 180 | D33: kg | F33: 3.8 | G33: =+G32+E33-F33 -> 311.9 | H33: Nguyễn Thị ,Tâm | I33: SX
B34: 45829 | C34: Túi Nilong trắng đựng hộp 180 | D34: kg | F34: 0.5 | G34: =+G33+E34-F34 -> 311.4 | H34: Nguyễn Thị ,Tâm | I34: SX
B35: 45836 | C35: Túi Nilong trắng đựng hộp 180 | D35: kg | F35: 2.3 | G35: =+G34+E35-F35 -> 309.1 | H35: Nguyễn Thị ,Tâm | I35: SX
B36: 45838 | C36: Túi Nilong trắng đựng hộp 180 | D36: kg | F36: 3.5 | G36: =+G35+E36-F36 -> 305.6 | H36: Nguyễn Thị ,Tâm | I36: SX
B37: 45842 | C37: Túi Nilong trắng đựng hộp 180 | D37: kg | F37: 2.3 | G37: =+G36+E37-F37 -> 303.3 | H37: Nguyễn Thị ,Tâm | I37: SX
... B74: 45929 | C74: Túi Nilong trắng đựng hộp 180 | D74: kg | F74: 2.6 | G74: =+G73+E74-F74 -> 193.4 | H74: Nguyễn Thị ,Tâm | I74: SX
C75: Túi Nilong trắng đựng hộp 180 | D75: kg | G75: =+G74+E75-F75 -> 193.4 | H75: Nguyễn Thị ,Tâm | I75: SX
C76: Túi Nilong trắng đựng hộp 180 | D76: kg | G76: =+G75+E76-F76 -> 193.4 | H76: Nguyễn Thị ,Tâm | I76: SX
C77: Túi Nilong trắng đựng hộp 180 | D77: kg | G77: =+G76+E77-F77 -> 193.4
C78: Túi Nilong trắng đựng hộp 180 | D78: kg | G78: =+G77+E78-F78 -> 193.4
C79: Túi Nilong trắng đựng hộp 180 | D79: kg | G79: =+G78+E79-F79 -> 193.4
...

Sheet Bao vô cây CN 
A1: Cty TNHH Đông Á
A2: Thôn Mộc Ty, xã Trưng Trắc, huyện Văn Lâm, tỉnh Hưng Yên
A4: =+'[1]Hộp oto'!A4:I5 -> THẺ KHO NGUYÊN VẬT LIỆU
A7: STT | B7: Ngày tháng | C7: Tên nguyên vật liệu | D7: ĐVT | E7: Số lượng nhập | F7: Số lượng xuất | G7: Tồn | H7: Người nhận | I7: Ghi chú
B8: 45658 | C8: Tồn đầu kỳ | D8: kg | G8: 552
B9: 45670 | C9: Bao vô cây cuộn CN 47*95 | D9: kg | F9: 1.6 | G9: =+G8+E9-F9 -> 550.4 | H9: Nguyễn Thị Liên | I9: SX
B10: 45671 | C10: Bao vô cây cuộn CN 47*95 | D10: kg | F10: 4.5 | G10: =+G9+E10-F10 -> 545.9 | H10: Nguyễn Thị Liên | I10: SX
B11: 45672 | C11: Bao vô cây cuộn CN 47*95 | D11: kg | F11: 3.3 | G11: =+G10+E11-F11 -> 542.6 | H11: Nguyễn Thị Liên | I11: SX
B12: 45673 | C12: Bao vô cây cuộn CN 47*95 | D12: kg | F12: 6.2 | G12: =+G11+E12-F12 -> 536.4 | H12: Nguyễn Thị Liên | I12: SX
B13: 45674 | C13: Bao vô cây cuộn CN 47*95 | D13: kg | F13: 1.8 | G13: =+G12+E13-F13 -> 534.6 | H13: Nguyễn Thị Liên | I13: SX
B14: 45681 | C14: Bao vô cây cuộn CN 47*95 | D14: kg | F14: 1 | G14: =+G13+E14-F14 -> 533.6 | H14: Nguyễn Thị Liên | I14: SX
B15: 45690 | C15: Bao vô cây cuộn CN 47*95 | D15: kg | F15: 0.8 | G15: =+G14+E15-F15 -> 532.8 | H15: Nguyễn Thị Liên | I15: SX
B16: 45691 | C16: Bao vô cây cuộn CN 47*95 | D16: kg | F16: 3.6 | G16: =+G15+E16-F16 -> 529.2 | H16: Nguyễn Thị Liên | I16: SX
B17: 45692 | C17: Bao vô cây cuộn CN 47*95 | D17: kg | F17: 5.5 | G17: =+G16+E17-F17 -> 523.7 | H17: Nguyễn Thị Liên | I17: SX
B18: 45706 | C18: Bao vô cây cuộn CN 47*95 | D18: kg | F18: 6.7 | G18: =+G17+E18-F18 -> 517 | H18: Nguyễn Thị Liên | I18: Bao Bì minh Sơn
B19: 45707 | C19: Bao vô cây cuộn CN 47*95 | D19: kg | F19: 6.4 | G19: =+G18+E19-F19 -> 510.6 | H19: Nguyễn Thị Liên | I19: SX
B20: 45708 | C20: Bao vô cây cuộn CN 47*95 | D20: kg | F20: 5.2 | G20: =+G19+E20-F20 -> 505.4 | H20: Nguyễn Thị Liên | I20: SX
... B43: 45845 | C43: Bao vô cây cuộn CN 47*95 | D43: kg | F43: 9.5 | G43: =+G42+E43-F43 -> 365.3 | H43: Nguyễn Thị ,Tâm | I43: SX
B44: 45846 | C44: Bao vô cây cuộn CN 47*95 | D44: kg | F44: 9.7 | G44: =+G43+E44-F44 -> 355.6 | H44: Nguyễn Thị ,Tâm | I44: SX | P44: =32*88 -> 2816
B45: 45857 | C45: Bao vô cây cuộn CN 47*95 | D45: kg | F45: 5.4 | G45: =+G44+E45-F45 -> 350.2 | H45: Nguyễn Thị ,Tâm | I45: SX
B46: 45859 | C46: Bao vô cây cuộn CN 47*95 | D46: kg | F46: 4.1 | G46: =+G45+E46-F46 -> 346.1 | H46: Nguyễn Thị ,Tâm | I46: SX
B47: 45860 | C47: Bao vô cây cuộn CN 47*95 | D47: kg | F47: 13.5 | G47: =+G46+E47-F47 -> 332.6 | H47: Nguyễn Thị ,Tâm | I47: SX
B48: 45868 | C48: Bao vô cây cuộn CN 47*95 | D48: kg | F48: 13.8 | G48: =+G47+E48-F48 -> 318.8 | H48: Nguyễn Thị ,Tâm | I48: SX
B49: 45878 | C49: Bao vô cây cuộn CN 47*95 | D49: kg | F49: 5 | G49: =+G48+E49-F49 -> 313.8 | H49: Nguyễn Thị ,Tâm | I49: SX
B50: 45880 | C50: Bao vô cây cuộn CN 47*95 | D50: kg | F50: 6.3 | G50: =+G49+E50-F50 -> 307.5 | H50: Nguyễn Thị ,Tâm | I50: SX
B51: 45881 | C51: Bao vô cây cuộn CN 47*95 | D51: kg | F51: 9.8 | G51: =+G50+E51-F51 -> 297.7 | H51: Nguyễn Thị ,Tâm | I51: SX
B52: 45882 | C52: Bao vô cây cuộn CN 47*95 | D52: kg | F52: 9.1 | G52: =+G51+E52-F52 -> 288.6 | H52: Nguyễn Thị ,Tâm | I52: SX
B53: 45890 | C53: Bao vô cây cuộn CN 47*95 | D53: kg | F53: 10 | G53: =+G52+E53-F53 -> 278.6 | H53: Nguyễn Thị ,Tâm | I53: SX
B54: 45891 | C54: Bao vô cây cuộn CN 47*95 | D54: kg | F54: 6 | G54: =+G53+E54-F54 -> 272.6 | H54: Nguyễn Thị ,Tâm | I54: SX
B55: 45892 | C55: Bao vô cây cuộn CN 47*95 | D55: kg | F55: 3 | G55: =+G54+E55-F55 -> 269.6 | H55: Nguyễn Thị ,Tâm | I55: SX
B56: 45894 | C56: Bao vô cây cuộn CN 47*95 | D56: kg | F56: 9.4 | G56: =+G55+E56-F56 -> 260.2 | H56: Nguyễn Thị ,Tâm | I56: SX
... B63: 45911 | C63: Bao vô cây cuộn CN 47*95 | D63: kg | F63: 8.7 | G63: =+G62+E63-F63 -> 194.5 | H63: Nguyễn Thị ,Tâm | I63: SX
B64: 45915 | C64: Bao vô cây cuộn CN 47*95 | D64: kg | E64: 176.3 | G64: =+G63+E64-F64 -> 370.8 | H64: Nguyễn Thị ,Tâm | I64: SX
C65: Bao vô cây cuộn CN 47*95 | D65: kg | G65: =+G64+E65-F65 -> 370.8 | H65: Nguyễn Thị ,Tâm | I65: SX
C66: Bao vô cây cuộn CN 47*95 | D66: kg | G66: =+G65+E66-F66 -> 370.8 | H66: Nguyễn Thị ,Tâm | I66: SX
C67: Bao vô cây cuộn CN 47*95 | D67: kg | G67: =+G66+E67-F67 -> 370.8 | H67: Nguyễn Thị ,Tâm | I67: SX
C68: Bao vô cây cuộn CN 47*95 | D68: kg | G68: =+G67+E68-F68 -> 370.8 | H68: Nguyễn Thị ,Tâm | I68: SX
C69: Bao vô cây cuộn CN 47*95 | D69: kg | G69: =+G68+E69-F69 -> 370.8 | H69: Nguyễn Thị ,Tâm | I69: SX
C70: Bao vô cây cuộn CN 47*95 | D70: kg | G70: =+G69+E70-F70 -> 370.8 | H70: Nguyễn Thị ,Tâm | I70: SX
C71: Bao vô cây cuộn CN 47*95 | D71: kg | G71: =+G70+E71-F71 -> 370.8 | H71: Nguyễn Thị ,Tâm | I71: SX
...

Sheet Bao vô cây CN  10 cuộn
A1: Cty TNHH Đông Á
A2: Thôn Mộc Ty, xã Trưng Trắc, huyện Văn Lâm, tỉnh Hưng Yên
A4: =+'[1]Hộp oto'!A4:I5 -> THẺ KHO NGUYÊN VẬT LIỆU
A7: STT | B7: Ngày tháng | C7: Tên nguyên vật liệu | D7: ĐVT | E7: Số lượng nhập | F7: Số lượng xuất | G7: Tồn | H7: Người nhận | I7: Ghi chú
B8: 45658 | C8: Tồn đầu kỳ | D8: kg | G8: 119
B9: 45700 | C9: Bao vô cây cuộn CN 55,8*72 | D9: kg | F9: 4.5 | G9: =+G8+E9-F9 -> 114.5 | H9: Nguyễn Thị Liên | I9: SX
B10: 45701 | C10: Bao vô cây cuộn CN 47*95 | D10: kg | F10: 12.1 | G10: =+G9+E10-F10 -> 102.4 | H10: Nguyễn Thị Liên | I10: SX
B11: 45741 | C11: Bao vô cây cuộn CN 47*95 | D11: kg | F11: 6.5 | G11: =+G10+E11-F11 -> 95.9 | H11: Nguyễn Thị Liên | I11: SX
B12: 45742 | C12: Bao vô cây cuộn CN 47*95 | D12: kg | F12: 10.7 | G12: =+G11+E12-F12 -> 85.2 | H12: Nguyễn Thị Liên | I12: SX
B13: 45791 | C13: Bao vô cây cuộn CN 47*95 | D13: kg | F13: 12 | G13: =+G12+E13-F13 -> 73.2 | H13: Nguyễn Thị Liên | I13: SX
B14: 45800 | C14: Bao vô cây cuộn CN 47*95 | D14: kg | F14: 6 | G14: =+G13+E14-F14 -> 67.2 | H14: Nguyễn Thị Liên | I14: Đóng lại hàng jp
B15: 45809 | C15: Bao vô cây cuộn CN 47*95 | D15: kg | F15: 0.5 | G15: =+G14+E15-F15 -> 66.7 | H15: Nguyễn Thị Liên | I15: Xuât cho my đóng hàng đi giao
B16: 45812 | C16: Bao vô cây cuộn CN 47*95 | D16: kg | F16: 19 | G16: =+G15+E16-F16 -> 47.7 | H16: Nguyễn Thị Liên | I16: SX
B17: 45824 | C17: Bao vô cây cuộn CN 47*95 | D17: kg | F17: 20 | G17: =+G16+E17-F17 -> 27.7 | H17: Nguyễn Thị Liên | I17: SX
B18: 45834 | C18: Bao vô cây cuộn CN 47*95 | D18: kg | F18: 6.5 | G18: =+G17+E18-F18 -> 21.2 | H18: Nguyễn Thị Liên | I18: Bao Bì minh Sơn
B19: 45835 | C19: Bao vô cây cuộn CN 47*95 | D19: kg | F19: 9 | G19: =+G18+E19-F19 -> 12.2 | H19: Nguyễn Thị Liên | I19: SX
B20: 45839 | C20: Bao vô cây cuộn CN 47*95 | D20: kg | F20: 8.4 | G20: =+G19+E20-F20 -> 3.8 | H20: Nguyễn Thị Liên | I20: SX
B21: 45849 | C21: Bao vô cây cuộn CN 47*95 | D21: kg | E21: 219 | G21: =+G20+E21-F21 -> 222.8 | H21: Nguyễn Thị Liên | I21: SX
B22: 45850 | C22: Bao vô cây cuộn CN 47*95 | D22: kg | F22: 11 | G22: =+G21+E22-F22 -> 211.8 | H22: Nguyễn Thị Liên | I22: SX
B23: 45869 | C23: Bao vô cây cuộn CN 47*95 | D23: kg | F23: 12.8 | G23: =+G22+E23-F23 -> 199 | H23: Nguyễn Thị Liên | I23: SX
B24: 45870 | C24: Bao vô cây cuộn CN 47*95 | D24: kg | F24: 17.2 | G24: =+G23+E24-F24 -> 181.8 | H24: Nguyễn Thị Liên | I24: Đóng lại hàng linh an
B25: 45875 | C25: Bao vô cây cuộn CN 47*95 | D25: kg | F25: 5.5 | G25: =+G24+E25-F25 -> 176.3 | H25: Nguyễn Thị Liên | I25: SX
B26: 45915 | C26: Bao vô cây cuộn CN 47*95 | D26: kg | F26: 176.3 | G26: =+G25+E26-F26 -> 0 | H26: Nguyễn Thị Liên | I26: Chuyển sang bao 20 cn
B27: 45916 | C27: Bao vô cây cuộn CN 47*95 | D27: kg | E27: 50 | G27: =+G26+E27-F27 -> 50 | H27: Nguyễn Thị Liên | I27: SX
B28: 45917 | C28: Bao vô cây cuộn CN 47*95 | D28: kg | F28: 10.8 | G28: =+G27+E28-F28 -> 39.2 | H28: Nguyễn Thị Liên | I28: SX
B29: 45918 | C29: Bao vô cây cuộn CN 47*95 | D29: kg | F29: 3.7 | G29: =+G28+E29-F29 -> 35.5 | H29: Nguyễn Thị Liên | I29: SX
B30: 45924 | C30: Bao vô cây cuộn CN 47*95 | D30: kg | F30: 8.8 | G30: =+G29+E30-F30 -> 26.7 | H30: Nguyễn Thị Liên | I30: SX
B31: 45925 | C31: Bao vô cây cuộn CN 47*95 | D31: kg | F31: 7.8 | G31: =+G30+E31-F31 -> 18.9 | H31: Nguyễn Thị Liên | I31: SX
B32: 45926 | C32: Bao vô cây cuộn CN 47*95 | D32: kg | F32: 7.7 | G32: =+G31+E32-F32 -> 11.2 | H32: Nguyễn Thị Liên | I32: SX
B33: 45927 | C33: Bao vô cây cuộn CN 47*95 | D33: kg | F33: 2.3 | G33: =+G32+E33-F33 -> 8.9 | H33: Nguyễn Thị Liên | I33: SX
B34: 45930 | C34: Bao vô cây cuộn CN 47*95 | D34: kg | E34: =8*25+5 -> 205 | F34: 10 | G34: =+G33+E34-F34 -> 203.9 | H34: Nguyễn Thị Liên | I34: SX
B35: 45938 | C35: Bao vô cây cuộn CN 47*95 | D35: kg | F35: 5.6 | G35: =+G34+E35-F35 -> 198.3 | H35: Nguyễn Thị Liên | I35: SX
C36: Bao vô cây cuộn CN 47*95 | D36: kg | G36: =+G35+E36-F36 -> 198.3 | H36: Nguyễn Thị Liên | I36: SX
C37: Bao vô cây cuộn CN 47*95 | D37: kg | G37: =+G36+E37-F37 -> 198.3 | H37: Nguyễn Thị Liên | I37: SX
C38: Bao vô cây cuộn CN 47*95 | D38: kg | G38: =+G37+E38-F38 -> 198.3 | H38: Nguyễn Thị Liên | I38: SX
C39: Bao vô cây cuộn CN 47*95 | D39: kg | G39: =+G38+E39-F39 -> 198.3 | H39: Nguyễn Thị Liên | I39: SX
C40: Bao vô cây cuộn CN 47*95 | D40: kg | G40: =+G39+E40-F40 -> 198.3 | H40: Nguyễn Thị ,Tâm | I40: SX
C41: Bao vô cây cuộn CN 47*95 | D41: kg | G41: =+G40+E41-F41 -> 198.3 | H41: Nguyễn Thị ,Tâm | I41: SX
C42: Bao vô cây cuộn CN 47*95 | D42: kg | G42: =+G41+E42-F42 -> 198.3 | H42: Nguyễn Thị ,Tâm | I42: SX
C43: Bao vô cây cuộn CN 47*95 | D43: kg | G43: =+G42+E43-F43 -> 198.3 | H43: Nguyễn Thị ,Tâm | I43: SX
...

Sheet Bao 5 cuộn CN
A1: Cty TNHH Đông Á
A2: Thôn Mộc Ty, xã Trưng Trắc, huyện Văn Lâm, tỉnh Hưng Yên
A4: =+'[1]Hộp oto'!A4:I5 -> THẺ KHO NGUYÊN VẬT LIỆU
A7: STT | B7: Ngày tháng | C7: Tên nguyên vật liệu | D7: ĐVT | E7: Số lượng nhập | F7: Số lượng xuất | G7: Tồn | H7: Người nhận | I7: Ghi chú
B8: 45658 | C8: Tồn đầu kỳ | D8: kg | G8: 523
B9: 45670 | C9: Bao 5 cuộn 30*70 | D9: kg | F9: 1.8 | G9: =+G8+E9-F9 -> 521.2 | I9: SX
B10: 45671 | C10: Bao 5 cuộn 30*70 | D10: kg | F10: 5 | G10: =+G9+E10-F10 -> 516.2 | H10: Nguyễn Thị Liên | I10: SX
B11: 45672 | C11: Bao 5 cuộn 30*70 | D11: kg | F11: 3.7 | G11: =+G10+E11-F11 -> 512.5 | H11: Nguyễn Thị Liên | I11: SX
B12: 45673 | C12: Bao 5 cuộn 30*70 | D12: kg | F12: 6.8 | G12: =+G11+E12-F12 -> 505.7 | I12: SX
B13: 45674 | C13: Bao 5 cuộn 30*70 | D13: kg | F13: 2.2 | G13: =+G12+E13-F13 -> 503.5 | H13: Nguyễn Thị Liên | I13: SX
B14: 45681 | C14: Bao 5 cuộn 30*70 | D14: kg | F14: 1.1 | G14: =+G13+E14-F14 -> 502.4 | H14: Nguyễn Thị Liên | I14: SX
B15: 45690 | C15: Bao 5 cuộn 30*70 | F15: 0.8 | G15: =+G14+E15-F15 -> 501.6
B16: 45691 | C16: Bao 5 cuộn 30*70 | D16: kg | F16: 4 | G16: =+G15+E16-F16 -> 497.6 | H16: Nguyễn Thị Liên | I16: SX
B17: 45692 | C17: Bao 5 cuộn 30*70 | D17: kg | F17: 6 | G17: =+G16+E17-F17 -> 491.6 | H17: Nguyễn Thị Liên | I17: SX
B18: 45706 | C18: Bao 5 cuộn 30*70 | D18: kg | F18: 7.6 | G18: =+G17+E18-F18 -> 484 | H18: Nguyễn Thị Liên | I18: SX
B19: 45707 | C19: Bao 5 cuộn 30*70 | D19: kg | F19: 7.3 | G19: =+G18+E19-F19 -> 476.7 | I19: Bao bì minh sơn
B20: 45708 | C20: Bao 5 cuộn 30*70 | D20: kg | F20: 5.5 | G20: =+G19+E20-F20 -> 471.2 | H20: Nguyễn Thị Liên | I20: SX
B21: 45709 | C21: Bao 5 cuộn 30*70 | D21: kg | F21: 2.6 | G21: =+G20+E21-F21 -> 468.6 | H21: Nguyễn Thị Liên | I21: SX
B22: 45757 | C22: Bao 5 cuộn 30*70 | D22: kg | F22: 5.1 | G22: =+G21+E22-F22 -> 463.5 | H22: Nguyễn Thị Liên | I22: SX
B23: 45758 | C23: Bao 5 cuộn 30*70 | D23: kg | F23: 6.5 | G23: =+G22+E23-F23 -> 457 | H23: Nguyễn Thị Liên | I23: SX
B24: 45759 | C24: Bao 5 cuộn 30*70 | D24: kg | F24: 15 | G24: =+G23+E24-F24 -> 442 | H24: Nguyễn Thị Liên | I24: SX
B25: 45761 | C25: Bao 5 cuộn 30*70 | D25: kg | F25: 8.4 | G25: =+G24+E25-F25 -> 433.6 | H25: Nguyễn Thị Liên | I25: Đóng lại hàng linh an
B26: 45771 | C26: Bao 5 cuộn 30*70 | D26: kg | F26: 8.8 | G26: =+G25+E26-F26 -> 424.8 | H26: Nguyễn Thị Liên | I26: SX
B27: 45773 | C27: Bao 5 cuộn 30*70 | D27: kg | F27: 5.3 | G27: =+G26+E27-F27 -> 419.5 | H27: Nguyễn Thị Liên | I27: SX
B28: 45775 | C28: Bao 5 cuộn 30*70 | D28: kg | F28: 8.5 | G28: =+G27+E28-F28 -> 411 | H28: Nguyễn Thị Liên | I28: SX
B29: 45776 | C29: Bao 5 cuộn 30*70 | D29: kg | F29: 2.7 | G29: =+G28+E29-F29 -> 408.3 | H29: Nguyễn Thị Liên | I29: SX
B30: 45783 | C30: Bao 5 cuộn 30*70 | D30: kg | F30: 2.5 | G30: =+G29+E30-F30 -> 405.8 | H30: Nguyễn Thị Liên | I30: SX
B31: 45784 | C31: Bao 5 cuộn 30*70 | D31: kg | F31: 13.7 | G31: =+G30+E31-F31 -> 392.1 | H31: Nguyễn Thị Liên | I31: SX
B32: 45809 | C32: Bao 5 cuộn 30*70 | D32: kg | F32: 0.9 | G32: =+G31+E32-F32 -> 391.2 | H32: Nguyễn Thị Liên | I32: SX
B33: 45810 | C33: Bao 5 cuộn 30*70 | D33: kg | F33: 8.4 | G33: =+G32+E33-F33 -> 382.8 | I33: SX
B34: 45812 | C34: Bao 5 cuộn 30*70 | D34: kg | F34: 10 | G34: =+G33+E34-F34 -> 372.8 | I34: SX
B35: 45813 | C35: Bao 5 cuộn 30*70 | D35: kg | F35: 8.5 | G35: =+G34+E35-F35 -> 364.3 | H35: Đóng lại hàng jp | I35: SX
B36: 45825 | C36: Bao 5 cuộn 30*70 | D36: kg | F36: 2.5 | G36: =+G35+E36-F36 -> 361.8 | I36: SX
B37: 45834 | C37: Bao 5 cuộn 30*70 | D37: kg | F37: 9.4 | G37: =+G36+E37-F37 -> 352.4 | I37: SX
B38: 45835 | C38: Bao 5 cuộn 30*70 | D38: kg | F38: 7.6 | G38: =+G37+E38-F38 -> 344.8 | I38: SX
B39: 45843 | C39: Bao 5 cuộn 30*70 | D39: kg | F39: 6.3 | G39: =+G38+E39-F39 -> 338.5 | I39: SX
B40: 45845 | C40: Bao 5 cuộn 30*70 | D40: kg | F40: 9.7 | G40: =+G39+E40-F40 -> 328.8 | I40: SX
B41: 45846 | C41: Bao 5 cuộn 30*70 | D41: kg | E41: 334.5 | F41: 10.5 | G41: =+G40+E41-F41 -> 652.8 | I41: SX
B42: 45857 | C42: Bao 5 cuộn 30*70 | D42: kg | F42: 6.5 | G42: =+G41+E42-F42 -> 646.3 | I42: SX
B43: 45859 | C43: Bao 5 cuộn 30*70 | D43: kg | F43: 3.5 | G43: =+G42+E43-F43 -> 642.8 | I43: SX
...

Sheet Bao vô cây 12 cuộn
A1: Cty TNHH Đông Á
A2: Thôn Mộc Ty, xã Trưng Trắc, huyện Văn Lâm, tỉnh Hưng Yên
A4: =+'[1]Hộp oto'!A4:I5 -> THẺ KHO NGUYÊN VẬT LIỆU
A6: trung binh 9c/1kg
A7: STT | B7: Ngày tháng | C7: Tên nguyên vật liệu | D7: ĐVT | E7: Số lượng nhập | F7: Số lượng xuất | G7: Tồn | H7: Người nhận | I7: Ghi chú
B8: 45658 | C8: Tồn đầu kỳ | D8: kg | G8: 337
B9: 45714 | C9: Bao vô cây 12 cuộn 665*105 | D9: kg | F9: 0.9 | G9: =+G8+E9-F9 -> 336.1 | H9: Nguyễn Thị ,Tâm | I9: SX
B10: 45716 | C10: Bao vô cây 12 cuộn 665*105 | D10: kg | F10: 0.4 | G10: =+G9+E10-F10 -> 335.7 | H10: Nguyễn Thị ,Tâm | I10: SX
B11: 45717 | C11: Bao vô cây 12 cuộn 665*105 | D11: kg | F11: 0.5 | G11: =+G10+E11-F11 -> 335.2 | H11: Nguyễn Thị ,Tâm | I11: SX
B12: 45720 | C12: Bao vô cây 12 cuộn 665*105 | D12: kg | F12: 0.1 | G12: =+G11+E12-F12 -> 335.1 | H12: Nguyễn Thị Liên | I12: SX
B13: 45730 | C13: Bao vô cây 12 cuộn 665*105 | D13: kg | F13: 0.4 | G13: =+G12+E13-F13 -> 334.7 | H13: Nguyễn Thị Liên | I13: SX
B14: 45731 | C14: Bao vô cây 12 cuộn 665*105 | D14: kg | F14: 2.6 | G14: =+G13+E14-F14 -> 332.1 | H14: Nguyễn Thị Liên | I14: SX
B15: 45733 | C15: Bao vô cây 12 cuộn 665*105 | D15: kg | F15: 8.7 | G15: =+G14+E15-F15 -> 323.4 | H15: Nguyễn Thị Liên | I15: SX
B16: 45734 | C16: Bao vô cây 12 cuộn 665*105 | D16: kg | F16: 10.9 | G16: =+G15+E16-F16 -> 312.5 | H16: Nguyễn Thị Liên | I16: SX
B17: 45735 | C17: Bao vô cây 12 cuộn 665*105 | D17: kg | F17: 11.5 | G17: =+G16+E17-F17 -> 301 | H17: Nguyễn Thị Liên | I17: SX
B18: 45765 | C18: Bao vô cây 12 cuộn 665*105 | D18: kg | F18: 1.2 | G18: =+G17+E18-F18 -> 299.8 | H18: Nguyễn Thị Liên | I18: SX
B19: 45770 | C19: Bao vô cây 12 cuộn 665*105 | D19: kg | F19: 2 | G19: =+G18+E19-F19 -> 297.8 | H19: Nguyễn Thị Liên | I19: SX
B20: 45799 | C20: Bao vô cây 12 cuộn 665*105 | D20: kg | F20: 8.8 | G20: =+G19+E20-F20 -> 289 | H20: Nguyễn Thị Liên | I20: SX
... B34: 45875 | C34: Bao vô cây 12 cuộn 665*105 | D34: kg | F34: 2.5 | G34: =+G33+E34-F34 -> 224.4 | H34: Nguyễn Thị ,Tâm | I34: SX
B35: 45876 | C35: Bao vô cây 12 cuộn 665*105 | D35: kg | F35: 4 | G35: =+G34+E35-F35 -> 220.4 | H35: Nguyễn Thị ,Tâm | I35: SX | M35: =27/9 -> 3
B36: 45877 | C36: Bao vô cây 12 cuộn 665*105 | D36: kg | F36: 9.5 | G36: =+G35+E36-F36 -> 210.9 | H36: Nguyễn Thị ,Tâm | I36: Bao Bì minh Sơn
B37: 45878 | C37: Bao vô cây 12 cuộn 665*105 | D37: kg | F37: 4.5 | G37: =+G36+E37-F37 -> 206.4 | H37: Nguyễn Thị ,Tâm | I37: SX
B38: 45880 | C38: Bao vô cây 12 cuộn 665*105 | D38: kg | F38: 2.5 | G38: =+G37+E38-F38 -> 203.9 | H38: Nguyễn Thị ,Tâm | I38: SX
B39: 45888 | C39: Bao vô cây 12 cuộn 665*105 | D39: kg | F39: 2 | G39: =+G38+E39-F39 -> 201.9 | H39: Nguyễn Thị ,Tâm | I39: SX | J39: Sửa hàng phú thọ
B40: 45898 | C40: Bao vô cây 12 cuộn 665*105 | D40: kg | F40: 1.8 | G40: =+G39+E40-F40 -> 200.1 | H40: Nguyễn Thị ,Tâm | I40: SX
B41: 45899 | C41: Bao vô cây 12 cuộn 665*105 | D41: kg | F41: 0.7 | G41: =+G40+E41-F41 -> 199.4 | H41: Nguyễn Thị ,Tâm | I41: SX
B42: 45908 | C42: Bao vô cây 12 cuộn 665*105 | D42: kg | F42: 1 | G42: =+G41+E42-F42 -> 198.4 | H42: Nguyễn Thị ,Tâm | I42: SX
